Workbook

Sheet Liste Projets
B2: Liste Référentielle des Projets - Indicateurs Physiques
B3: Identification | J3: Indicateurs Physiques
B4: N° | C4: Province | D4: Commune | E4: Rubrique | F4: Intitulé Rubrique | G4: Projet | H4: Consistance | I4: Coût Total (DH) | J4: Unité | K4: Qté Prévue
B5: 1 | C5: Sidi Kacem | D5: KHENICHET | E5: 50-23 | F5: Entretien et réparation du réseau d'assainissement et de drainage | G5: Travaux de curage des canaux en terre | H5: Curage des collecteurs d'assainissement du secteur EST2 | I5: 2091568 | J5: ml | K5: 1046
B6: 2 | C6: Sidi Kacem | D6: KHENICHET | E6: 40-21 | F6: Travaux de pistes | G6: Travaux de réhabilitation des pistes agricoles | H6: Entretien des pistes agricoles Douar Nouagra et Douar ouled Salem | I6: 78000 | J6: km | K6: 1
B7: 3 | C7: Sidi Kacem | D7: KHENICHET | E7: 50-23 | F7: Entretien et réparation du réseau d'assainissement et de drainage | G7: Curage des prises sur l’oued, bâche d’aspiration et bassin de régulation. | H7: Curage de la chambre des joints de démontage des siphonnes de la station de pompage EST2. | I7: 126000 | J7: ml | K7: 42
B8: 4 | C8: Sidi Kacem | D8: KHENICHET | E8: 50-21 | F8: Entretien et réparation des stations de pompage | G8: Prestation de maintenance des débitmètres et leurs équipements annexes installés au niveau des station de pompage | H8: Changement trois débitmètre Ø 600mm inondés de la station de pompage EST 2 et deux capteurs VEGASON 62 | I8: 165500 | J8: U | K8: 3
B9: 5 | C9: Sidi Kacem | D9: BIR TALEB | E9: 50-23 | F9: Entretien et réparation du réseau d'assainissement et de drainage | G9: Travaux de curage des canaux en terre | H9: Curage du canal d'assainisement Tihli Aval | I9: 1000000 | J9: ml | K9: 500
B10: 6 | C10: Sidi Kacem | D10: BIR TALEB | E10: 50-23 | F10: Entretien et réparation du réseau d'assainissement et de drainage | H10: Curage des collecteurs d'assainissement du secteur P11/1 | I10: 846731 | J10: ml | K10: 423
B11: 7 | C11: Sidi Kacem | D11: BIR TALEB | E11: 50-23 | F11: Entretien et réparation du réseau d'assainissement et de drainage | G11: Curage des prises sur l’oued, bâche d’aspiration et bassin de régulation. | H11: Curage des prises sur l’oued de la station de pompage P11/1. | I11: 200000 | J11: ml | K11: 67
B12: 8 | C12: Sidi Kacem | D12: BIR TALEB | E12: 50-21 | F12: Entretien et réparation des stations de pompage | G12: Prestation de maintenance des débitmètres et leurs équipements annexes installés au niveau des station de pompage | H12: Changement trois débitmètre Ø 400mm inondés de la station de pompage P11/1 | I12: 141900 | J12: U | K12: 3
B13: 9 | C13: Sidi Kacem | D13: BIR TALEB | E13: 50-21 | F13: Entretien et réparation des stations de pompage | G13: Prestations de maintenance et de réparation mécanique des pompes et des groupes motopompes submersibles des stations de pompage. | H13: Démontage et expertise des roues des pompes principaux et pompes a vide de la station P11/1 Changement des roulements, tresses et organes d’effectués de la station P11/1 | I13: 26700 | J13: U | K13: 1
B14: 10 | C14: Sidi Kacem | D14: BIR TALEB | E14: 50-21 | F14: Entretien et réparation des stations de pompage | G14: Stabilisation Berge oued | H14: Pose de gabions et recouvrement du talus par matelas Reno des stations de pompage P11/1. | I14: 480000 | J14: m³ | K14: 320
B15: 11 | C15: Sidi Kacem | D15: BIR TALEB | E15: 50-21 | F15: Entretien et réparation des stations de pompage | G15: Génie civile des locaux des stations de pompage. | H15: Expertise d’état et d’étanchéité des locaux pompes. Renforcement d’étanchéité des locaux pompe sous niveau des oueds des stations de pompage P11/1. Entretien des supports en béton des conduites d’aspiration. | I15: 300000 | J15: U | K15: 1
B16: 12 | C16: Sidi Kacem | D16: CHEBANAT | E16: 50-23 | F16: Entretien et réparation du réseau d'assainissement et de drainage | G16: Travaux de curage des canaux en terre | H16: Curage des collecteurs d'assainissement des secteur SH5 et SH6. | I16: 1000000 | J16: ml | K16: 500
B17: 13 | C17: Sidi Kacem | D17: CHEBANAT | E17: 50-23 | F17: Entretien et réparation du réseau d'assainissement et de drainage | G17: Travaux de curage des canaux révetus | H17: Curage du canal principal d'irrigation beht partie aval 1. | I17: 739200 | J17: ml | K17: 370
B18: 14 | C18: Sidi Kacem | D18: ZIRARA | E18: 50-23 | F18: Entretien et réparation du réseau d'assainissement et de drainage | G18: Travaux de curage des canaux révetus | H18: Curage du canal principal d'irrigation beht partie aval 2. | I18: 1276800 | J18: ml | K18: 638
B19: 15 | C19: Sidi Kacem | D19: DAR LAASLOUJI | E19: 50-23 | F19: Entretien et réparation du réseau d'assainissement et de drainage | G19: Travaux de curage des canaux en terre | H19: Curage des collecteurs d'assainissement des secteurs P8-1 et P8-2 | I19: 5796360 | J19: ml | K19: 2898
B20: 16 | C20: Sidi Kacem | D20: DAR LAASLOUJI | E20: 40-21 | F20: Travaux de pistes | G20: Entretien des pistes agricoles | H20: Entretien des pistes agricoles | I20: 340000 | J20: km | K20: 1
B21: 17 | C21: Sidi Kacem | D21: HOUAFATE | E21: 20-11 | F21: Travaux de réhabilitation des équipements | G21: Travaux de réhabilitation des canaux portés d'irrigation | H21: Fourniture et de pose de canaux porté et accessoires du réseau S3 du secteur S13 | I21: 397934 | J21: ml | K21: 133
B22: 18 | C22: Sidi Kacem | D22: HOUAFATE | E22: 20-11 | F22: Travaux de réhabilitation des équipements | H22: Fourniture et de pose de canaux porté et accessoires du réseau T2S1 du secteur S13 | I22: 207575 | J22: ml | K22: 69
B23: 19 | C23: Sidi Kacem | D23: HOUAFATE | E23: 40-21 | F23: Travaux de pistes | G23: Entretien des pistes agricoles | H23: Entretien des pistes agricoles | I23: 2200000 | J23: km | K23: 4
B24: 20 | C24: Sidi Kacem | D24: HOUAFATE | E24: 50-23 | F24: Entretien et réparation du réseau d'assainissement et de drainage | G24: Curage des prises sur l’oued, bâche d’aspiration et bassin de régulation. | H24: Curage des prises sur l’oued de la station de pompage S17 et S13. Nettoyage des grilles de préfiltration des boues colmaté de la station de pompage S17 et S13. Curage de la bâche d’aspiration de la station S17 et S13. | I24: 300000 | J24: ml | K24: 100
B25: 21 | C25: Sidi Kacem | D25: HOUAFATE | E25: 50-21 | F25: Entretien et réparation des stations de pompage | G25: Prestation de maintenance des débitmètres et leurs équipements annexes installés au niveau des station de pompage | H25: Changement trois débitmètre Ø 600mm inondés de la station de pompage S13. | I25: 250000 | J25: U | K25: 3
B26: 22 | C26: Sidi Kacem | D26: HOUAFATE | E26: 50-21 | F26: Entretien et réparation des stations de pompage | G26: Prestations de maintenance des moteurs électriques des stations de pompage. | H26: Révision des trois moteurs électriques 200 KW principaux de la station S13. Révision des deux moteurs électriques 5,5 KW groupes vide de la station S13. | I26: 25000 | J26: U | K26: 3
B27: 23 | C27: Sidi Kacem | D27: HOUAFATE | E27: 50-21 | F27: Entretien et réparation des stations de pompage | G27: Prestations de maintenance et de réparation mécanique des pompes et des groupes motopompes submersibles des stations de pompage. | H27: Démontage et expertise des roues des pompes principaux et pompes a vide de la station S13. Changement des roulements, tresses et organes d’effectués de la station S13. | I27: 38000 | J27: U | K27: 1
B28: 24 | C28: Sidi Kacem | D28: HOUAFATE | E28: 50-21 | F28: Entretien et réparation des stations de pompage | G28: Stabilisation Berge oued | H28: Pose de gabions et recouvrement du talus par matelas Reno des stations de pompage S13. | I28: 10560000 | J28: m³ | K28: 7040
B29: 25 | C29: Sidi Kacem | D29: HOUAFATE | E29: 50-21 | F29: Entretien et réparation des stations de pompage | G29: Mur clôture des stations de pompage. | H29: Stabilisation du sol et reconstruction des murs clôture (270m) cote oued de la station S17. | I29: 144000 | J29: ml | K29: 270
B30: 26 | C30: Sidi Kacem | D30: HOUAFATE | E30: 50-21 | F30: Entretien et réparation des stations de pompage | G30: Génie civile des locaux des stations de pompage. | H30: Expertise d’état et d’étanchéité des locaux pompes, commande, puissance des stations de pompage S17 et S13. Renforcement d’étanchéité des locaux pompe sous niveau des oueds des stations de pompage S17 et S13. | I30: 800000 | J30: U | K30: 1
B31: 27 | C31: Sidi Kacem | D31: NOUIRAT | E31: 50-23 | F31: Entretien et réparation du réseau d'assainissement et de drainage | G31: Travaux de curage des canaux en terre | H31: Curage des collecteurs d'assainissement des secteurs EST1 et N5 | I31: 1733306 | J31: ml | K31: 867
B32: 28 | C32: Sidi Kacem | D32: NOUIRAT | E32: 40-21 | F32: Travaux de pistes | G32: Entretien des pistes agricoles | H32: Entretien des pistes agricoles | I32: 670000 | J32: km | K32: 1
B33: 29 | C33: Sidi Kacem | D33: NOUIRAT | E33: 20-11 | F33: Travaux de réhabilitation des équipements | G33: Travaux de réhabilitation des ouvrages de génie civil | H33: Réhabilitation de l'ouvrage( genie civil ,gabiollannage,clapet anti retour et buse) de l'ouvrage de débouche SE1 | I33: 2500000 | J33: U | K33: 5
B34: 30 | C34: Sidi Kacem | D34: NOUIRAT | E34: 50-23 | F34: Entretien et réparation du réseau d'assainissement et de drainage | G34: Curage des prises sur l’oued, bâche d’aspiration et bassin de régulation. | H34: Curage des prises sur l’oued de la station de pompage E1. Nettoyage des grilles de préfiltration des boues colmaté de la station de pompage E1. Curage de la bâche d’aspiration de la station E1. | I34: 800000 | J34: ml | K34: 267
... B42: 38 | C42: Sidi Kacem | D42: SAFSAF | E42: 20-11 | F42: Travaux de réhabilitation des équipements | G42: Travaux de réhabilitation des canaux portés d'irrigation | H42: Fourniture et pose de canaux porté et accessoires du réseau S4 du secteur S11 | I42: 232266 | J42: ml | K42: 77
B43: 39 | C43: Sidi Kacem | D43: SAFSAF | E43: 20-11 | F43: Travaux de réhabilitation des équipements | H43: Recalage des canaux portés du réseau T5S5 du secteur S9 | I43: 1055025 | J43: ml | K43: 352
B44: 40 | C44: Sidi Kacem | D44: SAFSAF | E44: 20-11 | F44: Travaux de réhabilitation des équipements | H44: Recalage des canaux portés du réseau T7S5 du secteur S9 | I44: 1004535 | J44: ml | K44: 335
B45: 41 | C45: Sidi Kacem | D45: SAFSAF | E45: 20-11 | F45: Travaux de réhabilitation des équipements | H45: Recalage des canaux portés du réseau T2S5 du secteur S9 | I45: 793830 | J45: ml | K45: 265
B46: 42 | C46: Sidi Kacem | D46: SAFSAF | E46: 40-21 | F46: Travaux de pistes | G46: Entretien des pistes agricoles | H46: Entretien des pistes agricoles | I46: 2000000 | J46: km | K46: 4
B47: 43 | C47: Sidi Kacem | D47: SAFSAF | E47: 50-23 | F47: Entretien et réparation du réseau d'assainissement et de drainage | G47: Curage des prises sur l’oued, bâche d’aspiration et bassin de régulation. | H47: Curage des prises sur l’oued des stations de pompage S11, S9, 7D et 7B. Nettoyage des grilles de préfiltration des boues colmaté des stations de pompage S11, S9, 7D et 7B. Nettoyage des crépines des boues colmaté de station pompage 7D. Curage des dalots et bâche d’aspiration des stations de pompage S11, S9, 7B. | I47: 200000 | J47: ml | K47: 67
B48: 44 | C48: Sidi Kacem | D48: SAFSAF | E48: 50-21 | F48: Entretien et réparation des stations de pompage | G48: Prestation de maintenance des débitmètres et leurs équipements annexes installés au niveau des station de pompage | H48: Changements Sept des débitmètres Ø 600mm inondé des deux stations de pompage S11 et S9. | I48: 580000 | J48: U | K48: 7
...

Sheet Guide
B2: Guide d'Utilisation du Canevas Hebdomadaire
B4: CODE COULEUR | C4: Jaune = Saisie | Vert = Formule auto inter-feuille | Noir = Formule calculée | Bleu = Valeur saisie
B5: SAISIE HEBDOMADAIRE | C5: Dans les feuilles S01-S52, saisissez uniquement les cellules jaunes : Qté Réalisée Semaine, Montants, Avancement Financier %, Observations. Chaque feuille correspond à une semaine ISO de 2026 avec la date pré-remplie.
B6: 52 SEMAINES 2026 | C6: Le classeur contient 52 feuilles hebdomadaires (S01 à S52), couvrant toute l'année 2026. Les couleurs des onglets changent par mois pour faciliter la navigation.
B7: INDICATEURS PHYSIQUES | C7: Chaque projet a une Unité (ml, km, m², m³, U) et une Qté Prévue définies dans 'Liste Projets'. L'Avancement Physique % est calculé automatiquement : Qté Réalisée Cumul / Qté Prévue
B8: CUMUL AUTOMATIQUE | C8: La Qté Réalisée Cumul = Cumul sem. précédente + Qté réalisée cette semaine. Le lien entre semaines est automatique (S02 référence S01, S03 référence S02, etc.).
B9: SUIVI MENSUEL | C9: L'onglet 'Récapitulatif' contient un Résumé Mensuel avec l'avancement en fin de mois, l'accroissement mensuel et l'écart physique-financier pour chaque mois de 2026. Les semaines de chaque mois sont indiquées (ex: S01-S04 pour Janvier).
B10: PROTECTION | C10: Cellules de référence et formules verrouillées. Mot de passe : ormvag2026
B11: MODIFIER UNITÉS/QTÉ | C11: Allez dans 'Liste Projets' pour modifier les Unités et Qté Prévue. Ces valeurs sont reportées dans les feuilles hebdomadaires.
B12: FORMAT POURCENTAGE | C12: Saisir 0.25 pour 25%, 0.50 pour 50%, 1.00 pour 100%. Valeurs entre 0 et 1.
B13: ÉCART PHYS.-FIN. | C13: Positif = le physique avance plus vite que le financier. Négatif = le financier avance plus vite. Problème si > 5% d'écart.
B14: DATES PRÉ-REMPLIES | C14: Chaque feuille hebdomadaire a la date du lundi de la semaine pré-remplie dans la cellule C3. Par exemple, S24 correspond au 08/06/2026 - 14/06/2026.

Sheet S01
B2: Suivi Hebdomadaire - Semaine 1 (29/12 - 04/01) — Décembre 2026 - Exécution Physique et Financière
B3: Date : | C3: 46020 | E3: IDENTIFICATION | J3: INDICATEURS PHYSIQUES | Q3: INDICATEURS FINANCIERS | W3: SYNTHÈSE
B4: N° | C4: Province | D4: Commune | E4: Rubrique | F4: Intitulé Rubrique | G4: Projet | H4: Consistance | I4: Coût Total (DH) | J4: Unité | K4: Qté Prévue | L4: Qté Réalisée Sem. | M4: Qté Réalisée Cumul | N4: Avancement Physique % | O4: % Phys. Sem. Préc. | P4: Accroissement Phys. % | Q4: Montant Décaissé (DH) | R4: Montant Payé (DH) | S4: Montant Ordonné (DH) | T4: Avancement Financier % | U4: % Fin. Sem. Préc. | V4: Accroissement Fin. % | W4: Écart Phys.-Fin. | X4: Observations
B5: 1 | C5: Sidi Kacem | D5: KHENICHET | E5: 50-23 | F5: Entretien et réparation du réseau d'assainissement et de drainage | G5: Travaux de curage des canaux en terre | H5: Curage des collecteurs d'assainissement du secteur EST2 | I5: 2091568 | J5: ml | K5: 1046 | M5: =L5 | N5: =IFERROR(M5/K5,0) | O5: 0 | P5: =N5-O5 | U5: 0 | V5: =T5-U5 | W5: =N5-T5
B6: 2 | C6: Sidi Kacem | D6: KHENICHET | E6: 40-21 | F6: Travaux de pistes | G6: Travaux de réhabilitation des pistes agricoles | H6: Entretien des pistes agricoles Douar Nouagra et Douar ouled Salem | I6: 78000 | J6: km | K6: 1 | M6: =L6 | N6: =IFERROR(M6/K6,0) | O6: 0 | P6: =N6-O6 | U6: 0 | V6: =T6-U6 | W6: =N6-T6
B7: 3 | C7: Sidi Kacem | D7: KHENICHET | E7: 50-23 | F7: Entretien et réparation du réseau d'assainissement et de drainage | G7: Curage des prises sur l’oued, bâche d’aspiration et bassin de régulation. | H7: Curage de la chambre des joints de démontage des siphonnes de la station de pompage EST2. | I7: 126000 | J7: ml | K7: 42 | M7: =L7 | N7: =IFERROR(M7/K7,0) | O7: 0 | P7: =N7-O7 | U7: 0 | V7: =T7-U7 | W7: =N7-T7
B8: 4 | C8: Sidi Kacem | D8: KHENICHET | E8: 50-21 | F8: Entretien et réparation des stations de pompage | G8: Prestation de maintenance des débitmètres et leurs équipements annexes installés au niveau des station de pompage | H8: Changement trois débitmètre Ø 600mm inondés de la station de pompage EST 2 et deux capteurs VEGASON 62 | I8: 165500 | J8: U | K8: 3 | M8: =L8 | N8: =IFERROR(M8/K8,0) | O8: 0 | P8: =N8-O8 | U8: 0 | V8: =T8-U8 | W8: =N8-T8
B9: 5 | C9: Sidi Kacem | D9: BIR TALEB | E9: 50-23 | F9: Entretien et réparation du réseau d'assainissement et de drainage | G9: Travaux de curage des canaux en terre | H9: Curage du canal d'assainisement Tihli Aval | I9: 1000000 | J9: ml | K9: 500 | M9: =L9 | N9: =IFERROR(M9/K9,0) | O9: 0 | P9: =N9-O9 | U9: 0 | V9: =T9-U9 | W9: =N9-T9
B10: 6 | C10: Sidi Kacem | D10: BIR TALEB | E10: 50-23 | F10: Entretien et réparation du réseau d'assainissement et de drainage | H10: Curage des collecteurs d'assainissement du secteur P11/1 | I10: 846731 | J10: ml | K10: 423 | M10: =L10 | N10: =IFERROR(M10/K10,0) | O10: 0 | P10: =N10-O10 | U10: 0 | V10: =T10-U10 | W10: =N10-T10
B11: 7 | C11: Sidi Kacem | D11: BIR TALEB | E11: 50-23 | F11: Entretien et réparation du réseau d'assainissement et de drainage | G11: Curage des prises sur l’oued, bâche d’aspiration et bassin de régulation. | H11: Curage des prises sur l’oued de la station de pompage P11/1. | I11: 200000 | J11: ml | K11: 67 | M11: =L11 | N11: =IFERROR(M11/K11,0) | O11: 0 | P11: =N11-O11 | U11: 0 | V11: =T11-U11 | W11: =N11-T11
B12: 8 | C12: Sidi Kacem | D12: BIR TALEB | E12: 50-21 | F12: Entretien et réparation des stations de pompage | G12: Prestation de maintenance des débitmètres et leurs équipements annexes installés au niveau des station de pompage | H12: Changement trois débitmètre Ø 400mm inondés de la station de pompage P11/1 | I12: 141900 | J12: U | K12: 3 | M12: =L12 | N12: =IFERROR(M12/K12,0) | O12: 0 | P12: =N12-O12 | U12: 0 | V12: =T12-U12 | W12: =N12-T12
B13: 9 | C13: Sidi Kacem | D13: BIR TALEB | E13: 50-21 | F13: Entretien et réparation des stations de pompage | G13: Prestations de maintenance et de réparation mécanique des pompes et des groupes motopompes submersibles des stations de pompage. | H13: Démontage et expertise des roues des pompes principaux et pompes a vide de la station P11/1 Changement des roulements, tresses et organes d’effectués de la station P11/1 | I13: 26700 | J13: U | K13: 1 | M13: =L13 | N13: =IFERROR(M13/K13,0) | O13: 0 | P13: =N13-O13 | U13: 0 | V13: =T13-U13 | W13: =N13-T13
B14: 10 | C14: Sidi Kacem | D14: BIR TALEB | E14: 50-21 | F14: Entretien et réparation des stations de pompage | G14: Stabilisation Berge oued | H14: Pose de gabions et recouvrement du talus par matelas Reno des stations de pompage P11/1. | I14: 480000 | J14: m³ | K14: 320 | M14: =L14 | N14: =IFERROR(M14/K14,0) | O14: 0 | P14: =N14-O14 | U14: 0 | V14: =T14-U14 | W14: =N14-T14
B15: 11 | C15: Sidi Kacem | D15: BIR TALEB | E15: 50-21 | F15: Entretien et réparation des stations de pompage | G15: Génie civile des locaux des stations de pompage. | H15: Expertise d’état et d’étanchéité des locaux pompes. Renforcement d’étanchéité des locaux pompe sous niveau des oueds des stations de pompage P11/1. Entretien des supports en béton des conduites d’aspiration. | I15: 300000 | J15: U | K15: 1 | M15: =L15 | N15: =IFERROR(M15/K15,0) | O15: 0 | P15: =N15-O15 | U15: 0 | V15: =T15-U15 | W15: =N15-T15
B16: 12 | C16: Sidi Kacem | D16: CHEBANAT | E16: 50-23 | F16: Entretien et réparation du réseau d'assainissement et de drainage | G16: Travaux de curage des canaux en terre | H16: Curage des collecteurs d'assainissement des secteur SH5 et SH6. | I16: 1000000 | J16: ml | K16: 500 | M16: =L16 | N16: =IFERROR(M16/K16,0) | O16: 0 | P16: =N16-O16 | U16: 0 | V16: =T16-U16 | W16: =N16-T16
B17: 13 | C17: Sidi Kacem | D17: CHEBANAT | E17: 50-23 | F17: Entretien et réparation du réseau d'assainissement et de drainage | G17: Travaux de curage des canaux révetus | H17: Curage du canal principal d'irrigation beht partie aval 1. | I17: 739200 | J17: ml | K17: 370 | M17: =L17 | N17: =IFERROR(M17/K17,0) | O17: 0 | P17: =N17-O17 | U17: 0 | V17: =T17-U17 | W17: =N17-T17
B18: 14 | C18: Sidi Kacem | D18: ZIRARA | E18: 50-23 | F18: Entretien et réparation du réseau d'assainissement et de drainage | G18: Travaux de curage des canaux révetus | H18: Curage du canal principal d'irrigation beht partie aval 2. | I18: 1276800 | J18: ml | K18: 638 | M18: =L18 | N18: =IFERROR(M18/K18,0) | O18: 0 | P18: =N18-O18 | U18: 0 | V18: =T18-U18 | W18: =N18-T18
B19: 15 | C19: Sidi Kacem | D19: DAR LAASLOUJI | E19: 50-23 | F19: Entretien et réparation du réseau d'assainissement et de drainage | G19: Travaux de curage des canaux en terre | H19: Curage des collecteurs d'assainissement des secteurs P8-1 et P8-2 | I19: 5796360 | J19: ml | K19: 2898 | M19: =L19 | N19: =IFERROR(M19/K19,0) | O19: 0 | P19: =N19-O19 | U19: 0 | V19: =T19-U19 | W19: =N19-T19
B20: 16 | C20: Sidi Kacem | D20: DAR LAASLOUJI | E20: 40-21 | F20: Travaux de pistes | G20: Entretien des pistes agricoles | H20: Entretien des pistes agricoles | I20: 340000 | J20: km | K20: 1 | M20: =L20 | N20: =IFERROR(M20/K20,0) | O20: 0 | P20: =N20-O20 | U20: 0 | V20: =T20-U20 | W20: =N20-T20
B21: 17 | C21: Sidi Kacem | D21: HOUAFATE | E21: 20-11 | F21: Travaux de réhabilitation des équipements | G21: Travaux de réhabilitation des canaux portés d'irrigation | H21: Fourniture et de pose de canaux porté et accessoires du réseau S3 du secteur S13 | I21: 397934 | J21: ml | K21: 133 | M21: =L21 | N21: =IFERROR(M21/K21,0) | O21: 0 | P21: =N21-O21 | U21: 0 | V21: =T21-U21 | W21: =N21-T21
B22: 18 | C22: Sidi Kacem | D22: HOUAFATE | E22: 20-11 | F22: Travaux de réhabilitation des équipements | H22: Fourniture et de pose de canaux porté et accessoires du réseau T2S1 du secteur S13 | I22: 207575 | J22: ml | K22: 69 | M22: =L22 | N22: =IFERROR(M22/K22,0) | O22: 0 | P22: =N22-O22 | U22: 0 | V22: =T22-U22 | W22: =N22-T22
B23: 19 | C23: Sidi Kacem | D23: HOUAFATE | E23: 40-21 | F23: Travaux de pistes | G23: Entretien des pistes agricoles | H23: Entretien des pistes agricoles | I23: 2200000 | J23: km | K23: 4 | M23: =L23 | N23: =IFERROR(M23/K23,0) | O23: 0 | P23: =N23-O23 | U23: 0 | V23: =T23-U23 | W23: =N23-T23
B24: 20 | C24: Sidi Kacem | D24: HOUAFATE | E24: 50-23 | F24: Entretien et réparation du réseau d'assainissement et de drainage | G24: Curage des prises sur l’oued, bâche d’aspiration et bassin de régulation. | H24: Curage des prises sur l’oued de la station de pompage S17 et S13. Nettoyage des grilles de préfiltration des boues colmaté de la station de pompage S17 et S13. Curage de la bâche d’aspiration de la station S17 et S13. | I24: 300000 | J24: ml | K24: 100 | M24: =L24 | N24: =IFERROR(M24/K24,0) | O24: 0 | P24: =N24-O24 | U24: 0 | V24: =T24-U24 | W24: =N24-T24
B25: 21 | C25: Sidi Kacem | D25: HOUAFATE | E25: 50-21 | F25: Entretien et réparation des stations de pompage | G25: Prestation de maintenance des débitmètres et leurs équipements annexes installés au niveau des station de pompage | H25: Changement trois débitmètre Ø 600mm inondés de la station de pompage S13. | I25: 250000 | J25: U | K25: 3 | M25: =L25 | N25: =IFERROR(M25/K25,0) | O25: 0 | P25: =N25-O25 | U25: 0 | V25: =T25-U25 | W25: =N25-T25
B26: 22 | C26: Sidi Kacem | D26: HOUAFATE | E26: 50-21 | F26: Entretien et réparation des stations de pompage | G26: Prestations de maintenance des moteurs électriques des stations de pompage. | H26: Révision des trois moteurs électriques 200 KW principaux de la station S13. Révision des deux moteurs électriques 5,5 KW groupes vide de la station S13. | I26: 25000 | J26: U | K26: 3 | M26: =L26 | N26: =IFERROR(M26/K26,0) | O26: 0 | P26: =N26-O26 | U26: 0 | V26: =T26-U26 | W26: =N26-T26
B27: 23 | C27: Sidi Kacem | D27: HOUAFATE | E27: 50-21 | F27: Entretien et réparation des stations de pompage | G27: Prestations de maintenance et de réparation mécanique des pompes et des groupes motopompes submersibles des stations de pompage. | H27: Démontage et expertise des roues des pompes principaux et pompes a vide de la station S13. Changement des roulements, tresses et organes d’effectués de la station S13. | I27: 38000 | J27: U | K27: 1 | M27: =L27 | N27: =IFERROR(M27/K27,0) | O27: 0 | P27: =N27-O27 | U27: 0 | V27: =T27-U27 | W27: =N27-T27
B28: 24 | C28: Sidi Kacem | D28: HOUAFATE | E28: 50-21 | F28: Entretien et réparation des stations de pompage | G28: Stabilisation Berge oued | H28: Pose de gabions et recouvrement du talus par matelas Reno des stations de pompage S13. | I28: 10560000 | J28: m³ | K28: 7040 | M28: =L28 | N28: =IFERROR(M28/K28,0) | O28: 0 | P28: =N28-O28 | U28: 0 | V28: =T28-U28 | W28: =N28-T28
B29: 25 | C29: Sidi Kacem | D29: HOUAFATE | E29: 50-21 | F29: Entretien et réparation des stations de pompage | G29: Mur clôture des stations de pompage. | H29: Stabilisation du sol et reconstruction des murs clôture (270m) cote oued de la station S17. | I29: 144000 | J29: ml | K29: 270 | M29: =L29 | N29: =IFERROR(M29/K29,0) | O29: 0 | P29: =N29-O29 | U29: 0 | V29: =T29-U29 | W29: =N29-T29
B30: 26 | C30: Sidi Kacem | D30: HOUAFATE | E30: 50-21 | F30: Entretien et réparation des stations de pompage | G30: Génie civile des locaux des stations de pompage. | H30: Expertise d’état et d’étanchéité des locaux pompes, commande, puissance des stations de pompage S17 et S13. Renforcement d’étanchéité des locaux pompe sous niveau des oueds des stations de pompage S17 et S13. | I30: 800000 | J30: U | K30: 1 | M30: =L30 | N30: =IFERROR(M30/K30,0) | O30: 0 | P30: =N30-O30 | U30: 0 | V30: =T30-U30 | W30: =N30-T30
B31: 27 | C31: Sidi Kacem | D31: NOUIRAT | E31: 50-23 | F31: Entretien et réparation du réseau d'assainissement et de drainage | G31: Travaux de curage des canaux en terre | H31: Curage des collecteurs d'assainissement des secteurs EST1 et N5 | I31: 1733306 | J31: ml | K31: 867 | M31: =L31 | N31: =IFERROR(M31/K31,0) | O31: 0 | P31: =N31-O31 | U31: 0 | V31: =T31-U31 | W31: =N31-T31
B32: 28 | C32: Sidi Kacem | D32: NOUIRAT | E32: 40-21 | F32: Travaux de pistes | G32: Entretien des pistes agricoles | H32: Entretien des pistes agricoles | I32: 670000 | J32: km | K32: 1 | M32: =L32 | N32: =IFERROR(M32/K32,0) | O32: 0 | P32: =N32-O32 | U32: 0 | V32: =T32-U32 | W32: =N32-T32
B33: 29 | C33: Sidi Kacem | D33: NOUIRAT | E33: 20-11 | F33: Travaux de réhabilitation des équipements | G33: Travaux de réhabilitation des ouvrages de génie civil | H33: Réhabilitation de l'ouvrage( genie civil ,gabiollannage,clapet anti retour et buse) de l'ouvrage de débouche SE1 | I33: 2500000 | J33: U | K33: 5 | M33: =L33 | N33: =IFERROR(M33/K33,0) | O33: 0 | P33: =N33-O33 | U33: 0 | V33: =T33-U33 | W33: =N33-T33
B34: 30 | C34: Sidi Kacem | D34: NOUIRAT | E34: 50-23 | F34: Entretien et réparation du réseau d'assainissement et de drainage | G34: Curage des prises sur l’oued, bâche d’aspiration et bassin de régulation. | H34: Curage des prises sur l’oued de la station de pompage E1. Nettoyage des grilles de préfiltration des boues colmaté de la station de pompage E1. Curage de la bâche d’aspiration de la station E1. | I34: 800000 | J34: ml | K34: 267 | M34: =L34 | N34: =IFERROR(M34/K34,0) | O34: 0 | P34: =N34-O34 | U34: 0 | V34: =T34-U34 | W34: =N34-T34
... B42: 38 | C42: Sidi Kacem | D42: SAFSAF | E42: 20-11 | F42: Travaux de réhabilitation des équipements | G42: Travaux de réhabilitation des canaux portés d'irrigation | H42: Fourniture et pose de canaux porté et accessoires du réseau S4 du secteur S11 | I42: 232266 | J42: ml | K42: 77 | M42: =L42 | N42: =IFERROR(M42/K42,0) | O42: 0 | P42: =N42-O42 | U42: 0 | V42: =T42-U42 | W42: =N42-T42
B43: 39 | C43: Sidi Kacem | D43: SAFSAF | E43: 20-11 | F43: Travaux de réhabilitation des équipements | H43: Recalage des canaux portés du réseau T5S5 du secteur S9 | I43: 1055025 | J43: ml | K43: 352 | M43: =L43 | N43: =IFERROR(M43/K43,0) | O43: 0 | P43: =N43-O43 | U43: 0 | V43: =T43-U43 | W43: =N43-T43
B44: 40 | C44: Sidi Kacem | D44: SAFSAF | E44: 20-11 | F44: Travaux de réhabilitation des équipements | H44: Recalage des canaux portés du réseau T7S5 du secteur S9 | I44: 1004535 | J44: ml | K44: 335 | M44: =L44 | N44: =IFERROR(M44/K44,0) | O44: 0 | P44: =N44-O44 | U44: 0 | V44: =T44-U44 | W44: =N44-T44
B45: 41 | C45: Sidi Kacem | D45: SAFSAF | E45: 20-11 | F45: Travaux de réhabilitation des équipements | H45: Recalage des canaux portés du réseau T2S5 du secteur S9 | I45: 793830 | J45: ml | K45: 265 | M45: =L45 | N45: =IFERROR(M45/K45,0) | O45: 0 | P45: =N45-O45 | U45: 0 | V45: =T45-U45 | W45: =N45-T45
B46: 42 | C46: Sidi Kacem | D46: SAFSAF | E46: 40-21 | F46: Travaux de pistes | G46: Entretien des pistes agricoles | H46: Entretien des pistes agricoles | I46: 2000000 | J46: km | K46: 4 | M46: =L46 | N46: =IFERROR(M46/K46,0) | O46: 0 | P46: =N46-O46 | U46: 0 | V46: =T46-U46 | W46: =N46-T46
B47: 43 | C47: Sidi Kacem | D47: SAFSAF | E47: 50-23 | F47: Entretien et réparation du réseau d'assainissement et de drainage | G47: Curage des prises sur l’oued, bâche d’aspiration et bassin de régulation. | H47: Curage des prises sur l’oued des stations de pompage S11, S9, 7D et 7B. Nettoyage des grilles de préfiltration des boues colmaté des stations de pompage S11, S9, 7D et 7B. Nettoyage des crépines des boues colmaté de station pompage 7D. Curage des dalots et bâche d’aspiration des stations de pompage S11, S9, 7B. | I47: 200000 | J47: ml | K47: 67 | M47: =L47 | N47: =IFERROR(M47/K47,0) | O47: 0 | P47: =N47-O47 | U47: 0 | V47: =T47-U47 | W47: =N47-T47
B48: 44 | C48: Sidi Kacem | D48: SAFSAF | E48: 50-21 | F48: Entretien et réparation des stations de pompage | G48: Prestation de maintenance des débitmètres et leurs équipements annexes installés au niveau des station de pompage | H48: Changements Sept des débitmètres Ø 600mm inondé des deux stations de pompage S11 et S9. | I48: 580000 | J48: U | K48: 7 | M48: =L48 | N48: =IFERROR(M48/K48,0) | O48: 0 | P48: =N48-O48 | U48: 0 | V48: =T48-U48 | W48: =N48-T48
...

Sheet S02
B2: Suivi Hebdomadaire - Semaine 2 (05/01 - 11/01) — Janvier 2026 - Exécution Physique et Financière
B3: Date : | C3: 46027 | E3: IDENTIFICATION | J3: INDICATEURS PHYSIQUES | Q3: INDICATEURS FINANCIERS | W3: SYNTHÈSE
B4: N° | C4: Province | D4: Commune | E4: Rubrique | F4: Intitulé Rubrique | G4: Projet | H4: Consistance | I4: Coût Total (DH) | J4: Unité | K4: Qté Prévue | L4: Qté Réalisée Sem. | M4: Qté Réalisée Cumul | N4: Avancement Physique % | O4: % Phys. Sem. Préc. | P4: Accroissement Phys. % | Q4: Montant Décaissé (DH) | R4: Montant Payé (DH) | S4: Montant Ordonné (DH) | T4: Avancement Financier % | U4: % Fin. Sem. Préc. | V4: Accroissement Fin. % | W4: Écart Phys.-Fin. | X4: Observations
B5: 1 | C5: Sidi Kacem | D5: KHENICHET | E5: 50-23 | F5: Entretien et réparation du réseau d'assainissement et de drainage | G5: Travaux de curage des canaux en terre | H5: Curage des collecteurs d'assainissement du secteur EST2 | I5: 2091568 | J5: ml | K5: 1046 | M5: ='S01'!M5+L5 | N5: =IFERROR(M5/K5,0) | O5: ='S01'!N5 | P5: =N5-O5 | U5: ='S01'!T5 | V5: =T5-U5 | W5: =N5-T5
B6: 2 | C6: Sidi Kacem | D6: KHENICHET | E6: 40-21 | F6: Travaux de pistes | G6: Travaux de réhabilitation des pistes agricoles | H6: Entretien des pistes agricoles Douar Nouagra et Douar ouled Salem | I6: 78000 | J6: km | K6: 1 | M6: ='S01'!M6+L6 | N6: =IFERROR(M6/K6,0) | O6: ='S01'!N6 | P6: =N6-O6 | U6: ='S01'!T6 | V6: =T6-U6 | W6: =N6-T6
B7: 3 | C7: Sidi Kacem | D7: KHENICHET | E7: 50-23 | F7: Entretien et réparation du réseau d'assainissement et de drainage | G7: Curage des prises sur l’oued, bâche d’aspiration et bassin de régulation. | H7: Curage de la chambre des joints de démontage des siphonnes de la station de pompage EST2. | I7: 126000 | J7: ml | K7: 42 | M7: ='S01'!M7+L7 | N7: =IFERROR(M7/K7,0) | O7: ='S01'!N7 | P7: =N7-O7 | U7: ='S01'!T7 | V7: =T7-U7 | W7: =N7-T7
B8: 4 | C8: Sidi Kacem | D8: KHENICHET | E8: 50-21 | F8: Entretien et réparation des stations de pompage | G8: Prestation de maintenance des débitmètres et leurs équipements annexes installés au niveau des station de pompage | H8: Changement trois débitmètre Ø 600mm inondés de la station de pompage EST 2 et deux capteurs VEGASON 62 | I8: 165500 | J8: U | K8: 3 | M8: ='S01'!M8+L8 | N8: =IFERROR(M8/K8,0) | O8: ='S01'!N8 | P8: =N8-O8 | U8: ='S01'!T8 | V8: =T8-U8 | W8: =N8-T8
B9: 5 | C9: Sidi Kacem | D9: BIR TALEB | E9: 50-23 | F9: Entretien et réparation du réseau d'assainissement et de drainage | G9: Travaux de curage des canaux en terre | H9: Curage du canal d'assainisement Tihli Aval | I9: 1000000 | J9: ml | K9: 500 | M9: ='S01'!M9+L9 | N9: =IFERROR(M9/K9,0) | O9: ='S01'!N9 | P9: =N9-O9 | U9: ='S01'!T9 | V9: =T9-U9 | W9: =N9-T9
B10: 6 | C10: Sidi Kacem | D10: BIR TALEB | E10: 50-23 | F10: Entretien et réparation du réseau d'assainissement et de drainage | H10: Curage des collecteurs d'assainissement du secteur P11/1 | I10: 846731 | J10: ml | K10: 423 | M10: ='S01'!M10+L10 | N10: =IFERROR(M10/K10,0) | O10: ='S01'!N10 | P10: =N10-O10 | U10: ='S01'!T10 | V10: =T10-U10 | W10: =N10-T10
B11: 7 | C11: Sidi Kacem | D11: BIR TALEB | E11: 50-23 | F11: Entretien et réparation du réseau d'assainissement et de drainage | G11: Curage des prises sur l’oued, bâche d’aspiration et bassin de régulation. | H11: Curage des prises sur l’oued de la station de pompage P11/1. | I11: 200000 | J11: ml | K11: 67 | M11: ='S01'!M11+L11 | N11: =IFERROR(M11/K11,0) | O11: ='S01'!N11 | P11: =N11-O11 | U11: ='S01'!T11 | V11: =T11-U11 | W11: =N11-T11
B12: 8 | C12: Sidi Kacem | D12: BIR TALEB | E12: 50-21 | F12: Entretien et réparation des stations de pompage | G12: Prestation de maintenance des débitmètres et leurs équipements annexes installés au niveau des station de pompage | H12: Changement trois débitmètre Ø 400mm inondés de la station de pompage P11/1 | I12: 141900 | J12: U | K12: 3 | M12: ='S01'!M12+L12 | N12: =IFERROR(M12/K12,0) | O12: ='S01'!N12 | P12: =N12-O12 | U12: ='S01'!T12 | V12: =T12-U12 | W12: =N12-T12
B13: 9 | C13: Sidi Kacem | D13: BIR TALEB | E13: 50-21 | F13: Entretien et réparation des stations de pompage | G13: Prestations de maintenance et de réparation mécanique des pompes et des groupes motopompes submersibles des stations de pompage. | H13: Démontage et expertise des roues des pompes principaux et pompes a vide de la station P11/1 Changement des roulements, tresses et organes d’effectués de la station P11/1 | I13: 26700 | J13: U | K13: 1 | M13: ='S01'!M13+L13 | N13: =IFERROR(M13/K13,0) | O13: ='S01'!N13 | P13: =N13-O13 | U13: ='S01'!T13 | V13: =T13-U13 | W13: =N13-T13
B14: 10 | C14: Sidi Kacem | D14: BIR TALEB | E14: 50-21 | F14: Entretien et réparation des stations de pompage | G14: Stabilisation Berge oued | H14: Pose de gabions et recouvrement du talus par matelas Reno des stations de pompage P11/1. | I14: 480000 | J14: m³ | K14: 320 | M14: ='S01'!M14+L14 | N14: =IFERROR(M14/K14,0) | O14: ='S01'!N14 | P14: =N14-O14 | U14: ='S01'!T14 | V14: =T14-U14 | W14: =N14-T14
B15: 11 | C15: Sidi Kacem | D15: BIR TALEB | E15: 50-21 | F15: Entretien et réparation des stations de pompage | G15: Génie civile des locaux des stations de pompage. | H15: Expertise d’état et d’étanchéité des locaux pompes. Renforcement d’étanchéité des locaux pompe sous niveau des oueds des stations de pompage P11/1. Entretien des supports en béton des conduites d’aspiration. | I15: 300000 | J15: U | K15: 1 | M15: ='S01'!M15+L15 | N15: =IFERROR(M15/K15,0) | O15: ='S01'!N15 | P15: =N15-O15 | U15: ='S01'!T15 | V15: =T15-U15 | W15: =N15-T15
B16: 12 | C16: Sidi Kacem | D16: CHEBANAT | E16: 50-23 | F16: Entretien et réparation du réseau d'assainissement et de drainage | G16: Travaux de curage des canaux en terre | H16: Curage des collecteurs d'assainissement des secteur SH5 et SH6. | I16: 1000000 | J16: ml | K16: 500 | M16: ='S01'!M16+L16 | N16: =IFERROR(M16/K16,0) | O16: ='S01'!N16 | P16: =N16-O16 | U16: ='S01'!T16 | V16: =T16-U16 | W16: =N16-T16
B17: 13 | C17: Sidi Kacem | D17: CHEBANAT | E17: 50-23 | F17: Entretien et réparation du réseau d'assainissement et de drainage | G17: Travaux de curage des canaux révetus | H17: Curage du canal principal d'irrigation beht partie aval 1. | I17: 739200 | J17: ml | K17: 370 | M17: ='S01'!M17+L17 | N17: =IFERROR(M17/K17,0) | O17: ='S01'!N17 | P17: =N17-O17 | U17: ='S01'!T17 | V17: =T17-U17 | W17: =N17-T17
B18: 14 | C18: Sidi Kacem | D18: ZIRARA | E18: 50-23 | F18: Entretien et réparation du réseau d'assainissement et de drainage | G18: Travaux de curage des canaux révetus | H18: Curage du canal principal d'irrigation beht partie aval 2. | I18: 1276800 | J18: ml | K18: 638 | M18: ='S01'!M18+L18 | N18: =IFERROR(M18/K18,0) | O18: ='S01'!N18 | P18: =N18-O18 | U18: ='S01'!T18 | V18: =T18-U18 | W18: =N18-T18
B19: 15 | C19: Sidi Kacem | D19: DAR LAASLOUJI | E19: 50-23 | F19: Entretien et réparation du réseau d'assainissement et de drainage | G19: Travaux de curage des canaux en terre | H19: Curage des collecteurs d'assainissement des secteurs P8-1 et P8-2 | I19: 5796360 | J19: ml | K19: 2898 | M19: ='S01'!M19+L19 | N19: =IFERROR(M19/K19,0) | O19: ='S01'!N19 | P19: =N19-O19 | U19: ='S01'!T19 | V19: =T19-U19 | W19: =N19-T19
B20: 16 | C20: Sidi Kacem | D20: DAR LAASLOUJI | E20: 40-21 | F20: Travaux de pistes | G20: Entretien des pistes agricoles | H20: Entretien des pistes agricoles | I20: 340000 | J20: km | K20: 1 | M20: ='S01'!M20+L20 | N20: =IFERROR(M20/K20,0) | O20: ='S01'!N20 | P20: =N20-O20 | U20: ='S01'!T20 | V20: =T20-U20 | W20: =N20-T20
B21: 17 | C21: Sidi Kacem | D21: HOUAFATE | E21: 20-11 | F21: Travaux de réhabilitation des équipements | G21: Travaux de réhabilitation des canaux portés d'irrigation | H21: Fourniture et de pose de canaux porté et accessoires du réseau S3 du secteur S13 | I21: 397934 | J21: ml | K21: 133 | M21: ='S01'!M21+L21 | N21: =IFERROR(M21/K21,0) | O21: ='S01'!N21 | P21: =N21-O21 | U21: ='S01'!T21 | V21: =T21-U21 | W21: =N21-T21
B22: 18 | C22: Sidi Kacem | D22: HOUAFATE | E22: 20-11 | F22: Travaux de réhabilitation des équipements | H22: Fourniture et de pose de canaux porté et accessoires du réseau T2S1 du secteur S13 | I22: 207575 | J22: ml | K22: 69 | M22: ='S01'!M22+L22 | N22: =IFERROR(M22/K22,0) | O22: ='S01'!N22 | P22: =N22-O22 | U22: ='S01'!T22 | V22: =T22-U22 | W22: =N22-T22
B23: 19 | C23: Sidi Kacem | D23: HOUAFATE | E23: 40-21 | F23: Travaux de pistes | G23: Entretien des pistes agricoles | H23: Entretien des pistes agricoles | I23: 2200000 | J23: km | K23: 4 | M23: ='S01'!M23+L23 | N23: =IFERROR(M23/K23,0) | O23: ='S01'!N23 | P23: =N23-O23 | U23: ='S01'!T23 | V23: =T23-U23 | W23: =N23-T23
B24: 20 | C24: Sidi Kacem | D24: HOUAFATE | E24: 50-23 | F24: Entretien et réparation du réseau d'assainissement et de drainage | G24: Curage des prises sur l’oued, bâche d’aspiration et bassin de régulation. | H24: Curage des prises sur l’oued de la station de pompage S17 et S13. Nettoyage des grilles de préfiltration des boues colmaté de la station de pompage S17 et S13. Curage de la bâche d’aspiration de la station S17 et S13. | I24: 300000 | J24: ml | K24: 100 | M24: ='S01'!M24+L24 | N24: =IFERROR(M24/K24,0) | O24: ='S01'!N24 | P24: =N24-O24 | U24: ='S01'!T24 | V24: =T24-U24 | W24: =N24-T24
B25: 21 | C25: Sidi Kacem | D25: HOUAFATE | E25: 50-21 | F25: Entretien et réparation des stations de pompage | G25: Prestation de maintenance des débitmètres et leurs équipements annexes installés au niveau des station de pompage | H25: Changement trois débitmètre Ø 600mm inondés de la station de pompage S13. | I25: 250000 | J25: U | K25: 3 | M25: ='S01'!M25+L25 | N25: =IFERROR(M25/K25,0) | O25: ='S01'!N25 | P25: =N25-O25 | U25: ='S01'!T25 | V25: =T25-U25 | W25: =N25-T25
B26: 22 | C26: Sidi Kacem | D26: HOUAFATE | E26: 50-21 | F26: Entretien et réparation des stations de pompage | G26: Prestations de maintenance des moteurs électriques des stations de pompage. | H26: Révision des trois moteurs électriques 200 KW principaux de la station S13. Révision des deux moteurs électriques 5,5 KW groupes vide de la station S13. | I26: 25000 | J26: U | K26: 3 | M26: ='S01'!M26+L26 | N26: =IFERROR(M26/K26,0) | O26: ='S01'!N26 | P26: =N26-O26 | U26: ='S01'!T26 | V26: =T26-U26 | W26: =N26-T26
B27: 23 | C27: Sidi Kacem | D27: HOUAFATE | E27: 50-21 | F27: Entretien et réparation des stations de pompage | G27: Prestations de maintenance et de réparation mécanique des pompes et des groupes motopompes submersibles des stations de pompage. | H27: Démontage et expertise des roues des pompes principaux et pompes a vide de la station S13. Changement des roulements, tresses et organes d’effectués de la station S13. | I27: 38000 | J27: U | K27: 1 | M27: ='S01'!M27+L27 | N27: =IFERROR(M27/K27,0) | O27: ='S01'!N27 | P27: =N27-O27 | U27: ='S01'!T27 | V27: =T27-U27 | W27: =N27-T27
B28: 24 | C28: Sidi Kacem | D28: HOUAFATE | E28: 50-21 | F28: Entretien et réparation des stations de pompage | G28: Stabilisation Berge oued | H28: Pose de gabions et recouvrement du talus par matelas Reno des stations de pompage S13. | I28: 10560000 | J28: m³ | K28: 7040 | M28: ='S01'!M28+L28 | N28: =IFERROR(M28/K28,0) | O28: ='S01'!N28 | P28: =N28-O28 | U28: ='S01'!T28 | V28: =T28-U28 | W28: =N28-T28
B29: 25 | C29: Sidi Kacem | D29: HOUAFATE | E29: 50-21 | F29: Entretien et réparation des stations de pompage | G29: Mur clôture des stations de pompage. | H29: Stabilisation du sol et reconstruction des murs clôture (270m) cote oued de la station S17. | I29: 144000 | J29: ml | K29: 270 | M29: ='S01'!M29+L29 | N29: =IFERROR(M29/K29,0) | O29: ='S01'!N29 | P29: =N29-O29 | U29: ='S01'!T29 | V29: =T29-U29 | W29: =N29-T29
B30: 26 | C30: Sidi Kacem | D30: HOUAFATE | E30: 50-21 | F30: Entretien et réparation des stations de pompage | G30: Génie civile des locaux des stations de pompage. | H30: Expertise d’état et d’étanchéité des locaux pompes, commande, puissance des stations de pompage S17 et S13. Renforcement d’étanchéité des locaux pompe sous niveau des oueds des stations de pompage S17 et S13. | I30: 800000 | J30: U | K30: 1 | M30: ='S01'!M30+L30 | N30: =IFERROR(M30/K30,0) | O30: ='S01'!N30 | P30: =N30-O30 | U30: ='S01'!T30 | V30: =T30-U30 | W30: =N30-T30
B31: 27 | C31: Sidi Kacem | D31: NOUIRAT | E31: 50-23 | F31: Entretien et réparation du réseau d'assainissement et de drainage | G31: Travaux de curage des canaux en terre | H31: Curage des collecteurs d'assainissement des secteurs EST1 et N5 | I31: 1733306 | J31: ml | K31: 867 | M31: ='S01'!M31+L31 | N31: =IFERROR(M31/K31,0) | O31: ='S01'!N31 | P31: =N31-O31 | U31: ='S01'!T31 | V31: =T31-U31 | W31: =N31-T31
B32: 28 | C32: Sidi Kacem | D32: NOUIRAT | E32: 40-21 | F32: Travaux de pistes | G32: Entretien des pistes agricoles | H32: Entretien des pistes agricoles | I32: 670000 | J32: km | K32: 1 | M32: ='S01'!M32+L32 | N32: =IFERROR(M32/K32,0) | O32: ='S01'!N32 | P32: =N32-O32 | U32: ='S01'!T32 | V32: =T32-U32 | W32: =N32-T32
B33: 29 | C33: Sidi Kacem | D33: NOUIRAT | E33: 20-11 | F33: Travaux de réhabilitation des équipements | G33: Travaux de réhabilitation des ouvrages de génie civil | H33: Réhabilitation de l'ouvrage( genie civil ,gabiollannage,clapet anti retour et buse) de l'ouvrage de débouche SE1 | I33: 2500000 | J33: U | K33: 5 | M33: ='S01'!M33+L33 | N33: =IFERROR(M33/K33,0) | O33: ='S01'!N33 | P33: =N33-O33 | U33: ='S01'!T33 | V33: =T33-U33 | W33: =N33-T33
B34: 30 | C34: Sidi Kacem | D34: NOUIRAT | E34: 50-23 | F34: Entretien et réparation du réseau d'assainissement et de drainage | G34: Curage des prises sur l’oued, bâche d’aspiration et bassin de régulation. | H34: Curage des prises sur l’oued de la station de pompage E1. Nettoyage des grilles de préfiltration des boues colmaté de la station de pompage E1. Curage de la bâche d’aspiration de la station E1. | I34: 800000 | J34: ml | K34: 267 | M34: ='S01'!M34+L34 | N34: =IFERROR(M34/K34,0) | O34: ='S01'!N34 | P34: =N34-O34 | U34: ='S01'!T34 | V34: =T34-U34 | W34: =N34-T34
... B42: 38 | C42: Sidi Kacem | D42: SAFSAF | E42: 20-11 | F42: Travaux de réhabilitation des équipements | G42: Travaux de réhabilitation des canaux portés d'irrigation | H42: Fourniture et pose de canaux porté et accessoires du réseau S4 du secteur S11 | I42: 232266 | J42: ml | K42: 77 | M42: ='S01'!M42+L42 | N42: =IFERROR(M42/K42,0) | O42: ='S01'!N42 | P42: =N42-O42 | U42: ='S01'!T42 | V42: =T42-U42 | W42: =N42-T42
B43: 39 | C43: Sidi Kacem | D43: SAFSAF | E43: 20-11 | F43: Travaux de réhabilitation des équipements | H43: Recalage des canaux portés du réseau T5S5 du secteur S9 | I43: 1055025 | J43: ml | K43: 352 | M43: ='S01'!M43+L43 | N43: =IFERROR(M43/K43,0) | O43: ='S01'!N43 | P43: =N43-O43 | U43: ='S01'!T43 | V43: =T43-U43 | W43: =N43-T43
B44: 40 | C44: Sidi Kacem | D44: SAFSAF | E44: 20-11 | F44: Travaux de réhabilitation des équipements | H44: Recalage des canaux portés du réseau T7S5 du secteur S9 | I44: 1004535 | J44: ml | K44: 335 | M44: ='S01'!M44+L44 | N44: =IFERROR(M44/K44,0) | O44: ='S01'!N44 | P44: =N44-O44 | U44: ='S01'!T44 | V44: =T44-U44 | W44: =N44-T44
B45: 41 | C45: Sidi Kacem | D45: SAFSAF | E45: 20-11 | F45: Travaux de réhabilitation des équipements | H45: Recalage des canaux portés du réseau T2S5 du secteur S9 | I45: 793830 | J45: ml | K45: 265 | M45: ='S01'!M45+L45 | N45: =IFERROR(M45/K45,0) | O45: ='S01'!N45 | P45: =N45-O45 | U45: ='S01'!T45 | V45: =T45-U45 | W45: =N45-T45
B46: 42 | C46: Sidi Kacem | D46: SAFSAF | E46: 40-21 | F46: Travaux de pistes | G46: Entretien des pistes agricoles | H46: Entretien des pistes agricoles | I46: 2000000 | J46: km | K46: 4 | M46: ='S01'!M46+L46 | N46: =IFERROR(M46/K46,0) | O46: ='S01'!N46 | P46: =N46-O46 | U46: ='S01'!T46 | V46: =T46-U46 | W46: =N46-T46
B47: 43 | C47: Sidi Kacem | D47: SAFSAF | E47: 50-23 | F47: Entretien et réparation du réseau d'assainissement et de drainage | G47: Curage des prises sur l’oued, bâche d’aspiration et bassin de régulation. | H47: Curage des prises sur l’oued des stations de pompage S11, S9, 7D et 7B. Nettoyage des grilles de préfiltration des boues colmaté des stations de pompage S11, S9, 7D et 7B. Nettoyage des crépines des boues colmaté de station pompage 7D. Curage des dalots et bâche d’aspiration des stations de pompage S11, S9, 7B. | I47: 200000 | J47: ml | K47: 67 | M47: ='S01'!M47+L47 | N47: =IFERROR(M47/K47,0) | O47: ='S01'!N47 | P47: =N47-O47 | U47: ='S01'!T47 | V47: =T47-U47 | W47: =N47-T47
B48: 44 | C48: Sidi Kacem | D48: SAFSAF | E48: 50-21 | F48: Entretien et réparation des stations de pompage | G48: Prestation de maintenance des débitmètres et leurs équipements annexes installés au niveau des station de pompage | H48: Changements Sept des débitmètres Ø 600mm inondé des deux stations de pompage S11 et S9. | I48: 580000 | J48: U | K48: 7 | M48: ='S01'!M48+L48 | N48: =IFERROR(M48/K48,0) | O48: ='S01'!N48 | P48: =N48-O48 | U48: ='S01'!T48 | V48: =T48-U48 | W48: =N48-T48
...

Sheet S03
B2: Suivi Hebdomadaire - Semaine 3 (12/01 - 18/01) — Janvier 2026 - Exécution Physique et Financière
B3: Date : | C3: 46034 | E3: IDENTIFICATION | J3: INDICATEURS PHYSIQUES | Q3: INDICATEURS FINANCIERS | W3: SYNTHÈSE
B4: N° | C4: Province | D4: Commune | E4: Rubrique | F4: Intitulé Rubrique | G4: Projet | H4: Consistance | I4: Coût Total (DH) | J4: Unité | K4: Qté Prévue | L4: Qté Réalisée Sem. | M4: Qté Réalisée Cumul | N4: Avancement Physique % | O4: % Phys. Sem. Préc. | P4: Accroissement Phys. % | Q4: Montant Décaissé (DH) | R4: Montant Payé (DH) | S4: Montant Ordonné (DH) | T4: Avancement Financier % | U4: % Fin. Sem. Préc. | V4: Accroissement Fin. % | W4: Écart Phys.-Fin. | X4: Observations
B5: 1 | C5: Sidi Kacem | D5: KHENICHET | E5: 50-23 | F5: Entretien et réparation du réseau d'assainissement et de drainage | G5: Travaux de curage des canaux en terre | H5: Curage des collecteurs d'assainissement du secteur EST2 | I5: 2091568 | J5: ml | K5: 1046 | M5: ='S02'!M5+L5 | N5: =IFERROR(M5/K5,0) | O5: ='S02'!N5 | P5: =N5-O5 | U5: ='S02'!T5 | V5: =T5-U5 | W5: =N5-T5
B6: 2 | C6: Sidi Kacem | D6: KHENICHET | E6: 40-21 | F6: Travaux de pistes | G6: Travaux de réhabilitation des pistes agricoles | H6: Entretien des pistes agricoles Douar Nouagra et Douar ouled Salem | I6: 78000 | J6: km | K6: 1 | M6: ='S02'!M6+L6 | N6: =IFERROR(M6/K6,0) | O6: ='S02'!N6 | P6: =N6-O6 | U6: ='S02'!T6 | V6: =T6-U6 | W6: =N6-T6
B7: 3 | C7: Sidi Kacem | D7: KHENICHET | E7: 50-23 | F7: Entretien et réparation du réseau d'assainissement et de drainage | G7: Curage des prises sur l’oued, bâche d’aspiration et bassin de régulation. | H7: Curage de la chambre des joints de démontage des siphonnes de la station de pompage EST2. | I7: 126000 | J7: ml | K7: 42 | M7: ='S02'!M7+L7 | N7: =IFERROR(M7/K7,0) | O7: ='S02'!N7 | P7: =N7-O7 | U7: ='S02'!T7 | V7: =T7-U7 | W7: =N7-T7
B8: 4 | C8: Sidi Kacem | D8: KHENICHET | E8: 50-21 | F8: Entretien et réparation des stations de pompage | G8: Prestation de maintenance des débitmètres et leurs équipements annexes installés au niveau des station de pompage | H8: Changement trois débitmètre Ø 600mm inondés de la station de pompage EST 2 et deux capteurs VEGASON 62 | I8: 165500 | J8: U | K8: 3 | M8: ='S02'!M8+L8 | N8: =IFERROR(M8/K8,0) | O8: ='S02'!N8 | P8: =N8-O8 | U8: ='S02'!T8 | V8: =T8-U8 | W8: =N8-T8
B9: 5 | C9: Sidi Kacem | D9: BIR TALEB | E9: 50-23 | F9: Entretien et réparation du réseau d'assainissement et de drainage | G9: Travaux de curage des canaux en terre | H9: Curage du canal d'assainisement Tihli Aval | I9: 1000000 | J9: ml | K9: 500 | M9: ='S02'!M9+L9 | N9: =IFERROR(M9/K9,0) | O9: ='S02'!N9 | P9: =N9-O9 | U9: ='S02'!T9 | V9: =T9-U9 | W9: =N9-T9
B10: 6 | C10: Sidi Kacem | D10: BIR TALEB | E10: 50-23 | F10: Entretien et réparation du réseau d'assainissement et de drainage | H10: Curage des collecteurs d'assainissement du secteur P11/1 | I10: 846731 | J10: ml | K10: 423 | M10: ='S02'!M10+L10 | N10: =IFERROR(M10/K10,0) | O10: ='S02'!N10 | P10: =N10-O10 | U10: ='S02'!T10 | V10: =T10-U10 | W10: =N10-T10
B11: 7 | C11: Sidi Kacem | D11: BIR TALEB | E11: 50-23 | F11: Entretien et réparation du réseau d'assainissement et de drainage | G11: Curage des prises sur l’oued, bâche d’aspiration et bassin de régulation. | H11: Curage des prises sur l’oued de la station de pompage P11/1. | I11: 200000 | J11: ml | K11: 67 | M11: ='S02'!M11+L11 | N11: =IFERROR(M11/K11,0) | O11: ='S02'!N11 | P11: =N11-O11 | U11: ='S02'!T11 | V11: =T11-U11 | W11: =N11-T11
B12: 8 | C12: Sidi Kacem | D12: BIR TALEB | E12: 50-21 | F12: Entretien et réparation des stations de pompage | G12: Prestation de maintenance des débitmètres et leurs équipements annexes installés au niveau des station de pompage | H12: Changement trois débitmètre Ø 400mm inondés de la station de pompage P11/1 | I12: 141900 | J12: U | K12: 3 | M12: ='S02'!M12+L12 | N12: =IFERROR(M12/K12,0) | O12: ='S02'!N12 | P12: =N12-O12 | U12: ='S02'!T12 | V12: =T12-U12 | W12: =N12-T12
B13: 9 | C13: Sidi Kacem | D13: BIR TALEB | E13: 50-21 | F13: Entretien et réparation des stations de pompage | G13: Prestations de maintenance et de réparation mécanique des pompes et des groupes motopompes submersibles des stations de pompage. | H13: Démontage et expertise des roues des pompes principaux et pompes a vide de la station P11/1 Changement des roulements, tresses et organes d’effectués de la station P11/1 | I13: 26700 | J13: U | K13: 1 | M13: ='S02'!M13+L13 | N13: =IFERROR(M13/K13,0) | O13: ='S02'!N13 | P13: =N13-O13 | U13: ='S02'!T13 | V13: =T13-U13 | W13: =N13-T13
B14: 10 | C14: Sidi Kacem | D14: BIR TALEB | E14: 50-21 | F14: Entretien et réparation des stations de pompage | G14: Stabilisation Berge oued | H14: Pose de gabions et recouvrement du talus par matelas Reno des stations de pompage P11/1. | I14: 480000 | J14: m³ | K14: 320 | M14: ='S02'!M14+L14 | N14: =IFERROR(M14/K14,0) | O14: ='S02'!N14 | P14: =N14-O14 | U14: ='S02'!T14 | V14: =T14-U14 | W14: =N14-T14
B15: 11 | C15: Sidi Kacem | D15: BIR TALEB | E15: 50-21 | F15: Entretien et réparation des stations de pompage | G15: Génie civile des locaux des stations de pompage. | H15: Expertise d’état et d’étanchéité des locaux pompes. Renforcement d’étanchéité des locaux pompe sous niveau des oueds des stations de pompage P11/1. Entretien des supports en béton des conduites d’aspiration. | I15: 300000 | J15: U | K15: 1 | M15: ='S02'!M15+L15 | N15: =IFERROR(M15/K15,0) | O15: ='S02'!N15 | P15: =N15-O15 | U15: ='S02'!T15 | V15: =T15-U15 | W15: =N15-T15
B16: 12 | C16: Sidi Kacem | D16: CHEBANAT | E16: 50-23 | F16: Entretien et réparation du réseau d'assainissement et de drainage | G16: Travaux de curage des canaux en terre | H16: Curage des collecteurs d'assainissement des secteur SH5 et SH6. | I16: 1000000 | J16: ml | K16: 500 | M16: ='S02'!M16+L16 | N16: =IFERROR(M16/K16,0) | O16: ='S02'!N16 | P16: =N16-O16 | U16: ='S02'!T16 | V16: =T16-U16 | W16: =N16-T16
B17: 13 | C17: Sidi Kacem | D17: CHEBANAT | E17: 50-23 | F17: Entretien et réparation du réseau d'assainissement et de drainage | G17: Travaux de curage des canaux révetus | H17: Curage du canal principal d'irrigation beht partie aval 1. | I17: 739200 | J17: ml | K17: 370 | M17: ='S02'!M17+L17 | N17: =IFERROR(M17/K17,0) | O17: ='S02'!N17 | P17: =N17-O17 | U17: ='S02'!T17 | V17: =T17-U17 | W17: =N17-T17
B18: 14 | C18: Sidi Kacem | D18: ZIRARA | E18: 50-23 | F18: Entretien et réparation du réseau d'assainissement et de drainage | G18: Travaux de curage des canaux révetus | H18: Curage du canal principal d'irrigation beht partie aval 2. | I18: 1276800 | J18: ml | K18: 638 | M18: ='S02'!M18+L18 | N18: =IFERROR(M18/K18,0) | O18: ='S02'!N18 | P18: =N18-O18 | U18: ='S02'!T18 | V18: =T18-U18 | W18: =N18-T18
B19: 15 | C19: Sidi Kacem | D19: DAR LAASLOUJI | E19: 50-23 | F19: Entretien et réparation du réseau d'assainissement et de drainage | G19: Travaux de curage des canaux en terre | H19: Curage des collecteurs d'assainissement des secteurs P8-1 et P8-2 | I19: 5796360 | J19: ml | K19: 2898 | M19: ='S02'!M19+L19 | N19: =IFERROR(M19/K19,0) | O19: ='S02'!N19 | P19: =N19-O19 | U19: ='S02'!T19 | V19: =T19-U19 | W19: =N19-T19
B20: 16 | C20: Sidi Kacem | D20: DAR LAASLOUJI | E20: 40-21 | F20: Travaux de pistes | G20: Entretien des pistes agricoles | H20: Entretien des pistes agricoles | I20: 340000 | J20: km | K20: 1 | M20: ='S02'!M20+L20 | N20: =IFERROR(M20/K20,0) | O20: ='S02'!N20 | P20: =N20-O20 | U20: ='S02'!T20 | V20: =T20-U20 | W20: =N20-T20
B21: 17 | C21: Sidi Kacem | D21: HOUAFATE | E21: 20-11 | F21: Travaux de réhabilitation des équipements | G21: Travaux de réhabilitation des canaux portés d'irrigation | H21: Fourniture et de pose de canaux porté et accessoires du réseau S3 du secteur S13 | I21: 397934 | J21: ml | K21: 133 | M21: ='S02'!M21+L21 | N21: =IFERROR(M21/K21,0) | O21: ='S02'!N21 | P21: =N21-O21 | U21: ='S02'!T21 | V21: =T21-U21 | W21: =N21-T21
B22: 18 | C22: Sidi Kacem | D22: HOUAFATE | E22: 20-11 | F22: Travaux de réhabilitation des équipements | H22: Fourniture et de pose de canaux porté et accessoires du réseau T2S1 du secteur S13 | I22: 207575 | J22: ml | K22: 69 | M22: ='S02'!M22+L22 | N22: =IFERROR(M22/K22,0) | O22: ='S02'!N22 | P22: =N22-O22 | U22: ='S02'!T22 | V22: =T22-U22 | W22: =N22-T22
B23: 19 | C23: Sidi Kacem | D23: HOUAFATE | E23: 40-21 | F23: Travaux de pistes | G23: Entretien des pistes agricoles | H23: Entretien des pistes agricoles | I23: 2200000 | J23: km | K23: 4 | M23: ='S02'!M23+L23 | N23: =IFERROR(M23/K23,0) | O23: ='S02'!N23 | P23: =N23-O23 | U23: ='S02'!T23 | V23: =T23-U23 | W23: =N23-T23
B24: 20 | C24: Sidi Kacem | D24: HOUAFATE | E24: 50-23 | F24: Entretien et réparation du réseau d'assainissement et de drainage | G24: Curage des prises sur l’oued, bâche d’aspiration et bassin de régulation. | H24: Curage des prises sur l’oued de la station de pompage S17 et S13. Nettoyage des grilles de préfiltration des boues colmaté de la station de pompage S17 et S13. Curage de la bâche d’aspiration de la station S17 et S13. | I24: 300000 | J24: ml | K24: 100 | M24: ='S02'!M24+L24 | N24: =IFERROR(M24/K24,0) | O24: ='S02'!N24 | P24: =N24-O24 | U24: ='S02'!T24 | V24: =T24-U24 | W24: =N24-T24
B25: 21 | C25: Sidi Kacem | D25: HOUAFATE | E25: 50-21 | F25: Entretien et réparation des stations de pompage | G25: Prestation de maintenance des débitmètres et leurs équipements annexes installés au niveau des station de pompage | H25: Changement trois débitmètre Ø 600mm inondés de la station de pompage S13. | I25: 250000 | J25: U | K25: 3 | M25: ='S02'!M25+L25 | N25: =IFERROR(M25/K25,0) | O25: ='S02'!N25 | P25: =N25-O25 | U25: ='S02'!T25 | V25: =T25-U25 | W25: =N25-T25
B26: 22 | C26: Sidi Kacem | D26: HOUAFATE | E26: 50-21 | F26: Entretien et réparation des stations de pompage | G26: Prestations de maintenance des moteurs électriques des stations de pompage. | H26: Révision des trois moteurs électriques 200 KW principaux de la station S13. Révision des deux moteurs électriques 5,5 KW groupes vide de la station S13. | I26: 25000 | J26: U | K26: 3 | M26: ='S02'!M26+L26 | N26: =IFERROR(M26/K26,0) | O26: ='S02'!N26 | P26: =N26-O26 | U26: ='S02'!T26 | V26: =T26-U26 | W26: =N26-T26
B27: 23 | C27: Sidi Kacem | D27: HOUAFATE | E27: 50-21 | F27: Entretien et réparation des stations de pompage | G27: Prestations de maintenance et de réparation mécanique des pompes et des groupes motopompes submersibles des stations de pompage. | H27: Démontage et expertise des roues des pompes principaux et pompes a vide de la station S13. Changement des roulements, tresses et organes d’effectués de la station S13. | I27: 38000 | J27: U | K27: 1 | M27: ='S02'!M27+L27 | N27: =IFERROR(M27/K27,0) | O27: ='S02'!N27 | P27: =N27-O27 | U27: ='S02'!T27 | V27: =T27-U27 | W27: =N27-T27
B28: 24 | C28: Sidi Kacem | D28: HOUAFATE | E28: 50-21 | F28: Entretien et réparation des stations de pompage | G28: Stabilisation Berge oued | H28: Pose de gabions et recouvrement du talus par matelas Reno des stations de pompage S13. | I28: 10560000 | J28: m³ | K28: 7040 | M28: ='S02'!M28+L28 | N28: =IFERROR(M28/K28,0) | O28: ='S02'!N28 | P28: =N28-O28 | U28: ='S02'!T28 | V28: =T28-U28 | W28: =N28-T28
B29: 25 | C29: Sidi Kacem | D29: HOUAFATE | E29: 50-21 | F29: Entretien et réparation des stations de pompage | G29: Mur clôture des stations de pompage. | H29: Stabilisation du sol et reconstruction des murs clôture (270m) cote oued de la station S17. | I29: 144000 | J29: ml | K29: 270 | M29: ='S02'!M29+L29 | N29: =IFERROR(M29/K29,0) | O29: ='S02'!N29 | P29: =N29-O29 | U29: ='S02'!T29 | V29: =T29-U29 | W29: =N29-T29
B30: 26 | C30: Sidi Kacem | D30: HOUAFATE | E30: 50-21 | F30: Entretien et réparation des stations de pompage | G30: Génie civile des locaux des stations de pompage. | H30: Expertise d’état et d’étanchéité des locaux pompes, commande, puissance des stations de pompage S17 et S13. Renforcement d’étanchéité des locaux pompe sous niveau des oueds des stations de pompage S17 et S13. | I30: 800000 | J30: U | K30: 1 | M30: ='S02'!M30+L30 | N30: =IFERROR(M30/K30,0) | O30: ='S02'!N30 | P30: =N30-O30 | U30: ='S02'!T30 | V30: =T30-U30 | W30: =N30-T30
B31: 27 | C31: Sidi Kacem | D31: NOUIRAT | E31: 50-23 | F31: Entretien et réparation du réseau d'assainissement et de drainage | G31: Travaux de curage des canaux en terre | H31: Curage des collecteurs d'assainissement des secteurs EST1 et N5 | I31: 1733306 | J31: ml | K31: 867 | M31: ='S02'!M31+L31 | N31: =IFERROR(M31/K31,0) | O31: ='S02'!N31 | P31: =N31-O31 | U31: ='S02'!T31 | V31: =T31-U31 | W31: =N31-T31
B32: 28 | C32: Sidi Kacem | D32: NOUIRAT | E32: 40-21 | F32: Travaux de pistes | G32: Entretien des pistes agricoles | H32: Entretien des pistes agricoles | I32: 670000 | J32: km | K32: 1 | M32: ='S02'!M32+L32 | N32: =IFERROR(M32/K32,0) | O32: ='S02'!N32 | P32: =N32-O32 | U32: ='S02'!T32 | V32: =T32-U32 | W32: =N32-T32
B33: 29 | C33: Sidi Kacem | D33: NOUIRAT | E33: 20-11 | F33: Travaux de réhabilitation des équipements | G33: Travaux de réhabilitation des ouvrages de génie civil | H33: Réhabilitation de l'ouvrage( genie civil ,gabiollannage,clapet anti retour et buse) de l'ouvrage de débouche SE1 | I33: 2500000 | J33: U | K33: 5 | M33: ='S02'!M33+L33 | N33: =IFERROR(M33/K33,0) | O33: ='S02'!N33 | P33: =N33-O33 | U33: ='S02'!T33 | V33: =T33-U33 | W33: =N33-T33
