Workbook

Sheet Suivi des Projets
B2: Suivi Physique et Financier des Projets — Région du Gharb 2026 (Juin–Décembre)
B4: N° | C4: Province | D4: Commune | E4: Rubrique | F4: Intitulé Rubrique | G4: Intitulé Projet | H4: Consistance | I4: Budget Prévu (DH) | J4: Avancement Physique (%) | K4: Avancement Financier (%) | L4: Montant Décaissé (DH) | M4: Reste à Décaisser (DH) | N4: Taux de Décaissement (%) | O4: Écart Phys.-Fin. (pts) | P4: Statut | Q4: Observations | R4: N° Consultation | S4: Société Titulaire | T4: Date Ouverture Plis | U4: Date Jugement | V4: Date OSC | W4: Délai Exécution (j) | X4: Date Réception Provisoire
B5: 1 | C5: Sidi Kacem | D5: KHENICHET | E5: 50-23 | F5: Entretien et réparation du réseau d'assainissement et de drainage | G5: Travaux de curage des canaux en terre | H5: Curage des collecteurs d'assainissement du secteur EST2 | I5: 2091568 | M5: =IF(L5="","",I5-L5) | N5: =IFERROR(IF(L5="","",L5/I5),"") | O5: =IFERROR(IF(OR(J5="",K5=""),"",J5-K5),"")
B6: 2 | C6: Sidi Kacem | D6: KHENICHET | E6: 40-21 | F6: Travaux de pistes | G6: Travaux de réhabilitation des pistes agricoles | H6: Entretien des pistes agricoles Douar Nouagra et Douar ouled Salem | I6: 78000 | M6: =IF(L6="","",I6-L6) | N6: =IFERROR(IF(L6="","",L6/I6),"") | O6: =IFERROR(IF(OR(J6="",K6=""),"",J6-K6),"")
B7: 3 | C7: Sidi Kacem | D7: KHENICHET | E7: 50-23 | F7: Entretien et réparation du réseau d'assainissement et de drainage | G7: Curage des prises sur l'oued, bâche d'aspiration et bassin de régulation. | H7: Curage de la chambre des joints de démontage des siphonnes de la station de pompage EST2. | I7: 126000 | M7: =IF(L7="","",I7-L7) | N7: =IFERROR(IF(L7="","",L7/I7),"") | O7: =IFERROR(IF(OR(J7="",K7=""),"",J7-K7),"")
B8: 4 | C8: Sidi Kacem | D8: KHENICHET | E8: 50-21 | F8: Entretien et réparation des stations de pompage | G8: Prestation de maintenance des débitmètres et leurs équipements annexes | H8: Changement trois débitmètre Ø 600mm inondés de la station de pompage EST 2 et deux capteurs VEGASON 62 | I8: 165500 | M8: =IF(L8="","",I8-L8) | N8: =IFERROR(IF(L8="","",L8/I8),"") | O8: =IFERROR(IF(OR(J8="",K8=""),"",J8-K8),"")
B9: 5 | C9: Sidi Kacem | D9: BIR TALEB | E9: 50-23 | F9: Entretien et réparation du réseau d'assainissement et de drainage | G9: Travaux de curage des canaux en terre | H9: Curage du canal d'assainisement Tihli Aval | I9: 1000000 | M9: =IF(L9="","",I9-L9) | N9: =IFERROR(IF(L9="","",L9/I9),"") | O9: =IFERROR(IF(OR(J9="",K9=""),"",J9-K9),"")
B10: 6 | C10: Sidi Kacem | D10: BIR TALEB | E10: 50-23 | F10: Entretien et réparation du réseau d'assainissement et de drainage | H10: Curage des collecteurs d'assainissement du secteur P11/1 | I10: 846731 | M10: =IF(L10="","",I10-L10) | N10: =IFERROR(IF(L10="","",L10/I10),"") | O10: =IFERROR(IF(OR(J10="",K10=""),"",J10-K10),"")
B11: 7 | C11: Sidi Kacem | D11: BIR TALEB | E11: 50-23 | F11: Entretien et réparation du réseau d'assainissement et de drainage | G11: Curage des prises sur l'oued, bâche d'aspiration et bassin de régulation. | H11: Curage des prises sur l'oued de la station de pompage P11/1. | I11: 200000 | M11: =IF(L11="","",I11-L11) | N11: =IFERROR(IF(L11="","",L11/I11),"") | O11: =IFERROR(IF(OR(J11="",K11=""),"",J11-K11),"")
B12: 8 | C12: Sidi Kacem | D12: BIR TALEB | E12: 50-21 | F12: Entretien et réparation des stations de pompage | G12: Prestation de maintenance des débitmètres et leurs équipements annexes | H12: Changement trois débitmètre Ø 400mm inondés de la station de pompage P11/1 | I12: 141900 | M12: =IF(L12="","",I12-L12) | N12: =IFERROR(IF(L12="","",L12/I12),"") | O12: =IFERROR(IF(OR(J12="",K12=""),"",J12-K12),"")
B13: 9 | C13: Sidi Kacem | D13: BIR TALEB | E13: 50-21 | F13: Entretien et réparation des stations de pompage | G13: Prestations de maintenance et de réparation mécanique des pompes et des groupes motopompes submersibles | H13: Démontage et expertise des roues des pompes principaux et pompes a vide de la station P11/1 | I13: 26700 | M13: =IF(L13="","",I13-L13) | N13: =IFERROR(IF(L13="","",L13/I13),"") | O13: =IFERROR(IF(OR(J13="",K13=""),"",J13-K13),"")
B14: 10 | C14: Sidi Kacem | D14: BIR TALEB | E14: 50-21 | F14: Entretien et réparation des stations de pompage | G14: Stabilisation Berge oued | H14: Pose de gabions et recouvrement du talus par matelas Reno des stations de pompage P11/1. | I14: 480000 | M14: =IF(L14="","",I14-L14) | N14: =IFERROR(IF(L14="","",L14/I14),"") | O14: =IFERROR(IF(OR(J14="",K14=""),"",J14-K14),"")
B15: 11 | C15: Sidi Kacem | D15: BIR TALEB | E15: 50-21 | F15: Entretien et réparation des stations de pompage | G15: Génie civile des locaux des stations de pompage. | H15: Expertise d'état et d'étanchéité des locaux pompes. | I15: 300000 | M15: =IF(L15="","",I15-L15) | N15: =IFERROR(IF(L15="","",L15/I15),"") | O15: =IFERROR(IF(OR(J15="",K15=""),"",J15-K15),"")
B16: 12 | C16: Sidi Kacem | D16: CHEBANAT | E16: 50-23 | F16: Entretien et réparation du réseau d'assainissement et de drainage | G16: Travaux de curage des canaux en terre | H16: Curage des collecteurs d'assainissement des secteur SH5 et SH6. | I16: 1000000 | M16: =IF(L16="","",I16-L16) | N16: =IFERROR(IF(L16="","",L16/I16),"") | O16: =IFERROR(IF(OR(J16="",K16=""),"",J16-K16),"")
B17: 13 | C17: Sidi Kacem | D17: CHEBANAT | E17: 50-23 | F17: Entretien et réparation du réseau d'assainissement et de drainage | G17: Travaux de curage des canaux révetés | H17: Curage du canal principal d'irrigation beht partie aval 1. | I17: 739200 | M17: =IF(L17="","",I17-L17) | N17: =IFERROR(IF(L17="","",L17/I17),"") | O17: =IFERROR(IF(OR(J17="",K17=""),"",J17-K17),"")
B18: 14 | C18: Sidi Kacem | D18: ZIRARA | E18: 50-23 | F18: Entretien et réparation du réseau d'assainissement et de drainage | G18: Travaux de curage des canaux révetés | H18: Curage du canal principal d'irrigation beht partie aval 2. | I18: 1276800 | M18: =IF(L18="","",I18-L18) | N18: =IFERROR(IF(L18="","",L18/I18),"") | O18: =IFERROR(IF(OR(J18="",K18=""),"",J18-K18),"")
B19: 15 | C19: Sidi Kacem | D19: DAR LAASLOUJI | E19: 50-23 | F19: Entretien et réparation du réseau d'assainissement et de drainage | G19: Travaux de curage des canaux en terre | H19: Curage des collecteurs d'assainissement des secteurs P8-1 et P8-2 | I19: 5796360 | M19: =IF(L19="","",I19-L19) | N19: =IFERROR(IF(L19="","",L19/I19),"") | O19: =IFERROR(IF(OR(J19="",K19=""),"",J19-K19),"")
B20: 16 | C20: Sidi Kacem | D20: DAR LAASLOUJI | E20: 40-21 | F20: Travaux de pistes | G20: Entretien des pistes agricoles | H20: Entretien des pistes agricoles | I20: 340000 | M20: =IF(L20="","",I20-L20) | N20: =IFERROR(IF(L20="","",L20/I20),"") | O20: =IFERROR(IF(OR(J20="",K20=""),"",J20-K20),"")
B21: 17 | C21: Sidi Kacem | D21: HOUAFATE | E21: 20-11 | F21: Travaux de réhabilitation des équipements | G21: Travaux de réhabilitation des canaux portés d'irrigation | H21: Fourniture et de pose de canaux porté et accessoires du réseau S3 du secteur S13 | I21: 397934 | M21: =IF(L21="","",I21-L21) | N21: =IFERROR(IF(L21="","",L21/I21),"") | O21: =IFERROR(IF(OR(J21="",K21=""),"",J21-K21),"")
B22: 18 | C22: Sidi Kacem | D22: HOUAFATE | E22: 20-11 | F22: Travaux de réhabilitation des équipements | H22: Fourniture et de pose de canaux porté et accessoires du réseau T2S1 du secteur S13 | I22: 207575 | M22: =IF(L22="","",I22-L22) | N22: =IFERROR(IF(L22="","",L22/I22),"") | O22: =IFERROR(IF(OR(J22="",K22=""),"",J22-K22),"")
B23: 19 | C23: Sidi Kacem | D23: HOUAFATE | E23: 40-21 | F23: Travaux de pistes | G23: Entretien des pistes agricoles | H23: Entretien des pistes agricoles | I23: 2200000 | M23: =IF(L23="","",I23-L23) | N23: =IFERROR(IF(L23="","",L23/I23),"") | O23: =IFERROR(IF(OR(J23="",K23=""),"",J23-K23),"")
B24: 20 | C24: Sidi Kacem | D24: HOUAFATE | E24: 50-23 | F24: Entretien et réparation du réseau d'assainissement et de drainage | G24: Curage des prises sur l'oued, bâche d'aspiration et bassin de régulation. | H24: Curage des prises sur l'oued de la station de pompage S17 et S13. | I24: 300000 | M24: =IF(L24="","",I24-L24) | N24: =IFERROR(IF(L24="","",L24/I24),"") | O24: =IFERROR(IF(OR(J24="",K24=""),"",J24-K24),"")
B25: 21 | C25: Sidi Kacem | D25: HOUAFATE | E25: 50-21 | F25: Entretien et réparation des stations de pompage | G25: Prestation de maintenance des débitmètres et leurs équipements annexes | H25: Changement trois débitmètre Ø 600mm inondés de la station de pompage S13. | I25: 250000 | M25: =IF(L25="","",I25-L25) | N25: =IFERROR(IF(L25="","",L25/I25),"") | O25: =IFERROR(IF(OR(J25="",K25=""),"",J25-K25),"")
B26: 22 | C26: Sidi Kacem | D26: HOUAFATE | E26: 50-21 | F26: Entretien et réparation des stations de pompage | G26: Prestations de maintenance des moteurs électriques des stations de pompage. | H26: Révision des trois moteurs électriques 200 KW principaux de la station S13. | I26: 25000 | M26: =IF(L26="","",I26-L26) | N26: =IFERROR(IF(L26="","",L26/I26),"") | O26: =IFERROR(IF(OR(J26="",K26=""),"",J26-K26),"")
B27: 23 | C27: Sidi Kacem | D27: HOUAFATE | E27: 50-21 | F27: Entretien et réparation des stations de pompage | G27: Prestations de maintenance et de réparation mécanique des pompes et des groupes motopompes submersibles | H27: Démontage et expertise des roues des pompes principaux et pompes a vide de la station S13. | I27: 38000 | M27: =IF(L27="","",I27-L27) | N27: =IFERROR(IF(L27="","",L27/I27),"") | O27: =IFERROR(IF(OR(J27="",K27=""),"",J27-K27),"")
B28: 24 | C28: Sidi Kacem | D28: HOUAFATE | E28: 50-21 | F28: Entretien et réparation des stations de pompage | G28: Stabilisation Berge oued | H28: Pose de gabions et recouvrement du talus par matelas Reno des stations de pompage S13. | I28: 10560000 | M28: =IF(L28="","",I28-L28) | N28: =IFERROR(IF(L28="","",L28/I28),"") | O28: =IFERROR(IF(OR(J28="",K28=""),"",J28-K28),"")
B29: 25 | C29: Sidi Kacem | D29: HOUAFATE | E29: 50-21 | F29: Entretien et réparation des stations de pompage | G29: Mur clôture des stations de pompage. | H29: Stabilisation du sol et reconstruction des murs clôture (270m) cote oued de la station S17. | I29: 144000 | M29: =IF(L29="","",I29-L29) | N29: =IFERROR(IF(L29="","",L29/I29),"") | O29: =IFERROR(IF(OR(J29="",K29=""),"",J29-K29),"")
B30: 26 | C30: Sidi Kacem | D30: HOUAFATE | E30: 50-21 | F30: Entretien et réparation des stations de pompage | G30: Génie civile des locaux des stations de pompage. | H30: Expertise d'état et d'étanchéité des locaux pompes, commande, puissance des stations de pompage S17 et S13. | I30: 800000 | M30: =IF(L30="","",I30-L30) | N30: =IFERROR(IF(L30="","",L30/I30),"") | O30: =IFERROR(IF(OR(J30="",K30=""),"",J30-K30),"")
B31: 27 | C31: Sidi Kacem | D31: NOUIRAT | E31: 50-23 | F31: Entretien et réparation du réseau d'assainissement et de drainage | G31: Travaux de curage des canaux en terre | H31: Curage des collecteurs d'assainissement des secteurs EST1 et N5 | I31: 1733306 | M31: =IF(L31="","",I31-L31) | N31: =IFERROR(IF(L31="","",L31/I31),"") | O31: =IFERROR(IF(OR(J31="",K31=""),"",J31-K31),"")
B32: 28 | C32: Sidi Kacem | D32: NOUIRAT | E32: 40-21 | F32: Travaux de pistes | G32: Entretien des pistes agricoles | H32: Entretien des pistes agricoles | I32: 670000 | M32: =IF(L32="","",I32-L32) | N32: =IFERROR(IF(L32="","",L32/I32),"") | O32: =IFERROR(IF(OR(J32="",K32=""),"",J32-K32),"")
B33: 29 | C33: Sidi Kacem | D33: NOUIRAT | E33: 20-11 | F33: Travaux de réhabilitation des équipements | G33: Travaux de réhabilitation des ouvrages de génie civil | H33: Réhabilitation de l'ouvrage de l'ouvrage de débouche SE1 | I33: 2500000 | M33: =IF(L33="","",I33-L33) | N33: =IFERROR(IF(L33="","",L33/I33),"") | O33: =IFERROR(IF(OR(J33="",K33=""),"",J33-K33),"")
B34: 30 | C34: Sidi Kacem | D34: NOUIRAT | E34: 50-23 | F34: Entretien et réparation du réseau d'assainissement et de drainage | G34: Curage des prises sur l'oued, bâche d'aspiration et bassin de régulation. | H34: Curage des prises sur l'oued de la station de pompage E1. | I34: 800000 | M34: =IF(L34="","",I34-L34) | N34: =IFERROR(IF(L34="","",L34/I34),"") | O34: =IFERROR(IF(OR(J34="",K34=""),"",J34-K34),"")
... B42: 38 | C42: Sidi Kacem | D42: SAFSAF | E42: 20-11 | F42: Travaux de réhabilitation des équipements | G42: Travaux de réhabilitation des canaux portés d'irrigation | H42: Fourniture et pose de canaux porté et accessoires du réseau S4 du secteur S11 | I42: 232266 | M42: =IF(L42="","",I42-L42) | N42: =IFERROR(IF(L42="","",L42/I42),"") | O42: =IFERROR(IF(OR(J42="",K42=""),"",J42-K42),"")
B43: 39 | C43: Sidi Kacem | D43: SAFSAF | E43: 20-11 | F43: Travaux de réhabilitation des équipements | H43: Recalage des canaux portés du réseau T5S5 du secteur S9 | I43: 1055025 | M43: =IF(L43="","",I43-L43) | N43: =IFERROR(IF(L43="","",L43/I43),"") | O43: =IFERROR(IF(OR(J43="",K43=""),"",J43-K43),"")
B44: 40 | C44: Sidi Kacem | D44: SAFSAF | E44: 20-11 | F44: Travaux de réhabilitation des équipements | H44: Recalage des canaux portés du réseau T7S5 du secteur S9 | I44: 1004535 | M44: =IF(L44="","",I44-L44) | N44: =IFERROR(IF(L44="","",L44/I44),"") | O44: =IFERROR(IF(OR(J44="",K44=""),"",J44-K44),"")
B45: 41 | C45: Sidi Kacem | D45: SAFSAF | E45: 20-11 | F45: Travaux de réhabilitation des équipements | H45: Recalage des canaux portés du réseau T2S5 du secteur S9 | I45: 793830 | M45: =IF(L45="","",I45-L45) | N45: =IFERROR(IF(L45="","",L45/I45),"") | O45: =IFERROR(IF(OR(J45="",K45=""),"",J45-K45),"")
B46: 42 | C46: Sidi Kacem | D46: SAFSAF | E46: 40-21 | F46: Travaux de pistes | G46: Entretien des pistes agricoles | H46: Entretien des pistes agricoles | I46: 2000000 | M46: =IF(L46="","",I46-L46) | N46: =IFERROR(IF(L46="","",L46/I46),"") | O46: =IFERROR(IF(OR(J46="",K46=""),"",J46-K46),"")
B47: 43 | C47: Sidi Kacem | D47: SAFSAF | E47: 50-23 | F47: Entretien et réparation du réseau d'assainissement et de drainage | G47: Curage des prises sur l'oued, bâche d'aspiration et bassin de régulation. | H47: Curage des prises sur l'oued des stations de pompage S11, S9, 7D et 7B. | I47: 200000 | M47: =IF(L47="","",I47-L47) | N47: =IFERROR(IF(L47="","",L47/I47),"") | O47: =IFERROR(IF(OR(J47="",K47=""),"",J47-K47),"")
B48: 44 | C48: Sidi Kacem | D48: SAFSAF | E48: 50-21 | F48: Entretien et réparation des stations de pompage | G48: Prestation de maintenance des débitmètres et leurs équipements annexes | H48: Changements Sept des débitmètres Ø 600mm inondé des deux stations de pompage S11 et S9. | I48: 580000 | M48: =IF(L48="","",I48-L48) | N48: =IFERROR(IF(L48="","",L48/I48),"") | O48: =IFERROR(IF(OR(J48="",K48=""),"",J48-K48),"")
B49: 45 | C49: Sidi Kacem | D49: SAFSAF | E49: 50-21 | F49: Entretien et réparation des stations de pompage | G49: Stabilisation Berge oued | H49: Pose de murs en gabions et recouvrement du talus par matelas Reno des stations de pompage S11, S9, 7D et 7B. | I49: 4000000 | M49: =IF(L49="","",I49-L49) | N49: =IFERROR(IF(L49="","",L49/I49),"") | O49: =IFERROR(IF(OR(J49="",K49=""),"",J49-K49),"")
...

Sheet Récap. par Province
B2: Récapitulatif par Province — Région du Gharb 2026 (Juin–Décembre)
B4: Province | C4: Nb Projets | D4: Nb Communes | E4: Budget Total (DH) | F4: Montant Décaissé (DH) | G4: Reste à Décaisser (DH) | H4: Taux Décaissement (%) | I4: Avancement Physique Moyen (%) | J4: Avancement Financier Moyen (%) | K4: Écart Phys.-Fin. (pts)
B5: Kénitra | C5: =COUNTIF('Suivi des Projets'!C5:C76,B5) | D5: =COUNTIFS('Suivi des Projets'!C5:C76,B5,'Suivi des Projets'!D5:D76,"<>") | E5: =SUMIF('Suivi des Projets'!C5:C76,B5,'Suivi des Projets'!I5:I76) | F5: =SUMIF('Suivi des Projets'!C5:C76,B5,'Suivi des Projets'!L5:L76) | G5: =F5-E5 | H5: =IFERROR(F5/E5,"") | I5: =IFERROR(AVERAGEIF('Suivi des Projets'!C5:C76,B5,'Suivi des Projets'!J5:J76),"") | J5: =IFERROR(AVERAGEIF('Suivi des Projets'!C5:C76,B5,'Suivi des Projets'!K5:K76),"") | K5: =I5-J5
B6: Sidi Kacem | C6: =COUNTIF('Suivi des Projets'!C5:C76,B6) | D6: =COUNTIFS('Suivi des Projets'!C5:C76,B6,'Suivi des Projets'!D5:D76,"<>") | E6: =SUMIF('Suivi des Projets'!C5:C76,B6,'Suivi des Projets'!I5:I76) | F6: =SUMIF('Suivi des Projets'!C5:C76,B6,'Suivi des Projets'!L5:L76) | G6: =F6-E6 | H6: =IFERROR(F6/E6,"") | I6: =IFERROR(AVERAGEIF('Suivi des Projets'!C5:C76,B6,'Suivi des Projets'!J5:J76),"") | J6: =IFERROR(AVERAGEIF('Suivi des Projets'!C5:C76,B6,'Suivi des Projets'!K5:K76),"") | K6: =I6-J6
B7: Sidi Slimane | C7: =COUNTIF('Suivi des Projets'!C5:C76,B7) | D7: =COUNTIFS('Suivi des Projets'!C5:C76,B7,'Suivi des Projets'!D5:D76,"<>") | E7: =SUMIF('Suivi des Projets'!C5:C76,B7,'Suivi des Projets'!I5:I76) | F7: =SUMIF('Suivi des Projets'!C5:C76,B7,'Suivi des Projets'!L5:L76) | G7: =F7-E7 | H7: =IFERROR(F7/E7,"") | I7: =IFERROR(AVERAGEIF('Suivi des Projets'!C5:C76,B7,'Suivi des Projets'!J5:J76),"") | J7: =IFERROR(AVERAGEIF('Suivi des Projets'!C5:C76,B7,'Suivi des Projets'!K5:K76),"") | K7: =I7-J7
B8: TOTAL RÉGION | C8: =SUM(C5:C7) | E8: =SUM(E5:E7) | F8: =SUM(F5:F7) | G8: =SUM(G5:G7) | H8: =IFERROR(F8/E8,"") | I8: =IFERROR(AVERAGE(I5:I7),"") | J8: =IFERROR(AVERAGE(J5:J7),"") | K8: =I8-J8

Sheet Récap. par Secteur
B2: Récapitulatif par Secteur — Région du Gharb 2026 (Juin–Décembre)
B4: Secteur | C4: Nb Projets | D4: Nb Communes | E4: Budget Total (DH) | F4: Montant Décaissé (DH) | G4: Reste à Décaisser (DH) | H4: Taux Décaissement (%) | I4: Avancement Physique Moyen (%) | J4: Avancement Financier Moyen (%) | K4: Écart Phys.-Fin. (pts)
B5: Assainissement & Drainage | C5: =COUNTIF('Suivi des Projets'!F5:F76,"Entretien et réparation du réseau d'assainissement et de drainage") | E5: =SUMIF('Suivi des Projets'!F5:F76,"Entretien et réparation du réseau d'assainissement et de drainage",'Suivi des Projets'!I5:I76) | F5: =SUMIF('Suivi des Projets'!F5:F76,"Entretien et réparation du réseau d'assainissement et de drainage",'Suivi des Projets'!L5:L76) | G5: =F5-E5 | H5: =IFERROR(F5/E5,"") | I5: =IFERROR(AVERAGEIF('Suivi des Projets'!F5:F76,"Entretien et réparation du réseau d'assainissement et de drainage",'Suivi des Projets'!J5:J76),"") | J5: =IFERROR(AVERAGEIF('Suivi des Projets'!F5:F76,"Entretien et réparation du réseau d'assainissement et de drainage",'Suivi des Projets'!K5:K76),"") | K5: =I5-J5
B6: Pistes agricoles | C6: =COUNTIF('Suivi des Projets'!F5:F76,"Travaux de pistes") | E6: =SUMIF('Suivi des Projets'!F5:F76,"Travaux de pistes",'Suivi des Projets'!I5:I76) | F6: =SUMIF('Suivi des Projets'!F5:F76,"Travaux de pistes",'Suivi des Projets'!L5:L76) | G6: =F6-E6 | H6: =IFERROR(F6/E6,"") | I6: =IFERROR(AVERAGEIF('Suivi des Projets'!F5:F76,"Travaux de pistes",'Suivi des Projets'!J5:J76),"") | J6: =IFERROR(AVERAGEIF('Suivi des Projets'!F5:F76,"Travaux de pistes",'Suivi des Projets'!K5:K76),"") | K6: =I6-J6
B7: Stations de pompage | C7: =COUNTIF('Suivi des Projets'!F5:F76,"Entretien et réparation des stations de pompage") | E7: =SUMIF('Suivi des Projets'!F5:F76,"Entretien et réparation des stations de pompage",'Suivi des Projets'!I5:I76) | F7: =SUMIF('Suivi des Projets'!F5:F76,"Entretien et réparation des stations de pompage",'Suivi des Projets'!L5:L76) | G7: =F7-E7 | H7: =IFERROR(F7/E7,"") | I7: =IFERROR(AVERAGEIF('Suivi des Projets'!F5:F76,"Entretien et réparation des stations de pompage",'Suivi des Projets'!J5:J76),"") | J7: =IFERROR(AVERAGEIF('Suivi des Projets'!F5:F76,"Entretien et réparation des stations de pompage",'Suivi des Projets'!K5:K76),"") | K7: =I7-J7
B8: Réhabilitation équipements | C8: =COUNTIF('Suivi des Projets'!F5:F76,"Travaux de réhabilitation des équipements") | E8: =SUMIF('Suivi des Projets'!F5:F76,"Travaux de réhabilitation des équipements",'Suivi des Projets'!I5:I76) | F8: =SUMIF('Suivi des Projets'!F5:F76,"Travaux de réhabilitation des équipements",'Suivi des Projets'!L5:L76) | G8: =F8-E8 | H8: =IFERROR(F8/E8,"") | I8: =IFERROR(AVERAGEIF('Suivi des Projets'!F5:F76,"Travaux de réhabilitation des équipements",'Suivi des Projets'!J5:J76),"") | J8: =IFERROR(AVERAGEIF('Suivi des Projets'!F5:F76,"Travaux de réhabilitation des équipements",'Suivi des Projets'!K5:K76),"") | K8: =I8-J8
B9: TOTAL | C9: =SUM(C5:C8) | E9: =SUM(E5:E8) | F9: =SUM(F5:F8) | G9: =SUM(G5:G8) | H9: =IFERROR(F9/E9,"") | I9: =IFERROR(AVERAGE(I5:I8),"") | J9: =IFERROR(AVERAGE(J5:J8),"") | K9: =I9-J9

Sheet Mode d'emploi
B2: Mode d'emploi — Fichier de Suivi
C5: Ce fichier Excel sert de modèle pour alimenter le dashboard SIG Gharb avec les données de suivi physique et financier des projets (Juin à Décembre 2026).
B7: COLONNES À REMPLIR
B8: Avancement Physique (%) | C8: Saisir le pourcentage de progression des travaux sur le terrain (0% à 100%). Exemples : 0%, 25%, 50%, 75%, 100%
B9: Avancement Financier (%) | C9: Saisir le pourcentage de consommation du budget (0% à 100%). Représente la part du budget engagée/dépensée.
B10: Montant Décaissé (DH) | C10: Saisir le montant effectivement décaissé en Dirhams. Doit être inférieur ou égal au Budget Prévu.
B11: Statut | C11: Sélectionner dans la liste déroulante : Terminé, En cours, ou Non démarré
B12: Observations | C12: Zone libre pour notes, commentaires, problèmes rencontrés, etc.
B14: COLONNES CALCULÉES AUTOMATIQUEMENT
B15: Reste à Décaisser | C15: Budget Prévu - Montant Décaissé
B16: Taux de Décaissement | C16: Montant Décaissé / Budget Prévu
B17: Écart Phys.-Fin. (pts) | C17: =Avancement Physique - Avancement Financier. Un écart négatif important (>15pts) signale un retard physique.
B19: COULEURS CONDITIONNELLES
B20: Avancement | C20: Rouge (0-33%) → Jaune (34-66%) → Vert (67-100%)
B21: Statut | C21: Vert = Terminé, Orange = En cours, Rouge = Non démarré
B22: Écart | C22: Rouge si écart < -15pts (retard physique significatif)
B24: FEUILLES DU FICHIER
B25: Suivi des Projets | C25: Liste détaillée des 72 projets avec toutes les informations
B26: Récap. par Province | C26: Synthèse automatique par province (Kénitra, Sidi Kacem, Sidi Slimane)
B27: Récap. par Secteur | C27: Synthèse automatique par secteur d'activité
B28: Mode d'emploi | C28: Cette feuille — guide d'utilisation
B30: IMPORT DANS LE DASHBOARD
C31: Pour importer les données dans le dashboard SIG Gharb :
B32: 1. | C32: Remplir les colonnes Avancement Physique, Avancement Financier, Montant Décaissé et Statut pour chaque projet
B33: 2. | C33: Exporter le fichier en format CSV ou JSON
B34: 3. | C34: Mettre à jour le fichier dashboard_data.json avec les nouvelles valeurs
B35: 4. | C35: Le dashboard se met à jour automatiquement après déploiement
