Workbook

Sheet Suivi Hebdomadaire
B2: SUIVI HEBDOMADAIRE D'EXÉCUTION PHYSIQUE ET FINANCIÈRE — PROJETS INONDATIONS GHARB 2026 (Juin–Décembre)
B3: Office Régional de Mise en Valeur Agricole du Gharb — Kénitra | H3: Semaine N° : | L3: Date début : | P3: Date fin :
B5: N° | C5: Province | D5: Commune | E5: Rubrique | F5: Intitulé Rubrique | G5: Intitulé Projet | H5: Consistance | I5: Budget Prévu (DH) | J5: Avancement Physique Sem. Préc. (%) | K5: Avancement Physique Sem. Act. (%) | L5: Δ Phys. (pts) | M5: Avancement Financier Sem. Préc. (%) | N5: Avancement Financier Sem. Act. (%) | O5: Δ Fin. (pts) | P5: Montant Décaissé Cumulé (DH) | Q5: Reste à Décaisser (DH) | R5: Taux Décaissement (%) | S5: Écart Phys.-Fin. (pts) | T5: Statut | U5: Observations | V5: N° Consultation | W5: Société Titulaire | X5: Date Ouverture Plis | Y5: Date Jugement | Z5: Date OSC | AA5: Délai Exécution (j) | AB5: Date Réception Provisoire
B6: 1 | C6: Sidi Kacem | D6: KHENICHET | E6: 50-23 | F6: Entretien et réparation du réseau d'assainissement et de drainage | G6: Travaux de curage des canaux en terre | H6: Curage des collecteurs d'assainissement du secteur EST2 | I6: 2091568 | L6: =IFERROR(K6-J6,"") | O6: =IFERROR(N6-M6,"") | Q6: =IF(P6="","",I6-P6) | R6: =IFERROR(P6/I6,"") | S6: =IFERROR(K6-N6,"")
B7: 2 | C7: Sidi Kacem | D7: KHENICHET | E7: 40-21 | F7: Travaux de pistes | G7: Travaux de réhabilitation des pistes agricoles | H7: Entretien des pistes agricoles Douar Nouagra et Douar ouled Salem | I7: 78000 | L7: =IFERROR(K7-J7,"") | O7: =IFERROR(N7-M7,"") | Q7: =IF(P7="","",I7-P7) | R7: =IFERROR(P7/I7,"") | S7: =IFERROR(K7-N7,"")
B8: 3 | C8: Sidi Kacem | D8: KHENICHET | E8: 50-23 | F8: Entretien et réparation du réseau d'assainissement et de drainage | G8: Curage des prises sur l’oued, bâche d’aspiration et bassin de régulation. | H8: Curage de la chambre des joints de démontage des siphonnes de la station de pompage EST2. | I8: 126000 | L8: =IFERROR(K8-J8,"") | O8: =IFERROR(N8-M8,"") | Q8: =IF(P8="","",I8-P8) | R8: =IFERROR(P8/I8,"") | S8: =IFERROR(K8-N8,"")
B9: 4 | C9: Sidi Kacem | D9: KHENICHET | E9: 50-21 | F9: Entretien et réparation des stations de pompage | G9: Prestation de maintenance des débitmètres et leurs équipements annexes installés au niveau des station de pompage | H9: Changement trois débitmètre Ø 600mm inondés de la station de pompage EST 2 et deux capteurs VEGASON 62 | I9: 165500 | L9: =IFERROR(K9-J9,"") | O9: =IFERROR(N9-M9,"") | Q9: =IF(P9="","",I9-P9) | R9: =IFERROR(P9/I9,"") | S9: =IFERROR(K9-N9,"")
B10: 5 | C10: Sidi Kacem | D10: BIR TALEB | E10: 50-23 | F10: Entretien et réparation du réseau d'assainissement et de drainage | G10: Travaux de curage des canaux en terre | H10: Curage du canal d'assainisement Tihli Aval | I10: 1000000 | L10: =IFERROR(K10-J10,"") | O10: =IFERROR(N10-M10,"") | Q10: =IF(P10="","",I10-P10) | R10: =IFERROR(P10/I10,"") | S10: =IFERROR(K10-N10,"")
B11: 6 | C11: Sidi Kacem | D11: BIR TALEB | E11: 50-23 | F11: Entretien et réparation du réseau d'assainissement et de drainage | H11: Curage des collecteurs d'assainissement du secteur P11/1 | I11: 846731 | L11: =IFERROR(K11-J11,"") | O11: =IFERROR(N11-M11,"") | Q11: =IF(P11="","",I11-P11) | R11: =IFERROR(P11/I11,"") | S11: =IFERROR(K11-N11,"")
B12: 7 | C12: Sidi Kacem | D12: BIR TALEB | E12: 50-23 | F12: Entretien et réparation du réseau d'assainissement et de drainage | G12: Curage des prises sur l’oued, bâche d’aspiration et bassin de régulation. | H12: Curage des prises sur l’oued de la station de pompage P11/1. | I12: 200000 | L12: =IFERROR(K12-J12,"") | O12: =IFERROR(N12-M12,"") | Q12: =IF(P12="","",I12-P12) | R12: =IFERROR(P12/I12,"") | S12: =IFERROR(K12-N12,"")
B13: 8 | C13: Sidi Kacem | D13: BIR TALEB | E13: 50-21 | F13: Entretien et réparation des stations de pompage | G13: Prestation de maintenance des débitmètres et leurs équipements annexes installés au niveau des station de pompage | H13: Changement trois débitmètre Ø 400mm inondés de la station de pompage P11/1 | I13: 141900 | L13: =IFERROR(K13-J13,"") | O13: =IFERROR(N13-M13,"") | Q13: =IF(P13="","",I13-P13) | R13: =IFERROR(P13/I13,"") | S13: =IFERROR(K13-N13,"")
B14: 9 | C14: Sidi Kacem | D14: BIR TALEB | E14: 50-21 | F14: Entretien et réparation des stations de pompage | G14: Prestations de maintenance et de réparation mécanique des pompes et des groupes motopompes submersibles des stations de pompage. | H14: Démontage et expertise des roues des pompes principaux et pompes a vide de la station P11/1 Changement des roulements, tresses et organes d’effectués de la station P11/1 | I14: 26700 | L14: =IFERROR(K14-J14,"") | O14: =IFERROR(N14-M14,"") | Q14: =IF(P14="","",I14-P14) | R14: =IFERROR(P14/I14,"") | S14: =IFERROR(K14-N14,"")
B15: 10 | C15: Sidi Kacem | D15: BIR TALEB | E15: 50-21 | F15: Entretien et réparation des stations de pompage | G15: Stabilisation Berge oued | H15: Pose de gabions et recouvrement du talus par matelas Reno des stations de pompage P11/1. | I15: 480000 | L15: =IFERROR(K15-J15,"") | O15: =IFERROR(N15-M15,"") | Q15: =IF(P15="","",I15-P15) | R15: =IFERROR(P15/I15,"") | S15: =IFERROR(K15-N15,"")
B16: 11 | C16: Sidi Kacem | D16: BIR TALEB | E16: 50-21 | F16: Entretien et réparation des stations de pompage | G16: Génie civile des locaux des stations de pompage. | H16: Expertise d’état et d’étanchéité des locaux pompes. Renforcement d’étanchéité des locaux pompe sous niveau des oueds des stations de pompage P11/1. Entretien des supports en béton des conduites d’aspiration. | I16: 300000 | L16: =IFERROR(K16-J16,"") | O16: =IFERROR(N16-M16,"") | Q16: =IF(P16="","",I16-P16) | R16: =IFERROR(P16/I16,"") | S16: =IFERROR(K16-N16,"")
B17: 12 | C17: Sidi Kacem | D17: CHEBANAT | E17: 50-23 | F17: Entretien et réparation du réseau d'assainissement et de drainage | G17: Travaux de curage des canaux en terre | H17: Curage des collecteurs d'assainissement des secteur SH5 et SH6. | I17: 1000000 | L17: =IFERROR(K17-J17,"") | O17: =IFERROR(N17-M17,"") | Q17: =IF(P17="","",I17-P17) | R17: =IFERROR(P17/I17,"") | S17: =IFERROR(K17-N17,"")
B18: 13 | C18: Sidi Kacem | D18: CHEBANAT | E18: 50-23 | F18: Entretien et réparation du réseau d'assainissement et de drainage | G18: Travaux de curage des canaux révetus | H18: Curage du canal principal d'irrigation beht partie aval 1. | I18: 739200 | L18: =IFERROR(K18-J18,"") | O18: =IFERROR(N18-M18,"") | Q18: =IF(P18="","",I18-P18) | R18: =IFERROR(P18/I18,"") | S18: =IFERROR(K18-N18,"")
B19: 14 | C19: Sidi Kacem | D19: ZIRARA | E19: 50-23 | F19: Entretien et réparation du réseau d'assainissement et de drainage | G19: Travaux de curage des canaux révetus | H19: Curage du canal principal d'irrigation beht partie aval 2. | I19: 1276800 | L19: =IFERROR(K19-J19,"") | O19: =IFERROR(N19-M19,"") | Q19: =IF(P19="","",I19-P19) | R19: =IFERROR(P19/I19,"") | S19: =IFERROR(K19-N19,"")
B20: 15 | C20: Sidi Kacem | D20: DAR LAASLOUJI | E20: 50-23 | F20: Entretien et réparation du réseau d'assainissement et de drainage | G20: Travaux de curage des canaux en terre | H20: Curage des collecteurs d'assainissement des secteurs P8-1 et P8-2 | I20: 5796360 | L20: =IFERROR(K20-J20,"") | O20: =IFERROR(N20-M20,"") | Q20: =IF(P20="","",I20-P20) | R20: =IFERROR(P20/I20,"") | S20: =IFERROR(K20-N20,"")
B21: 16 | C21: Sidi Kacem | D21: DAR LAASLOUJI | E21: 40-21 | F21: Travaux de pistes | G21: Entretien des pistes agricoles | H21: Entretien des pistes agricoles | I21: 340000 | L21: =IFERROR(K21-J21,"") | O21: =IFERROR(N21-M21,"") | Q21: =IF(P21="","",I21-P21) | R21: =IFERROR(P21/I21,"") | S21: =IFERROR(K21-N21,"")
B22: 17 | C22: Sidi Kacem | D22: HOUAFATE | E22: 20-11 | F22: Travaux de réhabilitation des équipements | G22: Travaux de réhabilitation des canaux portés d'irrigation | H22: Fourniture et de pose de canaux porté et accessoires du réseau S3 du secteur S13 | I22: 397934 | L22: =IFERROR(K22-J22,"") | O22: =IFERROR(N22-M22,"") | Q22: =IF(P22="","",I22-P22) | R22: =IFERROR(P22/I22,"") | S22: =IFERROR(K22-N22,"")
B23: 18 | C23: Sidi Kacem | D23: HOUAFATE | E23: 20-11 | F23: Travaux de réhabilitation des équipements | H23: Fourniture et de pose de canaux porté et accessoires du réseau T2S1 du secteur S13 | I23: 207575 | L23: =IFERROR(K23-J23,"") | O23: =IFERROR(N23-M23,"") | Q23: =IF(P23="","",I23-P23) | R23: =IFERROR(P23/I23,"") | S23: =IFERROR(K23-N23,"")
B24: 19 | C24: Sidi Kacem | D24: HOUAFATE | E24: 40-21 | F24: Travaux de pistes | G24: Entretien des pistes agricoles | H24: Entretien des pistes agricoles | I24: 2200000 | L24: =IFERROR(K24-J24,"") | O24: =IFERROR(N24-M24,"") | Q24: =IF(P24="","",I24-P24) | R24: =IFERROR(P24/I24,"") | S24: =IFERROR(K24-N24,"")
B25: 20 | C25: Sidi Kacem | D25: HOUAFATE | E25: 50-23 | F25: Entretien et réparation du réseau d'assainissement et de drainage | G25: Curage des prises sur l’oued, bâche d’aspiration et bassin de régulation. | H25: Curage des prises sur l’oued de la station de pompage S17 et S13. Nettoyage des grilles de préfiltration des boues colmaté de la station de pompage S17 et S13. Curage de la bâche d’aspiration de la station S17 et S13. | I25: 300000 | L25: =IFERROR(K25-J25,"") | O25: =IFERROR(N25-M25,"") | Q25: =IF(P25="","",I25-P25) | R25: =IFERROR(P25/I25,"") | S25: =IFERROR(K25-N25,"")
B26: 21 | C26: Sidi Kacem | D26: HOUAFATE | E26: 50-21 | F26: Entretien et réparation des stations de pompage | G26: Prestation de maintenance des débitmètres et leurs équipements annexes installés au niveau des station de pompage | H26: Changement trois débitmètre Ø 600mm inondés de la station de pompage S13. | I26: 250000 | L26: =IFERROR(K26-J26,"") | O26: =IFERROR(N26-M26,"") | Q26: =IF(P26="","",I26-P26) | R26: =IFERROR(P26/I26,"") | S26: =IFERROR(K26-N26,"")
B27: 22 | C27: Sidi Kacem | D27: HOUAFATE | E27: 50-21 | F27: Entretien et réparation des stations de pompage | G27: Prestations de maintenance des moteurs électriques des stations de pompage. | H27: Révision des trois moteurs électriques 200 KW principaux de la station S13. Révision des deux moteurs électriques 5,5 KW groupes vide de la station S13. | I27: 25000 | L27: =IFERROR(K27-J27,"") | O27: =IFERROR(N27-M27,"") | Q27: =IF(P27="","",I27-P27) | R27: =IFERROR(P27/I27,"") | S27: =IFERROR(K27-N27,"")
B28: 23 | C28: Sidi Kacem | D28: HOUAFATE | E28: 50-21 | F28: Entretien et réparation des stations de pompage | G28: Prestations de maintenance et de réparation mécanique des pompes et des groupes motopompes submersibles des stations de pompage. | H28: Démontage et expertise des roues des pompes principaux et pompes a vide de la station S13. Changement des roulements, tresses et organes d’effectués de la station S13. | I28: 38000 | L28: =IFERROR(K28-J28,"") | O28: =IFERROR(N28-M28,"") | Q28: =IF(P28="","",I28-P28) | R28: =IFERROR(P28/I28,"") | S28: =IFERROR(K28-N28,"")
B29: 24 | C29: Sidi Kacem | D29: HOUAFATE | E29: 50-21 | F29: Entretien et réparation des stations de pompage | G29: Stabilisation Berge oued | H29: Pose de gabions et recouvrement du talus par matelas Reno des stations de pompage S13. | I29: 10560000 | L29: =IFERROR(K29-J29,"") | O29: =IFERROR(N29-M29,"") | Q29: =IF(P29="","",I29-P29) | R29: =IFERROR(P29/I29,"") | S29: =IFERROR(K29-N29,"")
B30: 25 | C30: Sidi Kacem | D30: HOUAFATE | E30: 50-21 | F30: Entretien et réparation des stations de pompage | G30: Mur clôture des stations de pompage. | H30: Stabilisation du sol et reconstruction des murs clôture (270m) cote oued de la station S17. | I30: 144000 | L30: =IFERROR(K30-J30,"") | O30: =IFERROR(N30-M30,"") | Q30: =IF(P30="","",I30-P30) | R30: =IFERROR(P30/I30,"") | S30: =IFERROR(K30-N30,"")
B31: 26 | C31: Sidi Kacem | D31: HOUAFATE | E31: 50-21 | F31: Entretien et réparation des stations de pompage | G31: Génie civile des locaux des stations de pompage. | H31: Expertise d’état et d’étanchéité des locaux pompes, commande, puissance des stations de pompage S17 et S13. Renforcement d’étanchéité des locaux pompe sous niveau des oueds des stations de pompage S17 et S13. | I31: 800000 | L31: =IFERROR(K31-J31,"") | O31: =IFERROR(N31-M31,"") | Q31: =IF(P31="","",I31-P31) | R31: =IFERROR(P31/I31,"") | S31: =IFERROR(K31-N31,"")
B32: 27 | C32: Sidi Kacem | D32: NOUIRAT | E32: 50-23 | F32: Entretien et réparation du réseau d'assainissement et de drainage | G32: Travaux de curage des canaux en terre | H32: Curage des collecteurs d'assainissement des secteurs EST1 et N5 | I32: 1733306 | L32: =IFERROR(K32-J32,"") | O32: =IFERROR(N32-M32,"") | Q32: =IF(P32="","",I32-P32) | R32: =IFERROR(P32/I32,"") | S32: =IFERROR(K32-N32,"")
B33: 28 | C33: Sidi Kacem | D33: NOUIRAT | E33: 40-21 | F33: Travaux de pistes | G33: Entretien des pistes agricoles | H33: Entretien des pistes agricoles | I33: 670000 | L33: =IFERROR(K33-J33,"") | O33: =IFERROR(N33-M33,"") | Q33: =IF(P33="","",I33-P33) | R33: =IFERROR(P33/I33,"") | S33: =IFERROR(K33-N33,"")
B34: 29 | C34: Sidi Kacem | D34: NOUIRAT | E34: 20-11 | F34: Travaux de réhabilitation des équipements | G34: Travaux de réhabilitation des ouvrages de génie civil | H34: Réhabilitation de l'ouvrage( genie civil ,gabiollannage,clapet anti retour et buse) de l'ouvrage de débouche SE1 | I34: 2500000 | L34: =IFERROR(K34-J34,"") | O34: =IFERROR(N34-M34,"") | Q34: =IF(P34="","",I34-P34) | R34: =IFERROR(P34/I34,"") | S34: =IFERROR(K34-N34,"")
B35: 30 | C35: Sidi Kacem | D35: NOUIRAT | E35: 50-23 | F35: Entretien et réparation du réseau d'assainissement et de drainage | G35: Curage des prises sur l’oued, bâche d’aspiration et bassin de régulation. | H35: Curage des prises sur l’oued de la station de pompage E1. Nettoyage des grilles de préfiltration des boues colmaté de la station de pompage E1. Curage de la bâche d’aspiration de la station E1. | I35: 800000 | L35: =IFERROR(K35-J35,"") | O35: =IFERROR(N35-M35,"") | Q35: =IF(P35="","",I35-P35) | R35: =IFERROR(P35/I35,"") | S35: =IFERROR(K35-N35,"")
... B43: 38 | C43: Sidi Kacem | D43: SAFSAF | E43: 20-11 | F43: Travaux de réhabilitation des équipements | G43: Travaux de réhabilitation des canaux portés d'irrigation | H43: Fourniture et pose de canaux porté et accessoires du réseau S4 du secteur S11 | I43: 232266 | L43: =IFERROR(K43-J43,"") | O43: =IFERROR(N43-M43,"") | Q43: =IF(P43="","",I43-P43) | R43: =IFERROR(P43/I43,"") | S43: =IFERROR(K43-N43,"")
B44: 39 | C44: Sidi Kacem | D44: SAFSAF | E44: 20-11 | F44: Travaux de réhabilitation des équipements | H44: Recalage des canaux portés du réseau T5S5 du secteur S9 | I44: 1055025 | L44: =IFERROR(K44-J44,"") | O44: =IFERROR(N44-M44,"") | Q44: =IF(P44="","",I44-P44) | R44: =IFERROR(P44/I44,"") | S44: =IFERROR(K44-N44,"")
B45: 40 | C45: Sidi Kacem | D45: SAFSAF | E45: 20-11 | F45: Travaux de réhabilitation des équipements | H45: Recalage des canaux portés du réseau T7S5 du secteur S9 | I45: 1004535 | L45: =IFERROR(K45-J45,"") | O45: =IFERROR(N45-M45,"") | Q45: =IF(P45="","",I45-P45) | R45: =IFERROR(P45/I45,"") | S45: =IFERROR(K45-N45,"")
B46: 41 | C46: Sidi Kacem | D46: SAFSAF | E46: 20-11 | F46: Travaux de réhabilitation des équipements | H46: Recalage des canaux portés du réseau T2S5 du secteur S9 | I46: 793830 | L46: =IFERROR(K46-J46,"") | O46: =IFERROR(N46-M46,"") | Q46: =IF(P46="","",I46-P46) | R46: =IFERROR(P46/I46,"") | S46: =IFERROR(K46-N46,"")
B47: 42 | C47: Sidi Kacem | D47: SAFSAF | E47: 40-21 | F47: Travaux de pistes | G47: Entretien des pistes agricoles | H47: Entretien des pistes agricoles | I47: 2000000 | L47: =IFERROR(K47-J47,"") | O47: =IFERROR(N47-M47,"") | Q47: =IF(P47="","",I47-P47) | R47: =IFERROR(P47/I47,"") | S47: =IFERROR(K47-N47,"")
B48: 43 | C48: Sidi Kacem | D48: SAFSAF | E48: 50-23 | F48: Entretien et réparation du réseau d'assainissement et de drainage | G48: Curage des prises sur l’oued, bâche d’aspiration et bassin de régulation. | H48: Curage des prises sur l’oued des stations de pompage S11, S9, 7D et 7B. Nettoyage des grilles de préfiltration des boues colmaté des stations de pompage S11, S9, 7D et 7B. Nettoyage des crépines des boues colmaté de station pompage 7D. Curage des dalots et bâche d’aspiration des stations de pompage S11, S9, 7B. | I48: 200000 | L48: =IFERROR(K48-J48,"") | O48: =IFERROR(N48-M48,"") | Q48: =IF(P48="","",I48-P48) | R48: =IFERROR(P48/I48,"") | S48: =IFERROR(K48-N48,"")
B49: 44 | C49: Sidi Kacem | D49: SAFSAF | E49: 50-21 | F49: Entretien et réparation des stations de pompage | G49: Prestation de maintenance des débitmètres et leurs équipements annexes installés au niveau des station de pompage | H49: Changements Sept des débitmètres Ø 600mm inondé des deux stations de pompage S11 et S9. | I49: 580000 | L49: =IFERROR(K49-J49,"") | O49: =IFERROR(N49-M49,"") | Q49: =IF(P49="","",I49-P49) | R49: =IFERROR(P49/I49,"") | S49: =IFERROR(K49-N49,"")
...

Sheet Historique Hebdomadaire
B2: HISTORIQUE D'AVANCEMENT PAR SEMAINE — VUE D'ENSEMBLE (Juin–Décembre 2026)
B3: Ce tableau permet de suivre l'évolution semaine par semaine de l'avancement global par province (Juin à Décembre 2026)
B5: Semaine | C5: Période | E5: Av. Phys. Kénitra (%) | F5: Av. Fin. Kénitra (%) | G5: Av. Phys. Sidi Kacem (%) | H5: Av. Fin. Sidi Kacem (%) | I5: Av. Phys. Sidi Slimane (%) | J5: Av. Fin. Sidi Slimane (%) | K5: Av. Phys. Global (%) | L5: Av. Fin. Global (%)
B6: 23 | C6: 01/06/2026 - 07/06/2026
B7: 24 | C7: 08/06/2026 - 14/06/2026
B8: 25 | C8: 15/06/2026 - 21/06/2026
B9: 26 | C9: 22/06/2026 - 28/06/2026
B10: 27 | C10: 29/06/2026 - 05/07/2026
B11: 28 | C11: 06/07/2026 - 12/07/2026
B12: 29 | C12: 13/07/2026 - 19/07/2026
B13: 30 | C13: 20/07/2026 - 26/07/2026
B14: 31 | C14: 27/07/2026 - 02/08/2026
B15: 32 | C15: 03/08/2026 - 09/08/2026
B16: 33 | C16: 10/08/2026 - 16/08/2026
B17: 34 | C17: 17/08/2026 - 23/08/2026
... B36: 53 | C36: 28/12/2026 - 03/01/2027

Sheet Récap. par Province
B2: RÉCAPITULATIF PAR PROVINCE — SEMAINE EN COURS (Juin–Décembre 2026)
B4: Province | C4: Nb Projets | D4: Nb Communes | E4: Budget Total (DH) | F4: Montant Décaissé (DH) | G4: Reste à Décaisser (DH) | H4: Taux Décaissement (%) | I4: Av. Physique (%) | J4: Av. Financier (%) | K4: Écart Phys.-Fin. (pts)
B5: Kénitra | C5: =COUNTIF('Suivi Hebdomadaire'!C6:C77,B5) | D5: =SUMPRODUCT(('Suivi Hebdomadaire'!C6:C77=B5)*1/COUNTIF('Suivi Hebdomadaire'!D6:D77,'Suivi Hebdomadaire'!D6:D77)) | E5: =SUMIF('Suivi Hebdomadaire'!C6:C77,B5,'Suivi Hebdomadaire'!I6:I77) | F5: =SUMIF('Suivi Hebdomadaire'!C6:C77,B5,'Suivi Hebdomadaire'!P6:P77) | G5: =E5-F5 | H5: =IFERROR(F5/E5,0) | I5: =IFERROR(AVERAGEIF('Suivi Hebdomadaire'!C6:C77,B5,'Suivi Hebdomadaire'!K6:K77),0) | J5: =IFERROR(AVERAGEIF('Suivi Hebdomadaire'!C6:C77,B5,'Suivi Hebdomadaire'!N6:N77),0) | K5: =IFERROR(I5-J5,0)
B6: Sidi Kacem | C6: =COUNTIF('Suivi Hebdomadaire'!C6:C77,B6) | D6: =SUMPRODUCT(('Suivi Hebdomadaire'!C6:C77=B6)*1/COUNTIF('Suivi Hebdomadaire'!D6:D77,'Suivi Hebdomadaire'!D6:D77)) | E6: =SUMIF('Suivi Hebdomadaire'!C6:C77,B6,'Suivi Hebdomadaire'!I6:I77) | F6: =SUMIF('Suivi Hebdomadaire'!C6:C77,B6,'Suivi Hebdomadaire'!P6:P77) | G6: =E6-F6 | H6: =IFERROR(F6/E6,0) | I6: =IFERROR(AVERAGEIF('Suivi Hebdomadaire'!C6:C77,B6,'Suivi Hebdomadaire'!K6:K77),0) | J6: =IFERROR(AVERAGEIF('Suivi Hebdomadaire'!C6:C77,B6,'Suivi Hebdomadaire'!N6:N77),0) | K6: =IFERROR(I6-J6,0)
B7: Sidi Slimane | C7: =COUNTIF('Suivi Hebdomadaire'!C6:C77,B7) | D7: =SUMPRODUCT(('Suivi Hebdomadaire'!C6:C77=B7)*1/COUNTIF('Suivi Hebdomadaire'!D6:D77,'Suivi Hebdomadaire'!D6:D77)) | E7: =SUMIF('Suivi Hebdomadaire'!C6:C77,B7,'Suivi Hebdomadaire'!I6:I77) | F7: =SUMIF('Suivi Hebdomadaire'!C6:C77,B7,'Suivi Hebdomadaire'!P6:P77) | G7: =E7-F7 | H7: =IFERROR(F7/E7,0) | I7: =IFERROR(AVERAGEIF('Suivi Hebdomadaire'!C6:C77,B7,'Suivi Hebdomadaire'!K6:K77),0) | J7: =IFERROR(AVERAGEIF('Suivi Hebdomadaire'!C6:C77,B7,'Suivi Hebdomadaire'!N6:N77),0) | K7: =IFERROR(I7-J7,0)
B8: TOTAL | C8: =SUM(C5:C7) | D8: =SUM(D5:D7) | E8: =SUM(E5:E7) | F8: =SUM(F5:F7) | G8: =SUM(G5:G7) | H8: =IFERROR(F8/E8,0) | I8: =IFERROR(AVERAGE(I5:I7),0) | J8: =IFERROR(AVERAGE(J5:J7),0) | K8: =IFERROR(I8-J8,0)

Sheet Mode d'emploi
B2: MODE D'EMPLOI — SUIVI HEBDOMADAIRE
B4: OBJECTIF | C4: Ce fichier permet d'assurer un suivi hebdomadaire (Juin à Décembre 2026) de l'exécution physique et financière des 72 projets de lutte contre les inondations dans la région du Gharb.
B6: FEUILLE 1 : SUIVI HEBDOMADAIRE
B7: Colonnes à remplir (jaune) | C7: • Semaine N° (cellule K3), Date début (O3), Date fin (Q3) • Avancement Physique Sem. Préc. (col J) : valeur de la semaine précédente • Avancement Physique Sem. Act. (col K) : valeur actuelle • Avancement Financier Sem. Préc. (col M) : valeur de la semaine précédente • Avancement Financier Sem. Act. (col N) : valeur actuelle • Montant Décaissé Cumulé (col P) : montant total décaissé à ce jour • Statut (col T) : Terminé / En cours / Non démarré • Observations (col U) : remarques éventuelles
B8: Colonnes calculées (auto) | C8: • Δ Phys (col L) = Sem. Act. - Sem. Préc. → progression hebdomadaire • Δ Fin (col O) = Sem. Act. - Sem. Préc. → progression hebdomadaire • Reste à Décaisser (col Q) = Budget - Décaissé • Taux Décaissement (col R) = Décaissé / Budget • Écart Phys.-Fin. (col S) = Av. Physique - Av. Financier
B9: Code couleur conditionnel | C9: • Vert : Avancement ≥ 67% • Orange/Jaune : Avancement entre 34% et 66% • Rouge : Avancement ≤ 33% • Écart < -15 pts : alerte rouge (retard physique important) • Δ négatif : régression (en rouge)
B11: FEUILLE 2 : HISTORIQUE HEBDOMADAIRE
B12: Utilisation | C12: Saisir chaque semaine les avancements moyens par province dans cette feuille. Cela permet de : • Visualiser la courbe d'avancement sur l'année • Détecter les ralentissements • Comparer les provinces entre elles • Préparer les rapports mensuels et trimestriels
B13: Colonnes | C13: • Semaine (numéro 1-52) • Période (date de début de semaine) • Av. Physique et Financier par province et global
B15: FEUILLE 3 : RÉCAPITULATIF PAR PROVINCE
B16: Utilisation | C16: Se met à jour automatiquement à partir de la Feuille 1. Affiche : • Nombre de projets et communes par province • Budget total, décaissé et reste à décaisser • Taux de décaissement • Avancement physique et financier moyen • Écart physique-financier
B18: WORKFLOW HEBDOMADAIRE RECOMMANDÉ
B19: Étape 1 | C19: Ouvrir le fichier et saisir le numéro de semaine et les dates en haut de la Feuille 1
B20: Étape 2 | C20: Recopier les valeurs de 'Sem. Act.' de la semaine précédente dans les colonnes + 7 colonnes consultation 'Sem. Préc.' (J et M)
B21: Étape 3 | C21: Saisir les nouvelles valeurs d'avancement physique et financier dans les colonnes + 7 colonnes consultation 'Sem. Act.' (K et N)
B22: Étape 4 | C22: Mettre à jour les montants décaissés cumulés (col P), les statuts (col T) et observations (col U)
B23: Étape 5 | C23: Reporter les avancements moyens par province dans la Feuille 2 (Historique)
B24: Étape 6 | C24: Vérifier le récapitulatif automatique dans la Feuille 3
B25: Étape 7 | C25: Sauvegarder une copie : 'Suivi_Gharb_S##_2026.xlsx' (## = numéro semaine)
B27: CONSEILS IMPORTANTS
C28: • Ne jamais modifier les colonnes + 7 colonnes consultation calculées (formules) — elles se mettent à jour automatiquement • Toujours sauvegarder une copie hebdomadaire avant de saisir les nouvelles données • Les cases jaunes sont les champs à remplir manuellement • Le filtre automatique permet de filtrer par province, commune ou statut
