Workbook

Sheet Liste Projets
B2: Liste Référentielle des Projets - ORMVAG Gharb
B4: N° | C4: Province | D4: Commune | E4: Rubrique | F4: Intitulé Rubrique | G4: Projet | H4: Consistance | I4: Coût Total (DH)
B5: 1 | C5: Sidi Kacem | D5: KHENICHET | E5: 50-23 | F5: Entretien et réparation du réseau d'assainissement et de drainage | G5: Travaux de curage des canaux en terre | H5: Curage des collecteurs d'assainissement du secteur EST2 | I5: 2091568
B6: 2 | C6: Sidi Kacem | D6: KHENICHET | E6: 40-21 | F6: Travaux de pistes | G6: Travaux de réhabilitation des pistes agricoles | H6: Entretien des pistes agricoles Douar Nouagra et Douar ouled Salem | I6: 78000
B7: 3 | C7: Sidi Kacem | D7: KHENICHET | E7: 50-23 | F7: Entretien et réparation du réseau d'assainissement et de drainage | G7: Curage des prises sur l’oued, bâche d’aspiration et bassin de régulation. | H7: Curage de la chambre des joints de démontage des siphonnes de la station de pompage EST2. | I7: 126000
B8: 4 | C8: Sidi Kacem | D8: KHENICHET | E8: 50-21 | F8: Entretien et réparation des stations de pompage | G8: Prestation de maintenance des débitmètres et leurs équipements annexes installés au niveau des station de pompage | H8: Changement trois débitmètre Ø 600mm inondés de la station de pompage EST 2 et deux capteurs VEGASON 62 | I8: 165500
B9: 5 | C9: Sidi Kacem | D9: BIR TALEB | E9: 50-23 | F9: Entretien et réparation du réseau d'assainissement et de drainage | G9: Travaux de curage des canaux en terre | H9: Curage du canal d'assainisement Tihli Aval | I9: 1000000
B10: 6 | C10: Sidi Kacem | D10: BIR TALEB | E10: 50-23 | F10: Entretien et réparation du réseau d'assainissement et de drainage | H10: Curage des collecteurs d'assainissement du secteur P11/1 | I10: 846731
B11: 7 | C11: Sidi Kacem | D11: BIR TALEB | E11: 50-23 | F11: Entretien et réparation du réseau d'assainissement et de drainage | G11: Curage des prises sur l’oued, bâche d’aspiration et bassin de régulation. | H11: Curage des prises sur l’oued de la station de pompage P11/1. | I11: 200000
B12: 8 | C12: Sidi Kacem | D12: BIR TALEB | E12: 50-21 | F12: Entretien et réparation des stations de pompage | G12: Prestation de maintenance des débitmètres et leurs équipements annexes installés au niveau des station de pompage | H12: Changement trois débitmètre Ø 400mm inondés de la station de pompage P11/1 | I12: 141900
B13: 9 | C13: Sidi Kacem | D13: BIR TALEB | E13: 50-21 | F13: Entretien et réparation des stations de pompage | G13: Prestations de maintenance et de réparation mécanique des pompes et des groupes motopompes submersibles des stations de pompage. | H13: Démontage et expertise des roues des pompes principaux et pompes a vide de la station P11/1 Changement des roulements, tresses et organes d’effectués de la station P11/1 | I13: 26700
B14: 10 | C14: Sidi Kacem | D14: BIR TALEB | E14: 50-21 | F14: Entretien et réparation des stations de pompage | G14: Stabilisation Berge oued | H14: Pose de gabions et recouvrement du talus par matelas Reno des stations de pompage P11/1. | I14: 480000
B15: 11 | C15: Sidi Kacem | D15: BIR TALEB | E15: 50-21 | F15: Entretien et réparation des stations de pompage | G15: Génie civile des locaux des stations de pompage. | H15: Expertise d’état et d’étanchéité des locaux pompes. Renforcement d’étanchéité des locaux pompe sous niveau des oueds des stations de pompage P11/1. Entretien des supports en béton des conduites d’aspiration. | I15: 300000
B16: 12 | C16: Sidi Kacem | D16: CHEBANAT | E16: 50-23 | F16: Entretien et réparation du réseau d'assainissement et de drainage | G16: Travaux de curage des canaux en terre | H16: Curage des collecteurs d'assainissement des secteur SH5 et SH6. | I16: 1000000
B17: 13 | C17: Sidi Kacem | D17: CHEBANAT | E17: 50-23 | F17: Entretien et réparation du réseau d'assainissement et de drainage | G17: Travaux de curage des canaux révetus | H17: Curage du canal principal d'irrigation beht partie aval 1. | I17: 739200
B18: 14 | C18: Sidi Kacem | D18: ZIRARA | E18: 50-23 | F18: Entretien et réparation du réseau d'assainissement et de drainage | G18: Travaux de curage des canaux révetus | H18: Curage du canal principal d'irrigation beht partie aval 2. | I18: 1276800
B19: 15 | C19: Sidi Kacem | D19: DAR LAASLOUJI | E19: 50-23 | F19: Entretien et réparation du réseau d'assainissement et de drainage | G19: Travaux de curage des canaux en terre | H19: Curage des collecteurs d'assainissement des secteurs P8-1 et P8-2 | I19: 5796360
B20: 16 | C20: Sidi Kacem | D20: DAR LAASLOUJI | E20: 40-21 | F20: Travaux de pistes | G20: Entretien des pistes agricoles | H20: Entretien des pistes agricoles | I20: 340000
B21: 17 | C21: Sidi Kacem | D21: HOUAFATE | E21: 20-11 | F21: Travaux de réhabilitation des équipements | G21: Travaux de réhabilitation des canaux portés d'irrigation | H21: Fourniture et de pose de canaux porté et accessoires du réseau S3 du secteur S13 | I21: 397934
B22: 18 | C22: Sidi Kacem | D22: HOUAFATE | E22: 20-11 | F22: Travaux de réhabilitation des équipements | H22: Fourniture et de pose de canaux porté et accessoires du réseau T2S1 du secteur S13 | I22: 207575
B23: 19 | C23: Sidi Kacem | D23: HOUAFATE | E23: 40-21 | F23: Travaux de pistes | G23: Entretien des pistes agricoles | H23: Entretien des pistes agricoles | I23: 2200000
B24: 20 | C24: Sidi Kacem | D24: HOUAFATE | E24: 50-23 | F24: Entretien et réparation du réseau d'assainissement et de drainage | G24: Curage des prises sur l’oued, bâche d’aspiration et bassin de régulation. | H24: Curage des prises sur l’oued de la station de pompage S17 et S13. Nettoyage des grilles de préfiltration des boues colmaté de la station de pompage S17 et S13. Curage de la bâche d’aspiration de la station S17 et S13. | I24: 300000
B25: 21 | C25: Sidi Kacem | D25: HOUAFATE | E25: 50-21 | F25: Entretien et réparation des stations de pompage | G25: Prestation de maintenance des débitmètres et leurs équipements annexes installés au niveau des station de pompage | H25: Changement trois débitmètre Ø 600mm inondés de la station de pompage S13. | I25: 250000
B26: 22 | C26: Sidi Kacem | D26: HOUAFATE | E26: 50-21 | F26: Entretien et réparation des stations de pompage | G26: Prestations de maintenance des moteurs électriques des stations de pompage. | H26: Révision des trois moteurs électriques 200 KW principaux de la station S13. Révision des deux moteurs électriques 5,5 KW groupes vide de la station S13. | I26: 25000
B27: 23 | C27: Sidi Kacem | D27: HOUAFATE | E27: 50-21 | F27: Entretien et réparation des stations de pompage | G27: Prestations de maintenance et de réparation mécanique des pompes et des groupes motopompes submersibles des stations de pompage. | H27: Démontage et expertise des roues des pompes principaux et pompes a vide de la station S13. Changement des roulements, tresses et organes d’effectués de la station S13. | I27: 38000
B28: 24 | C28: Sidi Kacem | D28: HOUAFATE | E28: 50-21 | F28: Entretien et réparation des stations de pompage | G28: Stabilisation Berge oued | H28: Pose de gabions et recouvrement du talus par matelas Reno des stations de pompage S13. | I28: 10560000
B29: 25 | C29: Sidi Kacem | D29: HOUAFATE | E29: 50-21 | F29: Entretien et réparation des stations de pompage | G29: Mur clôture des stations de pompage. | H29: Stabilisation du sol et reconstruction des murs clôture (270m) cote oued de la station S17. | I29: 144000
B30: 26 | C30: Sidi Kacem | D30: HOUAFATE | E30: 50-21 | F30: Entretien et réparation des stations de pompage | G30: Génie civile des locaux des stations de pompage. | H30: Expertise d’état et d’étanchéité des locaux pompes, commande, puissance des stations de pompage S17 et S13. Renforcement d’étanchéité des locaux pompe sous niveau des oueds des stations de pompage S17 et S13. | I30: 800000
B31: 27 | C31: Sidi Kacem | D31: NOUIRAT | E31: 50-23 | F31: Entretien et réparation du réseau d'assainissement et de drainage | G31: Travaux de curage des canaux en terre | H31: Curage des collecteurs d'assainissement des secteurs EST1 et N5 | I31: 1733306
B32: 28 | C32: Sidi Kacem | D32: NOUIRAT | E32: 40-21 | F32: Travaux de pistes | G32: Entretien des pistes agricoles | H32: Entretien des pistes agricoles | I32: 670000
B33: 29 | C33: Sidi Kacem | D33: NOUIRAT | E33: 20-11 | F33: Travaux de réhabilitation des équipements | G33: Travaux de réhabilitation des ouvrages de génie civil | H33: Réhabilitation de l'ouvrage( genie civil ,gabiollannage,clapet anti retour et buse) de l'ouvrage de débouche SE1 | I33: 2500000
B34: 30 | C34: Sidi Kacem | D34: NOUIRAT | E34: 50-23 | F34: Entretien et réparation du réseau d'assainissement et de drainage | G34: Curage des prises sur l’oued, bâche d’aspiration et bassin de régulation. | H34: Curage des prises sur l’oued de la station de pompage E1. Nettoyage des grilles de préfiltration des boues colmaté de la station de pompage E1. Curage de la bâche d’aspiration de la station E1. | I34: 800000
... B42: 38 | C42: Sidi Kacem | D42: SAFSAF | E42: 20-11 | F42: Travaux de réhabilitation des équipements | G42: Travaux de réhabilitation des canaux portés d'irrigation | H42: Fourniture et pose de canaux porté et accessoires du réseau S4 du secteur S11 | I42: 232266
B43: 39 | C43: Sidi Kacem | D43: SAFSAF | E43: 20-11 | F43: Travaux de réhabilitation des équipements | H43: Recalage des canaux portés du réseau T5S5 du secteur S9 | I43: 1055025
B44: 40 | C44: Sidi Kacem | D44: SAFSAF | E44: 20-11 | F44: Travaux de réhabilitation des équipements | H44: Recalage des canaux portés du réseau T7S5 du secteur S9 | I44: 1004535
B45: 41 | C45: Sidi Kacem | D45: SAFSAF | E45: 20-11 | F45: Travaux de réhabilitation des équipements | H45: Recalage des canaux portés du réseau T2S5 du secteur S9 | I45: 793830
B46: 42 | C46: Sidi Kacem | D46: SAFSAF | E46: 40-21 | F46: Travaux de pistes | G46: Entretien des pistes agricoles | H46: Entretien des pistes agricoles | I46: 2000000
B47: 43 | C47: Sidi Kacem | D47: SAFSAF | E47: 50-23 | F47: Entretien et réparation du réseau d'assainissement et de drainage | G47: Curage des prises sur l’oued, bâche d’aspiration et bassin de régulation. | H47: Curage des prises sur l’oued des stations de pompage S11, S9, 7D et 7B. Nettoyage des grilles de préfiltration des boues colmaté des stations de pompage S11, S9, 7D et 7B. Nettoyage des crépines des boues colmaté de station pompage 7D. Curage des dalots et bâche d’aspiration des stations de pompage S11, S9, 7B. | I47: 200000
B48: 44 | C48: Sidi Kacem | D48: SAFSAF | E48: 50-21 | F48: Entretien et réparation des stations de pompage | G48: Prestation de maintenance des débitmètres et leurs équipements annexes installés au niveau des station de pompage | H48: Changements Sept des débitmètres Ø 600mm inondé des deux stations de pompage S11 et S9. | I48: 580000
B49: 45 | C49: Sidi Kacem | D49: SAFSAF | E49: 50-21 | F49: Entretien et réparation des stations de pompage | G49: Stabilisation Berge oued | H49: Pose de murs en gabions et recouvrement du talus par matelas Reno des stations de pompage S11, S9, 7D et 7B . | I49: 4000000
...

Sheet Guide
B2: Guide d'Utilisation du Canevas Hebdomadaire
B5: RUBRIQUE | D5: DESCRIPTION
B6: Code Couleur | D6: Jaune = Cellule de saisie (modifiable) | Vert = Formule auto (réf. inter-feuille) | Noir = Formule calculée | Bleu = Valeur saisie
B7: Feuilles S01-S04 | D7: Chaque feuille représente une semaine. Saisissez uniquement dans les cellules jaunes : Avancement Physique %, Montants, Avancement Financier %, Observations.
B8: Colonnes Automatiques | D8: % Sem. Préc. : récupéré automatiquement de la semaine précédente | Accroissement % : calculé automatiquement | Écart Phys.-Fin. : différence entre avancement physique et financier
B9: Ajouter Semaines | D9: Pour ajouter S05 : Dupliquez S04, renommez en S05, puis modifiez les formules de la colonne K (% Sem. Préc.) pour référencer S04 au lieu de S03.
B10: Protection | D10: Les cellules de référence et les formules sont verrouillées. Mot de passe de déprotection : ormvag2026
B11: Récapitulatif | D11: La feuille Récapitulatif se met à jour automatiquement à partir de la dernière semaine (S04) et affiche les KPI, l'évolution hebdomadaire et le résumé par province.
B12: Format Pourcentages | D12: Saisir 0.25 pour 25%, 0.50 pour 50%, 1.00 pour 100%. Les valeurs doivent être entre 0 et 1.

Sheet S01
B2: Suivi Hebdomadaire - Semaine 1 - Exécution Physique et Financière
B3: Date Semaine :
B4: N° | C4: Province | D4: Commune | E4: Rubrique | F4: Intitulé Rubrique | G4: Projet | H4: Consistance | I4: Coût Total (DH) | J4: Avancement Physique % | K4: % Physique Sem. Préc. | L4: Accroissement Physique % | M4: Montant Décaissé (DH) | N4: Montant Payé (DH) | O4: Montant Ordonné (DH) | P4: Avancement Financier % | Q4: % Financier Sem. Préc. | R4: Accroissement Financier % | S4: Écart Physique-Financier | T4: Observations
B5: 1 | C5: Sidi Kacem | D5: KHENICHET | E5: 50-23 | F5: Entretien et réparation du réseau d'assainissement et de drainage | G5: Travaux de curage des canaux en terre | H5: Curage des collecteurs d'assainissement du secteur EST2 | I5: 2091568 | K5: 0 | L5: =J5-K5 -> 0 | Q5: 0 | R5: =P5-Q5 -> 0 | S5: =J5-P5 -> 0
B6: 2 | C6: Sidi Kacem | D6: KHENICHET | E6: 40-21 | F6: Travaux de pistes | G6: Travaux de réhabilitation des pistes agricoles | H6: Entretien des pistes agricoles Douar Nouagra et Douar ouled Salem | I6: 78000 | K6: 0 | L6: =J6-K6 -> 0 | Q6: 0 | R6: =P6-Q6 -> 0 | S6: =J6-P6 -> 0
B7: 3 | C7: Sidi Kacem | D7: KHENICHET | E7: 50-23 | F7: Entretien et réparation du réseau d'assainissement et de drainage | G7: Curage des prises sur l’oued, bâche d’aspiration et bassin de régulation. | H7: Curage de la chambre des joints de démontage des siphonnes de la station de pompage EST2. | I7: 126000 | K7: 0 | L7: =J7-K7 -> 0 | Q7: 0 | R7: =P7-Q7 -> 0 | S7: =J7-P7 -> 0
B8: 4 | C8: Sidi Kacem | D8: KHENICHET | E8: 50-21 | F8: Entretien et réparation des stations de pompage | G8: Prestation de maintenance des débitmètres et leurs équipements annexes installés au niveau des station de pompage | H8: Changement trois débitmètre Ø 600mm inondés de la station de pompage EST 2 et deux capteurs VEGASON 62 | I8: 165500 | K8: 0 | L8: =J8-K8 -> 0 | Q8: 0 | R8: =P8-Q8 -> 0 | S8: =J8-P8 -> 0
B9: 5 | C9: Sidi Kacem | D9: BIR TALEB | E9: 50-23 | F9: Entretien et réparation du réseau d'assainissement et de drainage | G9: Travaux de curage des canaux en terre | H9: Curage du canal d'assainisement Tihli Aval | I9: 1000000 | K9: 0 | L9: =J9-K9 -> 0 | Q9: 0 | R9: =P9-Q9 -> 0 | S9: =J9-P9 -> 0
B10: 6 | C10: Sidi Kacem | D10: BIR TALEB | E10: 50-23 | F10: Entretien et réparation du réseau d'assainissement et de drainage | H10: Curage des collecteurs d'assainissement du secteur P11/1 | I10: 846731 | K10: 0 | L10: =J10-K10 -> 0 | Q10: 0 | R10: =P10-Q10 -> 0 | S10: =J10-P10 -> 0
B11: 7 | C11: Sidi Kacem | D11: BIR TALEB | E11: 50-23 | F11: Entretien et réparation du réseau d'assainissement et de drainage | G11: Curage des prises sur l’oued, bâche d’aspiration et bassin de régulation. | H11: Curage des prises sur l’oued de la station de pompage P11/1. | I11: 200000 | K11: 0 | L11: =J11-K11 -> 0 | Q11: 0 | R11: =P11-Q11 -> 0 | S11: =J11-P11 -> 0
B12: 8 | C12: Sidi Kacem | D12: BIR TALEB | E12: 50-21 | F12: Entretien et réparation des stations de pompage | G12: Prestation de maintenance des débitmètres et leurs équipements annexes installés au niveau des station de pompage | H12: Changement trois débitmètre Ø 400mm inondés de la station de pompage P11/1 | I12: 141900 | K12: 0 | L12: =J12-K12 -> 0 | Q12: 0 | R12: =P12-Q12 -> 0 | S12: =J12-P12 -> 0
B13: 9 | C13: Sidi Kacem | D13: BIR TALEB | E13: 50-21 | F13: Entretien et réparation des stations de pompage | G13: Prestations de maintenance et de réparation mécanique des pompes et des groupes motopompes submersibles des stations de pompage. | H13: Démontage et expertise des roues des pompes principaux et pompes a vide de la station P11/1 Changement des roulements, tresses et organes d’effectués de la station P11/1 | I13: 26700 | K13: 0 | L13: =J13-K13 -> 0 | Q13: 0 | R13: =P13-Q13 -> 0 | S13: =J13-P13 -> 0
B14: 10 | C14: Sidi Kacem | D14: BIR TALEB | E14: 50-21 | F14: Entretien et réparation des stations de pompage | G14: Stabilisation Berge oued | H14: Pose de gabions et recouvrement du talus par matelas Reno des stations de pompage P11/1. | I14: 480000 | K14: 0 | L14: =J14-K14 -> 0 | Q14: 0 | R14: =P14-Q14 -> 0 | S14: =J14-P14 -> 0
B15: 11 | C15: Sidi Kacem | D15: BIR TALEB | E15: 50-21 | F15: Entretien et réparation des stations de pompage | G15: Génie civile des locaux des stations de pompage. | H15: Expertise d’état et d’étanchéité des locaux pompes. Renforcement d’étanchéité des locaux pompe sous niveau des oueds des stations de pompage P11/1. Entretien des supports en béton des conduites d’aspiration. | I15: 300000 | K15: 0 | L15: =J15-K15 -> 0 | Q15: 0 | R15: =P15-Q15 -> 0 | S15: =J15-P15 -> 0
B16: 12 | C16: Sidi Kacem | D16: CHEBANAT | E16: 50-23 | F16: Entretien et réparation du réseau d'assainissement et de drainage | G16: Travaux de curage des canaux en terre | H16: Curage des collecteurs d'assainissement des secteur SH5 et SH6. | I16: 1000000 | K16: 0 | L16: =J16-K16 -> 0 | Q16: 0 | R16: =P16-Q16 -> 0 | S16: =J16-P16 -> 0
B17: 13 | C17: Sidi Kacem | D17: CHEBANAT | E17: 50-23 | F17: Entretien et réparation du réseau d'assainissement et de drainage | G17: Travaux de curage des canaux révetus | H17: Curage du canal principal d'irrigation beht partie aval 1. | I17: 739200 | K17: 0 | L17: =J17-K17 -> 0 | Q17: 0 | R17: =P17-Q17 -> 0 | S17: =J17-P17 -> 0
B18: 14 | C18: Sidi Kacem | D18: ZIRARA | E18: 50-23 | F18: Entretien et réparation du réseau d'assainissement et de drainage | G18: Travaux de curage des canaux révetus | H18: Curage du canal principal d'irrigation beht partie aval 2. | I18: 1276800 | K18: 0 | L18: =J18-K18 -> 0 | Q18: 0 | R18: =P18-Q18 -> 0 | S18: =J18-P18 -> 0
B19: 15 | C19: Sidi Kacem | D19: DAR LAASLOUJI | E19: 50-23 | F19: Entretien et réparation du réseau d'assainissement et de drainage | G19: Travaux de curage des canaux en terre | H19: Curage des collecteurs d'assainissement des secteurs P8-1 et P8-2 | I19: 5796360 | K19: 0 | L19: =J19-K19 -> 0 | Q19: 0 | R19: =P19-Q19 -> 0 | S19: =J19-P19 -> 0
B20: 16 | C20: Sidi Kacem | D20: DAR LAASLOUJI | E20: 40-21 | F20: Travaux de pistes | G20: Entretien des pistes agricoles | H20: Entretien des pistes agricoles | I20: 340000 | K20: 0 | L20: =J20-K20 -> 0 | Q20: 0 | R20: =P20-Q20 -> 0 | S20: =J20-P20 -> 0
B21: 17 | C21: Sidi Kacem | D21: HOUAFATE | E21: 20-11 | F21: Travaux de réhabilitation des équipements | G21: Travaux de réhabilitation des canaux portés d'irrigation | H21: Fourniture et de pose de canaux porté et accessoires du réseau S3 du secteur S13 | I21: 397934 | K21: 0 | L21: =J21-K21 -> 0 | Q21: 0 | R21: =P21-Q21 -> 0 | S21: =J21-P21 -> 0
B22: 18 | C22: Sidi Kacem | D22: HOUAFATE | E22: 20-11 | F22: Travaux de réhabilitation des équipements | H22: Fourniture et de pose de canaux porté et accessoires du réseau T2S1 du secteur S13 | I22: 207575 | K22: 0 | L22: =J22-K22 -> 0 | Q22: 0 | R22: =P22-Q22 -> 0 | S22: =J22-P22 -> 0
B23: 19 | C23: Sidi Kacem | D23: HOUAFATE | E23: 40-21 | F23: Travaux de pistes | G23: Entretien des pistes agricoles | H23: Entretien des pistes agricoles | I23: 2200000 | K23: 0 | L23: =J23-K23 -> 0 | Q23: 0 | R23: =P23-Q23 -> 0 | S23: =J23-P23 -> 0
B24: 20 | C24: Sidi Kacem | D24: HOUAFATE | E24: 50-23 | F24: Entretien et réparation du réseau d'assainissement et de drainage | G24: Curage des prises sur l’oued, bâche d’aspiration et bassin de régulation. | H24: Curage des prises sur l’oued de la station de pompage S17 et S13. Nettoyage des grilles de préfiltration des boues colmaté de la station de pompage S17 et S13. Curage de la bâche d’aspiration de la station S17 et S13. | I24: 300000 | K24: 0 | L24: =J24-K24 -> 0 | Q24: 0 | R24: =P24-Q24 -> 0 | S24: =J24-P24 -> 0
B25: 21 | C25: Sidi Kacem | D25: HOUAFATE | E25: 50-21 | F25: Entretien et réparation des stations de pompage | G25: Prestation de maintenance des débitmètres et leurs équipements annexes installés au niveau des station de pompage | H25: Changement trois débitmètre Ø 600mm inondés de la station de pompage S13. | I25: 250000 | K25: 0 | L25: =J25-K25 -> 0 | Q25: 0 | R25: =P25-Q25 -> 0 | S25: =J25-P25 -> 0
B26: 22 | C26: Sidi Kacem | D26: HOUAFATE | E26: 50-21 | F26: Entretien et réparation des stations de pompage | G26: Prestations de maintenance des moteurs électriques des stations de pompage. | H26: Révision des trois moteurs électriques 200 KW principaux de la station S13. Révision des deux moteurs électriques 5,5 KW groupes vide de la station S13. | I26: 25000 | K26: 0 | L26: =J26-K26 -> 0 | Q26: 0 | R26: =P26-Q26 -> 0 | S26: =J26-P26 -> 0
B27: 23 | C27: Sidi Kacem | D27: HOUAFATE | E27: 50-21 | F27: Entretien et réparation des stations de pompage | G27: Prestations de maintenance et de réparation mécanique des pompes et des groupes motopompes submersibles des stations de pompage. | H27: Démontage et expertise des roues des pompes principaux et pompes a vide de la station S13. Changement des roulements, tresses et organes d’effectués de la station S13. | I27: 38000 | K27: 0 | L27: =J27-K27 -> 0 | Q27: 0 | R27: =P27-Q27 -> 0 | S27: =J27-P27 -> 0
B28: 24 | C28: Sidi Kacem | D28: HOUAFATE | E28: 50-21 | F28: Entretien et réparation des stations de pompage | G28: Stabilisation Berge oued | H28: Pose de gabions et recouvrement du talus par matelas Reno des stations de pompage S13. | I28: 10560000 | K28: 0 | L28: =J28-K28 -> 0 | Q28: 0 | R28: =P28-Q28 -> 0 | S28: =J28-P28 -> 0
B29: 25 | C29: Sidi Kacem | D29: HOUAFATE | E29: 50-21 | F29: Entretien et réparation des stations de pompage | G29: Mur clôture des stations de pompage. | H29: Stabilisation du sol et reconstruction des murs clôture (270m) cote oued de la station S17. | I29: 144000 | K29: 0 | L29: =J29-K29 -> 0 | Q29: 0 | R29: =P29-Q29 -> 0 | S29: =J29-P29 -> 0
B30: 26 | C30: Sidi Kacem | D30: HOUAFATE | E30: 50-21 | F30: Entretien et réparation des stations de pompage | G30: Génie civile des locaux des stations de pompage. | H30: Expertise d’état et d’étanchéité des locaux pompes, commande, puissance des stations de pompage S17 et S13. Renforcement d’étanchéité des locaux pompe sous niveau des oueds des stations de pompage S17 et S13. | I30: 800000 | K30: 0 | L30: =J30-K30 -> 0 | Q30: 0 | R30: =P30-Q30 -> 0 | S30: =J30-P30 -> 0
B31: 27 | C31: Sidi Kacem | D31: NOUIRAT | E31: 50-23 | F31: Entretien et réparation du réseau d'assainissement et de drainage | G31: Travaux de curage des canaux en terre | H31: Curage des collecteurs d'assainissement des secteurs EST1 et N5 | I31: 1733306 | K31: 0 | L31: =J31-K31 -> 0 | Q31: 0 | R31: =P31-Q31 -> 0 | S31: =J31-P31 -> 0
B32: 28 | C32: Sidi Kacem | D32: NOUIRAT | E32: 40-21 | F32: Travaux de pistes | G32: Entretien des pistes agricoles | H32: Entretien des pistes agricoles | I32: 670000 | K32: 0 | L32: =J32-K32 -> 0 | Q32: 0 | R32: =P32-Q32 -> 0 | S32: =J32-P32 -> 0
B33: 29 | C33: Sidi Kacem | D33: NOUIRAT | E33: 20-11 | F33: Travaux de réhabilitation des équipements | G33: Travaux de réhabilitation des ouvrages de génie civil | H33: Réhabilitation de l'ouvrage( genie civil ,gabiollannage,clapet anti retour et buse) de l'ouvrage de débouche SE1 | I33: 2500000 | K33: 0 | L33: =J33-K33 -> 0 | Q33: 0 | R33: =P33-Q33 -> 0 | S33: =J33-P33 -> 0
B34: 30 | C34: Sidi Kacem | D34: NOUIRAT | E34: 50-23 | F34: Entretien et réparation du réseau d'assainissement et de drainage | G34: Curage des prises sur l’oued, bâche d’aspiration et bassin de régulation. | H34: Curage des prises sur l’oued de la station de pompage E1. Nettoyage des grilles de préfiltration des boues colmaté de la station de pompage E1. Curage de la bâche d’aspiration de la station E1. | I34: 800000 | K34: 0 | L34: =J34-K34 -> 0 | Q34: 0 | R34: =P34-Q34 -> 0 | S34: =J34-P34 -> 0
... B42: 38 | C42: Sidi Kacem | D42: SAFSAF | E42: 20-11 | F42: Travaux de réhabilitation des équipements | G42: Travaux de réhabilitation des canaux portés d'irrigation | H42: Fourniture et pose de canaux porté et accessoires du réseau S4 du secteur S11 | I42: 232266 | K42: 0 | L42: =J42-K42 -> 0 | Q42: 0 | R42: =P42-Q42 -> 0 | S42: =J42-P42 -> 0
B43: 39 | C43: Sidi Kacem | D43: SAFSAF | E43: 20-11 | F43: Travaux de réhabilitation des équipements | H43: Recalage des canaux portés du réseau T5S5 du secteur S9 | I43: 1055025 | K43: 0 | L43: =J43-K43 -> 0 | Q43: 0 | R43: =P43-Q43 -> 0 | S43: =J43-P43 -> 0
B44: 40 | C44: Sidi Kacem | D44: SAFSAF | E44: 20-11 | F44: Travaux de réhabilitation des équipements | H44: Recalage des canaux portés du réseau T7S5 du secteur S9 | I44: 1004535 | K44: 0 | L44: =J44-K44 -> 0 | Q44: 0 | R44: =P44-Q44 -> 0 | S44: =J44-P44 -> 0
B45: 41 | C45: Sidi Kacem | D45: SAFSAF | E45: 20-11 | F45: Travaux de réhabilitation des équipements | H45: Recalage des canaux portés du réseau T2S5 du secteur S9 | I45: 793830 | K45: 0 | L45: =J45-K45 -> 0 | Q45: 0 | R45: =P45-Q45 -> 0 | S45: =J45-P45 -> 0
B46: 42 | C46: Sidi Kacem | D46: SAFSAF | E46: 40-21 | F46: Travaux de pistes | G46: Entretien des pistes agricoles | H46: Entretien des pistes agricoles | I46: 2000000 | K46: 0 | L46: =J46-K46 -> 0 | Q46: 0 | R46: =P46-Q46 -> 0 | S46: =J46-P46 -> 0
B47: 43 | C47: Sidi Kacem | D47: SAFSAF | E47: 50-23 | F47: Entretien et réparation du réseau d'assainissement et de drainage | G47: Curage des prises sur l’oued, bâche d’aspiration et bassin de régulation. | H47: Curage des prises sur l’oued des stations de pompage S11, S9, 7D et 7B. Nettoyage des grilles de préfiltration des boues colmaté des stations de pompage S11, S9, 7D et 7B. Nettoyage des crépines des boues colmaté de station pompage 7D. Curage des dalots et bâche d’aspiration des stations de pompage S11, S9, 7B. | I47: 200000 | K47: 0 | L47: =J47-K47 -> 0 | Q47: 0 | R47: =P47-Q47 -> 0 | S47: =J47-P47 -> 0
B48: 44 | C48: Sidi Kacem | D48: SAFSAF | E48: 50-21 | F48: Entretien et réparation des stations de pompage | G48: Prestation de maintenance des débitmètres et leurs équipements annexes installés au niveau des station de pompage | H48: Changements Sept des débitmètres Ø 600mm inondé des deux stations de pompage S11 et S9. | I48: 580000 | K48: 0 | L48: =J48-K48 -> 0 | Q48: 0 | R48: =P48-Q48 -> 0 | S48: =J48-P48 -> 0
...

Sheet S02
B2: Suivi Hebdomadaire - Semaine 2 - Exécution Physique et Financière
B3: Date Semaine :
B4: N° | C4: Province | D4: Commune | E4: Rubrique | F4: Intitulé Rubrique | G4: Projet | H4: Consistance | I4: Coût Total (DH) | J4: Avancement Physique % | K4: % Physique Sem. Préc. | L4: Accroissement Physique % | M4: Montant Décaissé (DH) | N4: Montant Payé (DH) | O4: Montant Ordonné (DH) | P4: Avancement Financier % | Q4: % Financier Sem. Préc. | R4: Accroissement Financier % | S4: Écart Physique-Financier | T4: Observations
B5: 1 | C5: Sidi Kacem | D5: KHENICHET | E5: 50-23 | F5: Entretien et réparation du réseau d'assainissement et de drainage | G5: Travaux de curage des canaux en terre | H5: Curage des collecteurs d'assainissement du secteur EST2 | I5: 2091568 | K5: =S01!J5 -> 0 | L5: =J5-K5 -> 0 | Q5: =S01!P5 -> 0 | R5: =P5-Q5 -> 0 | S5: =J5-P5 -> 0
B6: 2 | C6: Sidi Kacem | D6: KHENICHET | E6: 40-21 | F6: Travaux de pistes | G6: Travaux de réhabilitation des pistes agricoles | H6: Entretien des pistes agricoles Douar Nouagra et Douar ouled Salem | I6: 78000 | K6: =S01!J6 -> 0 | L6: =J6-K6 -> 0 | Q6: =S01!P6 -> 0 | R6: =P6-Q6 -> 0 | S6: =J6-P6 -> 0
B7: 3 | C7: Sidi Kacem | D7: KHENICHET | E7: 50-23 | F7: Entretien et réparation du réseau d'assainissement et de drainage | G7: Curage des prises sur l’oued, bâche d’aspiration et bassin de régulation. | H7: Curage de la chambre des joints de démontage des siphonnes de la station de pompage EST2. | I7: 126000 | K7: =S01!J7 -> 0 | L7: =J7-K7 -> 0 | Q7: =S01!P7 -> 0 | R7: =P7-Q7 -> 0 | S7: =J7-P7 -> 0
B8: 4 | C8: Sidi Kacem | D8: KHENICHET | E8: 50-21 | F8: Entretien et réparation des stations de pompage | G8: Prestation de maintenance des débitmètres et leurs équipements annexes installés au niveau des station de pompage | H8: Changement trois débitmètre Ø 600mm inondés de la station de pompage EST 2 et deux capteurs VEGASON 62 | I8: 165500 | K8: =S01!J8 -> 0 | L8: =J8-K8 -> 0 | Q8: =S01!P8 -> 0 | R8: =P8-Q8 -> 0 | S8: =J8-P8 -> 0
B9: 5 | C9: Sidi Kacem | D9: BIR TALEB | E9: 50-23 | F9: Entretien et réparation du réseau d'assainissement et de drainage | G9: Travaux de curage des canaux en terre | H9: Curage du canal d'assainisement Tihli Aval | I9: 1000000 | K9: =S01!J9 -> 0 | L9: =J9-K9 -> 0 | Q9: =S01!P9 -> 0 | R9: =P9-Q9 -> 0 | S9: =J9-P9 -> 0
B10: 6 | C10: Sidi Kacem | D10: BIR TALEB | E10: 50-23 | F10: Entretien et réparation du réseau d'assainissement et de drainage | H10: Curage des collecteurs d'assainissement du secteur P11/1 | I10: 846731 | K10: =S01!J10 -> 0 | L10: =J10-K10 -> 0 | Q10: =S01!P10 -> 0 | R10: =P10-Q10 -> 0 | S10: =J10-P10 -> 0
B11: 7 | C11: Sidi Kacem | D11: BIR TALEB | E11: 50-23 | F11: Entretien et réparation du réseau d'assainissement et de drainage | G11: Curage des prises sur l’oued, bâche d’aspiration et bassin de régulation. | H11: Curage des prises sur l’oued de la station de pompage P11/1. | I11: 200000 | K11: =S01!J11 -> 0 | L11: =J11-K11 -> 0 | Q11: =S01!P11 -> 0 | R11: =P11-Q11 -> 0 | S11: =J11-P11 -> 0
B12: 8 | C12: Sidi Kacem | D12: BIR TALEB | E12: 50-21 | F12: Entretien et réparation des stations de pompage | G12: Prestation de maintenance des débitmètres et leurs équipements annexes installés au niveau des station de pompage | H12: Changement trois débitmètre Ø 400mm inondés de la station de pompage P11/1 | I12: 141900 | K12: =S01!J12 -> 0 | L12: =J12-K12 -> 0 | Q12: =S01!P12 -> 0 | R12: =P12-Q12 -> 0 | S12: =J12-P12 -> 0
B13: 9 | C13: Sidi Kacem | D13: BIR TALEB | E13: 50-21 | F13: Entretien et réparation des stations de pompage | G13: Prestations de maintenance et de réparation mécanique des pompes et des groupes motopompes submersibles des stations de pompage. | H13: Démontage et expertise des roues des pompes principaux et pompes a vide de la station P11/1 Changement des roulements, tresses et organes d’effectués de la station P11/1 | I13: 26700 | K13: =S01!J13 -> 0 | L13: =J13-K13 -> 0 | Q13: =S01!P13 -> 0 | R13: =P13-Q13 -> 0 | S13: =J13-P13 -> 0
B14: 10 | C14: Sidi Kacem | D14: BIR TALEB | E14: 50-21 | F14: Entretien et réparation des stations de pompage | G14: Stabilisation Berge oued | H14: Pose de gabions et recouvrement du talus par matelas Reno des stations de pompage P11/1. | I14: 480000 | K14: =S01!J14 -> 0 | L14: =J14-K14 -> 0 | Q14: =S01!P14 -> 0 | R14: =P14-Q14 -> 0 | S14: =J14-P14 -> 0
B15: 11 | C15: Sidi Kacem | D15: BIR TALEB | E15: 50-21 | F15: Entretien et réparation des stations de pompage | G15: Génie civile des locaux des stations de pompage. | H15: Expertise d’état et d’étanchéité des locaux pompes. Renforcement d’étanchéité des locaux pompe sous niveau des oueds des stations de pompage P11/1. Entretien des supports en béton des conduites d’aspiration. | I15: 300000 | K15: =S01!J15 -> 0 | L15: =J15-K15 -> 0 | Q15: =S01!P15 -> 0 | R15: =P15-Q15 -> 0 | S15: =J15-P15 -> 0
B16: 12 | C16: Sidi Kacem | D16: CHEBANAT | E16: 50-23 | F16: Entretien et réparation du réseau d'assainissement et de drainage | G16: Travaux de curage des canaux en terre | H16: Curage des collecteurs d'assainissement des secteur SH5 et SH6. | I16: 1000000 | K16: =S01!J16 -> 0 | L16: =J16-K16 -> 0 | Q16: =S01!P16 -> 0 | R16: =P16-Q16 -> 0 | S16: =J16-P16 -> 0
B17: 13 | C17: Sidi Kacem | D17: CHEBANAT | E17: 50-23 | F17: Entretien et réparation du réseau d'assainissement et de drainage | G17: Travaux de curage des canaux révetus | H17: Curage du canal principal d'irrigation beht partie aval 1. | I17: 739200 | K17: =S01!J17 -> 0 | L17: =J17-K17 -> 0 | Q17: =S01!P17 -> 0 | R17: =P17-Q17 -> 0 | S17: =J17-P17 -> 0
B18: 14 | C18: Sidi Kacem | D18: ZIRARA | E18: 50-23 | F18: Entretien et réparation du réseau d'assainissement et de drainage | G18: Travaux de curage des canaux révetus | H18: Curage du canal principal d'irrigation beht partie aval 2. | I18: 1276800 | K18: =S01!J18 -> 0 | L18: =J18-K18 -> 0 | Q18: =S01!P18 -> 0 | R18: =P18-Q18 -> 0 | S18: =J18-P18 -> 0
B19: 15 | C19: Sidi Kacem | D19: DAR LAASLOUJI | E19: 50-23 | F19: Entretien et réparation du réseau d'assainissement et de drainage | G19: Travaux de curage des canaux en terre | H19: Curage des collecteurs d'assainissement des secteurs P8-1 et P8-2 | I19: 5796360 | K19: =S01!J19 -> 0 | L19: =J19-K19 -> 0 | Q19: =S01!P19 -> 0 | R19: =P19-Q19 -> 0 | S19: =J19-P19 -> 0
B20: 16 | C20: Sidi Kacem | D20: DAR LAASLOUJI | E20: 40-21 | F20: Travaux de pistes | G20: Entretien des pistes agricoles | H20: Entretien des pistes agricoles | I20: 340000 | K20: =S01!J20 -> 0 | L20: =J20-K20 -> 0 | Q20: =S01!P20 -> 0 | R20: =P20-Q20 -> 0 | S20: =J20-P20 -> 0
B21: 17 | C21: Sidi Kacem | D21: HOUAFATE | E21: 20-11 | F21: Travaux de réhabilitation des équipements | G21: Travaux de réhabilitation des canaux portés d'irrigation | H21: Fourniture et de pose de canaux porté et accessoires du réseau S3 du secteur S13 | I21: 397934 | K21: =S01!J21 -> 0 | L21: =J21-K21 -> 0 | Q21: =S01!P21 -> 0 | R21: =P21-Q21 -> 0 | S21: =J21-P21 -> 0
B22: 18 | C22: Sidi Kacem | D22: HOUAFATE | E22: 20-11 | F22: Travaux de réhabilitation des équipements | H22: Fourniture et de pose de canaux porté et accessoires du réseau T2S1 du secteur S13 | I22: 207575 | K22: =S01!J22 -> 0 | L22: =J22-K22 -> 0 | Q22: =S01!P22 -> 0 | R22: =P22-Q22 -> 0 | S22: =J22-P22 -> 0
B23: 19 | C23: Sidi Kacem | D23: HOUAFATE | E23: 40-21 | F23: Travaux de pistes | G23: Entretien des pistes agricoles | H23: Entretien des pistes agricoles | I23: 2200000 | K23: =S01!J23 -> 0 | L23: =J23-K23 -> 0 | Q23: =S01!P23 -> 0 | R23: =P23-Q23 -> 0 | S23: =J23-P23 -> 0
B24: 20 | C24: Sidi Kacem | D24: HOUAFATE | E24: 50-23 | F24: Entretien et réparation du réseau d'assainissement et de drainage | G24: Curage des prises sur l’oued, bâche d’aspiration et bassin de régulation. | H24: Curage des prises sur l’oued de la station de pompage S17 et S13. Nettoyage des grilles de préfiltration des boues colmaté de la station de pompage S17 et S13. Curage de la bâche d’aspiration de la station S17 et S13. | I24: 300000 | K24: =S01!J24 -> 0 | L24: =J24-K24 -> 0 | Q24: =S01!P24 -> 0 | R24: =P24-Q24 -> 0 | S24: =J24-P24 -> 0
B25: 21 | C25: Sidi Kacem | D25: HOUAFATE | E25: 50-21 | F25: Entretien et réparation des stations de pompage | G25: Prestation de maintenance des débitmètres et leurs équipements annexes installés au niveau des station de pompage | H25: Changement trois débitmètre Ø 600mm inondés de la station de pompage S13. | I25: 250000 | K25: =S01!J25 -> 0 | L25: =J25-K25 -> 0 | Q25: =S01!P25 -> 0 | R25: =P25-Q25 -> 0 | S25: =J25-P25 -> 0
B26: 22 | C26: Sidi Kacem | D26: HOUAFATE | E26: 50-21 | F26: Entretien et réparation des stations de pompage | G26: Prestations de maintenance des moteurs électriques des stations de pompage. | H26: Révision des trois moteurs électriques 200 KW principaux de la station S13. Révision des deux moteurs électriques 5,5 KW groupes vide de la station S13. | I26: 25000 | K26: =S01!J26 -> 0 | L26: =J26-K26 -> 0 | Q26: =S01!P26 -> 0 | R26: =P26-Q26 -> 0 | S26: =J26-P26 -> 0
B27: 23 | C27: Sidi Kacem | D27: HOUAFATE | E27: 50-21 | F27: Entretien et réparation des stations de pompage | G27: Prestations de maintenance et de réparation mécanique des pompes et des groupes motopompes submersibles des stations de pompage. | H27: Démontage et expertise des roues des pompes principaux et pompes a vide de la station S13. Changement des roulements, tresses et organes d’effectués de la station S13. | I27: 38000 | K27: =S01!J27 -> 0 | L27: =J27-K27 -> 0 | Q27: =S01!P27 -> 0 | R27: =P27-Q27 -> 0 | S27: =J27-P27 -> 0
B28: 24 | C28: Sidi Kacem | D28: HOUAFATE | E28: 50-21 | F28: Entretien et réparation des stations de pompage | G28: Stabilisation Berge oued | H28: Pose de gabions et recouvrement du talus par matelas Reno des stations de pompage S13. | I28: 10560000 | K28: =S01!J28 -> 0 | L28: =J28-K28 -> 0 | Q28: =S01!P28 -> 0 | R28: =P28-Q28 -> 0 | S28: =J28-P28 -> 0
B29: 25 | C29: Sidi Kacem | D29: HOUAFATE | E29: 50-21 | F29: Entretien et réparation des stations de pompage | G29: Mur clôture des stations de pompage. | H29: Stabilisation du sol et reconstruction des murs clôture (270m) cote oued de la station S17. | I29: 144000 | K29: =S01!J29 -> 0 | L29: =J29-K29 -> 0 | Q29: =S01!P29 -> 0 | R29: =P29-Q29 -> 0 | S29: =J29-P29 -> 0
B30: 26 | C30: Sidi Kacem | D30: HOUAFATE | E30: 50-21 | F30: Entretien et réparation des stations de pompage | G30: Génie civile des locaux des stations de pompage. | H30: Expertise d’état et d’étanchéité des locaux pompes, commande, puissance des stations de pompage S17 et S13. Renforcement d’étanchéité des locaux pompe sous niveau des oueds des stations de pompage S17 et S13. | I30: 800000 | K30: =S01!J30 -> 0 | L30: =J30-K30 -> 0 | Q30: =S01!P30 -> 0 | R30: =P30-Q30 -> 0 | S30: =J30-P30 -> 0
B31: 27 | C31: Sidi Kacem | D31: NOUIRAT | E31: 50-23 | F31: Entretien et réparation du réseau d'assainissement et de drainage | G31: Travaux de curage des canaux en terre | H31: Curage des collecteurs d'assainissement des secteurs EST1 et N5 | I31: 1733306 | K31: =S01!J31 -> 0 | L31: =J31-K31 -> 0 | Q31: =S01!P31 -> 0 | R31: =P31-Q31 -> 0 | S31: =J31-P31 -> 0
B32: 28 | C32: Sidi Kacem | D32: NOUIRAT | E32: 40-21 | F32: Travaux de pistes | G32: Entretien des pistes agricoles | H32: Entretien des pistes agricoles | I32: 670000 | K32: =S01!J32 -> 0 | L32: =J32-K32 -> 0 | Q32: =S01!P32 -> 0 | R32: =P32-Q32 -> 0 | S32: =J32-P32 -> 0
B33: 29 | C33: Sidi Kacem | D33: NOUIRAT | E33: 20-11 | F33: Travaux de réhabilitation des équipements | G33: Travaux de réhabilitation des ouvrages de génie civil | H33: Réhabilitation de l'ouvrage( genie civil ,gabiollannage,clapet anti retour et buse) de l'ouvrage de débouche SE1 | I33: 2500000 | K33: =S01!J33 -> 0 | L33: =J33-K33 -> 0 | Q33: =S01!P33 -> 0 | R33: =P33-Q33 -> 0 | S33: =J33-P33 -> 0
B34: 30 | C34: Sidi Kacem | D34: NOUIRAT | E34: 50-23 | F34: Entretien et réparation du réseau d'assainissement et de drainage | G34: Curage des prises sur l’oued, bâche d’aspiration et bassin de régulation. | H34: Curage des prises sur l’oued de la station de pompage E1. Nettoyage des grilles de préfiltration des boues colmaté de la station de pompage E1. Curage de la bâche d’aspiration de la station E1. | I34: 800000 | K34: =S01!J34 -> 0 | L34: =J34-K34 -> 0 | Q34: =S01!P34 -> 0 | R34: =P34-Q34 -> 0 | S34: =J34-P34 -> 0
... B42: 38 | C42: Sidi Kacem | D42: SAFSAF | E42: 20-11 | F42: Travaux de réhabilitation des équipements | G42: Travaux de réhabilitation des canaux portés d'irrigation | H42: Fourniture et pose de canaux porté et accessoires du réseau S4 du secteur S11 | I42: 232266 | K42: =S01!J42 -> 0 | L42: =J42-K42 -> 0 | Q42: =S01!P42 -> 0 | R42: =P42-Q42 -> 0 | S42: =J42-P42 -> 0
B43: 39 | C43: Sidi Kacem | D43: SAFSAF | E43: 20-11 | F43: Travaux de réhabilitation des équipements | H43: Recalage des canaux portés du réseau T5S5 du secteur S9 | I43: 1055025 | K43: =S01!J43 -> 0 | L43: =J43-K43 -> 0 | Q43: =S01!P43 -> 0 | R43: =P43-Q43 -> 0 | S43: =J43-P43 -> 0
B44: 40 | C44: Sidi Kacem | D44: SAFSAF | E44: 20-11 | F44: Travaux de réhabilitation des équipements | H44: Recalage des canaux portés du réseau T7S5 du secteur S9 | I44: 1004535 | K44: =S01!J44 -> 0 | L44: =J44-K44 -> 0 | Q44: =S01!P44 -> 0 | R44: =P44-Q44 -> 0 | S44: =J44-P44 -> 0
B45: 41 | C45: Sidi Kacem | D45: SAFSAF | E45: 20-11 | F45: Travaux de réhabilitation des équipements | H45: Recalage des canaux portés du réseau T2S5 du secteur S9 | I45: 793830 | K45: =S01!J45 -> 0 | L45: =J45-K45 -> 0 | Q45: =S01!P45 -> 0 | R45: =P45-Q45 -> 0 | S45: =J45-P45 -> 0
B46: 42 | C46: Sidi Kacem | D46: SAFSAF | E46: 40-21 | F46: Travaux de pistes | G46: Entretien des pistes agricoles | H46: Entretien des pistes agricoles | I46: 2000000 | K46: =S01!J46 -> 0 | L46: =J46-K46 -> 0 | Q46: =S01!P46 -> 0 | R46: =P46-Q46 -> 0 | S46: =J46-P46 -> 0
B47: 43 | C47: Sidi Kacem | D47: SAFSAF | E47: 50-23 | F47: Entretien et réparation du réseau d'assainissement et de drainage | G47: Curage des prises sur l’oued, bâche d’aspiration et bassin de régulation. | H47: Curage des prises sur l’oued des stations de pompage S11, S9, 7D et 7B. Nettoyage des grilles de préfiltration des boues colmaté des stations de pompage S11, S9, 7D et 7B. Nettoyage des crépines des boues colmaté de station pompage 7D. Curage des dalots et bâche d’aspiration des stations de pompage S11, S9, 7B. | I47: 200000 | K47: =S01!J47 -> 0 | L47: =J47-K47 -> 0 | Q47: =S01!P47 -> 0 | R47: =P47-Q47 -> 0 | S47: =J47-P47 -> 0
B48: 44 | C48: Sidi Kacem | D48: SAFSAF | E48: 50-21 | F48: Entretien et réparation des stations de pompage | G48: Prestation de maintenance des débitmètres et leurs équipements annexes installés au niveau des station de pompage | H48: Changements Sept des débitmètres Ø 600mm inondé des deux stations de pompage S11 et S9. | I48: 580000 | K48: =S01!J48 -> 0 | L48: =J48-K48 -> 0 | Q48: =S01!P48 -> 0 | R48: =P48-Q48 -> 0 | S48: =J48-P48 -> 0
...

Sheet S03
B2: Suivi Hebdomadaire - Semaine 3 - Exécution Physique et Financière
B3: Date Semaine :
B4: N° | C4: Province | D4: Commune | E4: Rubrique | F4: Intitulé Rubrique | G4: Projet | H4: Consistance | I4: Coût Total (DH) | J4: Avancement Physique % | K4: % Physique Sem. Préc. | L4: Accroissement Physique % | M4: Montant Décaissé (DH) | N4: Montant Payé (DH) | O4: Montant Ordonné (DH) | P4: Avancement Financier % | Q4: % Financier Sem. Préc. | R4: Accroissement Financier % | S4: Écart Physique-Financier | T4: Observations
B5: 1 | C5: Sidi Kacem | D5: KHENICHET | E5: 50-23 | F5: Entretien et réparation du réseau d'assainissement et de drainage | G5: Travaux de curage des canaux en terre | H5: Curage des collecteurs d'assainissement du secteur EST2 | I5: 2091568 | K5: =S02!J5 -> 0 | L5: =J5-K5 -> 0 | Q5: =S02!P5 -> 0 | R5: =P5-Q5 -> 0 | S5: =J5-P5 -> 0
B6: 2 | C6: Sidi Kacem | D6: KHENICHET | E6: 40-21 | F6: Travaux de pistes | G6: Travaux de réhabilitation des pistes agricoles | H6: Entretien des pistes agricoles Douar Nouagra et Douar ouled Salem | I6: 78000 | K6: =S02!J6 -> 0 | L6: =J6-K6 -> 0 | Q6: =S02!P6 -> 0 | R6: =P6-Q6 -> 0 | S6: =J6-P6 -> 0
B7: 3 | C7: Sidi Kacem | D7: KHENICHET | E7: 50-23 | F7: Entretien et réparation du réseau d'assainissement et de drainage | G7: Curage des prises sur l’oued, bâche d’aspiration et bassin de régulation. | H7: Curage de la chambre des joints de démontage des siphonnes de la station de pompage EST2. | I7: 126000 | K7: =S02!J7 -> 0 | L7: =J7-K7 -> 0 | Q7: =S02!P7 -> 0 | R7: =P7-Q7 -> 0 | S7: =J7-P7 -> 0
B8: 4 | C8: Sidi Kacem | D8: KHENICHET | E8: 50-21 | F8: Entretien et réparation des stations de pompage | G8: Prestation de maintenance des débitmètres et leurs équipements annexes installés au niveau des station de pompage | H8: Changement trois débitmètre Ø 600mm inondés de la station de pompage EST 2 et deux capteurs VEGASON 62 | I8: 165500 | K8: =S02!J8 -> 0 | L8: =J8-K8 -> 0 | Q8: =S02!P8 -> 0 | R8: =P8-Q8 -> 0 | S8: =J8-P8 -> 0
B9: 5 | C9: Sidi Kacem | D9: BIR TALEB | E9: 50-23 | F9: Entretien et réparation du réseau d'assainissement et de drainage | G9: Travaux de curage des canaux en terre | H9: Curage du canal d'assainisement Tihli Aval | I9: 1000000 | K9: =S02!J9 -> 0 | L9: =J9-K9 -> 0 | Q9: =S02!P9 -> 0 | R9: =P9-Q9 -> 0 | S9: =J9-P9 -> 0
B10: 6 | C10: Sidi Kacem | D10: BIR TALEB | E10: 50-23 | F10: Entretien et réparation du réseau d'assainissement et de drainage | H10: Curage des collecteurs d'assainissement du secteur P11/1 | I10: 846731 | K10: =S02!J10 -> 0 | L10: =J10-K10 -> 0 | Q10: =S02!P10 -> 0 | R10: =P10-Q10 -> 0 | S10: =J10-P10 -> 0
B11: 7 | C11: Sidi Kacem | D11: BIR TALEB | E11: 50-23 | F11: Entretien et réparation du réseau d'assainissement et de drainage | G11: Curage des prises sur l’oued, bâche d’aspiration et bassin de régulation. | H11: Curage des prises sur l’oued de la station de pompage P11/1. | I11: 200000 | K11: =S02!J11 -> 0 | L11: =J11-K11 -> 0 | Q11: =S02!P11 -> 0 | R11: =P11-Q11 -> 0 | S11: =J11-P11 -> 0
B12: 8 | C12: Sidi Kacem | D12: BIR TALEB | E12: 50-21 | F12: Entretien et réparation des stations de pompage | G12: Prestation de maintenance des débitmètres et leurs équipements annexes installés au niveau des station de pompage | H12: Changement trois débitmètre Ø 400mm inondés de la station de pompage P11/1 | I12: 141900 | K12: =S02!J12 -> 0 | L12: =J12-K12 -> 0 | Q12: =S02!P12 -> 0 | R12: =P12-Q12 -> 0 | S12: =J12-P12 -> 0
B13: 9 | C13: Sidi Kacem | D13: BIR TALEB | E13: 50-21 | F13: Entretien et réparation des stations de pompage | G13: Prestations de maintenance et de réparation mécanique des pompes et des groupes motopompes submersibles des stations de pompage. | H13: Démontage et expertise des roues des pompes principaux et pompes a vide de la station P11/1 Changement des roulements, tresses et organes d’effectués de la station P11/1 | I13: 26700 | K13: =S02!J13 -> 0 | L13: =J13-K13 -> 0 | Q13: =S02!P13 -> 0 | R13: =P13-Q13 -> 0 | S13: =J13-P13 -> 0
B14: 10 | C14: Sidi Kacem | D14: BIR TALEB | E14: 50-21 | F14: Entretien et réparation des stations de pompage | G14: Stabilisation Berge oued | H14: Pose de gabions et recouvrement du talus par matelas Reno des stations de pompage P11/1. | I14: 480000 | K14: =S02!J14 -> 0 | L14: =J14-K14 -> 0 | Q14: =S02!P14 -> 0 | R14: =P14-Q14 -> 0 | S14: =J14-P14 -> 0
B15: 11 | C15: Sidi Kacem | D15: BIR TALEB | E15: 50-21 | F15: Entretien et réparation des stations de pompage | G15: Génie civile des locaux des stations de pompage. | H15: Expertise d’état et d’étanchéité des locaux pompes. Renforcement d’étanchéité des locaux pompe sous niveau des oueds des stations de pompage P11/1. Entretien des supports en béton des conduites d’aspiration. | I15: 300000 | K15: =S02!J15 -> 0 | L15: =J15-K15 -> 0 | Q15: =S02!P15 -> 0 | R15: =P15-Q15 -> 0 | S15: =J15-P15 -> 0
B16: 12 | C16: Sidi Kacem | D16: CHEBANAT | E16: 50-23 | F16: Entretien et réparation du réseau d'assainissement et de drainage | G16: Travaux de curage des canaux en terre | H16: Curage des collecteurs d'assainissement des secteur SH5 et SH6. | I16: 1000000 | K16: =S02!J16 -> 0 | L16: =J16-K16 -> 0 | Q16: =S02!P16 -> 0 | R16: =P16-Q16 -> 0 | S16: =J16-P16 -> 0
B17: 13 | C17: Sidi Kacem | D17: CHEBANAT | E17: 50-23 | F17: Entretien et réparation du réseau d'assainissement et de drainage | G17: Travaux de curage des canaux révetus | H17: Curage du canal principal d'irrigation beht partie aval 1. | I17: 739200 | K17: =S02!J17 -> 0 | L17: =J17-K17 -> 0 | Q17: =S02!P17 -> 0 | R17: =P17-Q17 -> 0 | S17: =J17-P17 -> 0
B18: 14 | C18: Sidi Kacem | D18: ZIRARA | E18: 50-23 | F18: Entretien et réparation du réseau d'assainissement et de drainage | G18: Travaux de curage des canaux révetus | H18: Curage du canal principal d'irrigation beht partie aval 2. | I18: 1276800 | K18: =S02!J18 -> 0 | L18: =J18-K18 -> 0 | Q18: =S02!P18 -> 0 | R18: =P18-Q18 -> 0 | S18: =J18-P18 -> 0
B19: 15 | C19: Sidi Kacem | D19: DAR LAASLOUJI | E19: 50-23 | F19: Entretien et réparation du réseau d'assainissement et de drainage | G19: Travaux de curage des canaux en terre | H19: Curage des collecteurs d'assainissement des secteurs P8-1 et P8-2 | I19: 5796360 | K19: =S02!J19 -> 0 | L19: =J19-K19 -> 0 | Q19: =S02!P19 -> 0 | R19: =P19-Q19 -> 0 | S19: =J19-P19 -> 0
B20: 16 | C20: Sidi Kacem | D20: DAR LAASLOUJI | E20: 40-21 | F20: Travaux de pistes | G20: Entretien des pistes agricoles | H20: Entretien des pistes agricoles | I20: 340000 | K20: =S02!J20 -> 0 | L20: =J20-K20 -> 0 | Q20: =S02!P20 -> 0 | R20: =P20-Q20 -> 0 | S20: =J20-P20 -> 0
B21: 17 | C21: Sidi Kacem | D21: HOUAFATE | E21: 20-11 | F21: Travaux de réhabilitation des équipements | G21: Travaux de réhabilitation des canaux portés d'irrigation | H21: Fourniture et de pose de canaux porté et accessoires du réseau S3 du secteur S13 | I21: 397934 | K21: =S02!J21 -> 0 | L21: =J21-K21 -> 0 | Q21: =S02!P21 -> 0 | R21: =P21-Q21 -> 0 | S21: =J21-P21 -> 0
B22: 18 | C22: Sidi Kacem | D22: HOUAFATE | E22: 20-11 | F22: Travaux de réhabilitation des équipements | H22: Fourniture et de pose de canaux porté et accessoires du réseau T2S1 du secteur S13 | I22: 207575 | K22: =S02!J22 -> 0 | L22: =J22-K22 -> 0 | Q22: =S02!P22 -> 0 | R22: =P22-Q22 -> 0 | S22: =J22-P22 -> 0
B23: 19 | C23: Sidi Kacem | D23: HOUAFATE | E23: 40-21 | F23: Travaux de pistes | G23: Entretien des pistes agricoles | H23: Entretien des pistes agricoles | I23: 2200000 | K23: =S02!J23 -> 0 | L23: =J23-K23 -> 0 | Q23: =S02!P23 -> 0 | R23: =P23-Q23 -> 0 | S23: =J23-P23 -> 0
B24: 20 | C24: Sidi Kacem | D24: HOUAFATE | E24: 50-23 | F24: Entretien et réparation du réseau d'assainissement et de drainage | G24: Curage des prises sur l’oued, bâche d’aspiration et bassin de régulation. | H24: Curage des prises sur l’oued de la station de pompage S17 et S13. Nettoyage des grilles de préfiltration des boues colmaté de la station de pompage S17 et S13. Curage de la bâche d’aspiration de la station S17 et S13. | I24: 300000 | K24: =S02!J24 -> 0 | L24: =J24-K24 -> 0 | Q24: =S02!P24 -> 0 | R24: =P24-Q24 -> 0 | S24: =J24-P24 -> 0
B25: 21 | C25: Sidi Kacem | D25: HOUAFATE | E25: 50-21 | F25: Entretien et réparation des stations de pompage | G25: Prestation de maintenance des débitmètres et leurs équipements annexes installés au niveau des station de pompage | H25: Changement trois débitmètre Ø 600mm inondés de la station de pompage S13. | I25: 250000 | K25: =S02!J25 -> 0 | L25: =J25-K25 -> 0 | Q25: =S02!P25 -> 0 | R25: =P25-Q25 -> 0 | S25: =J25-P25 -> 0
B26: 22 | C26: Sidi Kacem | D26: HOUAFATE | E26: 50-21 | F26: Entretien et réparation des stations de pompage | G26: Prestations de maintenance des moteurs électriques des stations de pompage. | H26: Révision des trois moteurs électriques 200 KW principaux de la station S13. Révision des deux moteurs électriques 5,5 KW groupes vide de la station S13. | I26: 25000 | K26: =S02!J26 -> 0 | L26: =J26-K26 -> 0 | Q26: =S02!P26 -> 0 | R26: =P26-Q26 -> 0 | S26: =J26-P26 -> 0
B27: 23 | C27: Sidi Kacem | D27: HOUAFATE | E27: 50-21 | F27: Entretien et réparation des stations de pompage | G27: Prestations de maintenance et de réparation mécanique des pompes et des groupes motopompes submersibles des stations de pompage. | H27: Démontage et expertise des roues des pompes principaux et pompes a vide de la station S13. Changement des roulements, tresses et organes d’effectués de la station S13. | I27: 38000 | K27: =S02!J27 -> 0 | L27: =J27-K27 -> 0 | Q27: =S02!P27 -> 0 | R27: =P27-Q27 -> 0 | S27: =J27-P27 -> 0
B28: 24 | C28: Sidi Kacem | D28: HOUAFATE | E28: 50-21 | F28: Entretien et réparation des stations de pompage | G28: Stabilisation Berge oued | H28: Pose de gabions et recouvrement du talus par matelas Reno des stations de pompage S13. | I28: 10560000 | K28: =S02!J28 -> 0 | L28: =J28-K28 -> 0 | Q28: =S02!P28 -> 0 | R28: =P28-Q28 -> 0 | S28: =J28-P28 -> 0
B29: 25 | C29: Sidi Kacem | D29: HOUAFATE | E29: 50-21 | F29: Entretien et réparation des stations de pompage | G29: Mur clôture des stations de pompage. | H29: Stabilisation du sol et reconstruction des murs clôture (270m) cote oued de la station S17. | I29: 144000 | K29: =S02!J29 -> 0 | L29: =J29-K29 -> 0 | Q29: =S02!P29 -> 0 | R29: =P29-Q29 -> 0 | S29: =J29-P29 -> 0
B30: 26 | C30: Sidi Kacem | D30: HOUAFATE | E30: 50-21 | F30: Entretien et réparation des stations de pompage | G30: Génie civile des locaux des stations de pompage. | H30: Expertise d’état et d’étanchéité des locaux pompes, commande, puissance des stations de pompage S17 et S13. Renforcement d’étanchéité des locaux pompe sous niveau des oueds des stations de pompage S17 et S13. | I30: 800000 | K30: =S02!J30 -> 0 | L30: =J30-K30 -> 0 | Q30: =S02!P30 -> 0 | R30: =P30-Q30 -> 0 | S30: =J30-P30 -> 0
B31: 27 | C31: Sidi Kacem | D31: NOUIRAT | E31: 50-23 | F31: Entretien et réparation du réseau d'assainissement et de drainage | G31: Travaux de curage des canaux en terre | H31: Curage des collecteurs d'assainissement des secteurs EST1 et N5 | I31: 1733306 | K31: =S02!J31 -> 0 | L31: =J31-K31 -> 0 | Q31: =S02!P31 -> 0 | R31: =P31-Q31 -> 0 | S31: =J31-P31 -> 0
B32: 28 | C32: Sidi Kacem | D32: NOUIRAT | E32: 40-21 | F32: Travaux de pistes | G32: Entretien des pistes agricoles | H32: Entretien des pistes agricoles | I32: 670000 | K32: =S02!J32 -> 0 | L32: =J32-K32 -> 0 | Q32: =S02!P32 -> 0 | R32: =P32-Q32 -> 0 | S32: =J32-P32 -> 0
B33: 29 | C33: Sidi Kacem | D33: NOUIRAT | E33: 20-11 | F33: Travaux de réhabilitation des équipements | G33: Travaux de réhabilitation des ouvrages de génie civil | H33: Réhabilitation de l'ouvrage( genie civil ,gabiollannage,clapet anti retour et buse) de l'ouvrage de débouche SE1 | I33: 2500000 | K33: =S02!J33 -> 0 | L33: =J33-K33 -> 0 | Q33: =S02!P33 -> 0 | R33: =P33-Q33 -> 0 | S33: =J33-P33 -> 0
B34: 30 | C34: Sidi Kacem | D34: NOUIRAT | E34: 50-23 | F34: Entretien et réparation du réseau d'assainissement et de drainage | G34: Curage des prises sur l’oued, bâche d’aspiration et bassin de régulation. | H34: Curage des prises sur l’oued de la station de pompage E1. Nettoyage des grilles de préfiltration des boues colmaté de la station de pompage E1. Curage de la bâche d’aspiration de la station E1. | I34: 800000 | K34: =S02!J34 -> 0 | L34: =J34-K34 -> 0 | Q34: =S02!P34 -> 0 | R34: =P34-Q34 -> 0 | S34: =J34-P34 -> 0
... B42: 38 | C42: Sidi Kacem | D42: SAFSAF | E42: 20-11 | F42: Travaux de réhabilitation des équipements | G42: Travaux de réhabilitation des canaux portés d'irrigation | H42: Fourniture et pose de canaux porté et accessoires du réseau S4 du secteur S11 | I42: 232266 | K42: =S02!J42 -> 0 | L42: =J42-K42 -> 0 | Q42: =S02!P42 -> 0 | R42: =P42-Q42 -> 0 | S42: =J42-P42 -> 0
B43: 39 | C43: Sidi Kacem | D43: SAFSAF | E43: 20-11 | F43: Travaux de réhabilitation des équipements | H43: Recalage des canaux portés du réseau T5S5 du secteur S9 | I43: 1055025 | K43: =S02!J43 -> 0 | L43: =J43-K43 -> 0 | Q43: =S02!P43 -> 0 | R43: =P43-Q43 -> 0 | S43: =J43-P43 -> 0
B44: 40 | C44: Sidi Kacem | D44: SAFSAF | E44: 20-11 | F44: Travaux de réhabilitation des équipements | H44: Recalage des canaux portés du réseau T7S5 du secteur S9 | I44: 1004535 | K44: =S02!J44 -> 0 | L44: =J44-K44 -> 0 | Q44: =S02!P44 -> 0 | R44: =P44-Q44 -> 0 | S44: =J44-P44 -> 0
B45: 41 | C45: Sidi Kacem | D45: SAFSAF | E45: 20-11 | F45: Travaux de réhabilitation des équipements | H45: Recalage des canaux portés du réseau T2S5 du secteur S9 | I45: 793830 | K45: =S02!J45 -> 0 | L45: =J45-K45 -> 0 | Q45: =S02!P45 -> 0 | R45: =P45-Q45 -> 0 | S45: =J45-P45 -> 0
B46: 42 | C46: Sidi Kacem | D46: SAFSAF | E46: 40-21 | F46: Travaux de pistes | G46: Entretien des pistes agricoles | H46: Entretien des pistes agricoles | I46: 2000000 | K46: =S02!J46 -> 0 | L46: =J46-K46 -> 0 | Q46: =S02!P46 -> 0 | R46: =P46-Q46 -> 0 | S46: =J46-P46 -> 0
B47: 43 | C47: Sidi Kacem | D47: SAFSAF | E47: 50-23 | F47: Entretien et réparation du réseau d'assainissement et de drainage | G47: Curage des prises sur l’oued, bâche d’aspiration et bassin de régulation. | H47: Curage des prises sur l’oued des stations de pompage S11, S9, 7D et 7B. Nettoyage des grilles de préfiltration des boues colmaté des stations de pompage S11, S9, 7D et 7B. Nettoyage des crépines des boues colmaté de station pompage 7D. Curage des dalots et bâche d’aspiration des stations de pompage S11, S9, 7B. | I47: 200000 | K47: =S02!J47 -> 0 | L47: =J47-K47 -> 0 | Q47: =S02!P47 -> 0 | R47: =P47-Q47 -> 0 | S47: =J47-P47 -> 0
B48: 44 | C48: Sidi Kacem | D48: SAFSAF | E48: 50-21 | F48: Entretien et réparation des stations de pompage | G48: Prestation de maintenance des débitmètres et leurs équipements annexes installés au niveau des station de pompage | H48: Changements Sept des débitmètres Ø 600mm inondé des deux stations de pompage S11 et S9. | I48: 580000 | K48: =S02!J48 -> 0 | L48: =J48-K48 -> 0 | Q48: =S02!P48 -> 0 | R48: =P48-Q48 -> 0 | S48: =J48-P48 -> 0
...

Sheet S04
B2: Suivi Hebdomadaire - Semaine 4 - Exécution Physique et Financière
B3: Date Semaine :
B4: N° | C4: Province | D4: Commune | E4: Rubrique | F4: Intitulé Rubrique | G4: Projet | H4: Consistance | I4: Coût Total (DH) | J4: Avancement Physique % | K4: % Physique Sem. Préc. | L4: Accroissement Physique % | M4: Montant Décaissé (DH) | N4: Montant Payé (DH) | O4: Montant Ordonné (DH) | P4: Avancement Financier % | Q4: % Financier Sem. Préc. | R4: Accroissement Financier % | S4: Écart Physique-Financier | T4: Observations
B5: 1 | C5: Sidi Kacem | D5: KHENICHET | E5: 50-23 | F5: Entretien et réparation du réseau d'assainissement et de drainage | G5: Travaux de curage des canaux en terre | H5: Curage des collecteurs d'assainissement du secteur EST2 | I5: 2091568 | K5: =S03!J5 -> 0 | L5: =J5-K5 -> 0 | Q5: =S03!P5 -> 0 | R5: =P5-Q5 -> 0 | S5: =J5-P5 -> 0
B6: 2 | C6: Sidi Kacem | D6: KHENICHET | E6: 40-21 | F6: Travaux de pistes | G6: Travaux de réhabilitation des pistes agricoles | H6: Entretien des pistes agricoles Douar Nouagra et Douar ouled Salem | I6: 78000 | K6: =S03!J6 -> 0 | L6: =J6-K6 -> 0 | Q6: =S03!P6 -> 0 | R6: =P6-Q6 -> 0 | S6: =J6-P6 -> 0
B7: 3 | C7: Sidi Kacem | D7: KHENICHET | E7: 50-23 | F7: Entretien et réparation du réseau d'assainissement et de drainage | G7: Curage des prises sur l’oued, bâche d’aspiration et bassin de régulation. | H7: Curage de la chambre des joints de démontage des siphonnes de la station de pompage EST2. | I7: 126000 | K7: =S03!J7 -> 0 | L7: =J7-K7 -> 0 | Q7: =S03!P7 -> 0 | R7: =P7-Q7 -> 0 | S7: =J7-P7 -> 0
B8: 4 | C8: Sidi Kacem | D8: KHENICHET | E8: 50-21 | F8: Entretien et réparation des stations de pompage | G8: Prestation de maintenance des débitmètres et leurs équipements annexes installés au niveau des station de pompage | H8: Changement trois débitmètre Ø 600mm inondés de la station de pompage EST 2 et deux capteurs VEGASON 62 | I8: 165500 | K8: =S03!J8 -> 0 | L8: =J8-K8 -> 0 | Q8: =S03!P8 -> 0 | R8: =P8-Q8 -> 0 | S8: =J8-P8 -> 0
B9: 5 | C9: Sidi Kacem | D9: BIR TALEB | E9: 50-23 | F9: Entretien et réparation du réseau d'assainissement et de drainage | G9: Travaux de curage des canaux en terre | H9: Curage du canal d'assainisement Tihli Aval | I9: 1000000 | K9: =S03!J9 -> 0 | L9: =J9-K9 -> 0 | Q9: =S03!P9 -> 0 | R9: =P9-Q9 -> 0 | S9: =J9-P9 -> 0
B10: 6 | C10: Sidi Kacem | D10: BIR TALEB | E10: 50-23 | F10: Entretien et réparation du réseau d'assainissement et de drainage | H10: Curage des collecteurs d'assainissement du secteur P11/1 | I10: 846731 | K10: =S03!J10 -> 0 | L10: =J10-K10 -> 0 | Q10: =S03!P10 -> 0 | R10: =P10-Q10 -> 0 | S10: =J10-P10 -> 0
B11: 7 | C11: Sidi Kacem | D11: BIR TALEB | E11: 50-23 | F11: Entretien et réparation du réseau d'assainissement et de drainage | G11: Curage des prises sur l’oued, bâche d’aspiration et bassin de régulation. | H11: Curage des prises sur l’oued de la station de pompage P11/1. | I11: 200000 | K11: =S03!J11 -> 0 | L11: =J11-K11 -> 0 | Q11: =S03!P11 -> 0 | R11: =P11-Q11 -> 0 | S11: =J11-P11 -> 0
B12: 8 | C12: Sidi Kacem | D12: BIR TALEB | E12: 50-21 | F12: Entretien et réparation des stations de pompage | G12: Prestation de maintenance des débitmètres et leurs équipements annexes installés au niveau des station de pompage | H12: Changement trois débitmètre Ø 400mm inondés de la station de pompage P11/1 | I12: 141900 | K12: =S03!J12 -> 0 | L12: =J12-K12 -> 0 | Q12: =S03!P12 -> 0 | R12: =P12-Q12 -> 0 | S12: =J12-P12 -> 0
